2022-09-21 13:06:10,580 [autoreload | INFO] Watching for file changes with StatReloader
2022-09-21 13:07:02,204 [basehttp | INFO] "GET /swagger/ HTTP/1.1" 200 2160
2022-09-21 13:07:04,323 [basehttp | INFO] "GET /static/drf-yasg/style.css HTTP/1.1" 200 1047
2022-09-21 13:07:04,388 [basehttp | INFO] "GET /static/drf-yasg/swagger-ui-dist/swagger-ui.css HTTP/1.1" 200 143858
2022-09-21 13:07:04,398 [basehttp | INFO] "GET /static/drf-yasg/swagger-ui-init.js HTTP/1.1" 200 14964
2022-09-21 13:07:04,409 [basehttp | INFO] "GET /static/drf-yasg/insQ.min.js HTTP/1.1" 200 2093
2022-09-21 13:07:04,521 [basehttp | INFO] "GET /static/drf-yasg/immutable.min.js HTTP/1.1" 200 56904
2022-09-21 13:07:04,854 [basehttp | INFO] "GET /static/drf-yasg/swagger-ui-dist/swagger-ui-standalone-preset.js HTTP/1.1" 200 324275
2022-09-21 13:07:04,896 [basehttp | INFO] "GET /static/drf-yasg/swagger-ui-dist/swagger-ui-bundle.js HTTP/1.1" 200 1086481
2022-09-21 13:07:06,543 [basehttp | INFO] "GET /static/drf-yasg/swagger-ui-dist/favicon-32x32.png HTTP/1.1" 200 628
2022-09-21 13:07:07,943 [basehttp | INFO] "GET /swagger/?format=openapi HTTP/1.1" 200 75755
2022-09-21 13:07:34,065 [basehttp | INFO] "GET /admin/ HTTP/1.1" 200 15083
2022-09-21 13:07:34,167 [basehttp | INFO] "GET /static/admin/js/nav_sidebar.js HTTP/1.1" 200 3763
2022-09-21 13:07:34,172 [basehttp | INFO] "GET /static/admin/css/dashboard.css HTTP/1.1" 200 380
2022-09-21 13:07:34,188 [basehttp | INFO] "GET /static/admin/css/nav_sidebar.css HTTP/1.1" 200 2616
2022-09-21 13:07:34,193 [basehttp | INFO] "GET /static/admin/css/base.css HTTP/1.1" 200 19513
2022-09-21 13:07:34,196 [basehttp | INFO] "GET /static/admin/css/responsive.css HTTP/1.1" 200 18575
2022-09-21 13:07:34,255 [basehttp | INFO] "GET /static/admin/css/fonts.css HTTP/1.1" 200 423
2022-09-21 13:07:34,296 [basehttp | INFO] "GET /static/admin/img/icon-changelink.svg HTTP/1.1" 200 380
2022-09-21 13:07:34,297 [basehttp | INFO] "GET /static/admin/img/icon-addlink.svg HTTP/1.1" 200 331
2022-09-21 13:07:34,369 [basehttp | INFO] "GET /static/admin/fonts/Roboto-Regular-webfont.woff HTTP/1.1" 200 85876
2022-09-21 13:07:34,371 [basehttp | INFO] "GET /static/admin/fonts/Roboto-Light-webfont.woff HTTP/1.1" 200 85692
2022-09-21 13:07:34,401 [basehttp | INFO] "GET /static/admin/fonts/Roboto-Bold-webfont.woff HTTP/1.1" 200 86184
2022-09-21 13:07:36,456 [log | ERROR] Internal Server Error: /admin/adds/post/ @ /usr/local/lib/python3.10/site-packages/django/utils/log.py : 241 : log_response
Traceback (most recent call last):
  File "/usr/local/lib/python3.10/site-packages/django/db/backends/utils.py", line 89, in _execute
    return self.cursor.execute(sql, params)
psycopg2.errors.UndefinedColumn: column adds_post.views does not exist
LINE 1: ...ds_post"."wa_number", "adds_post"."is_activated", "adds_post...
                                                             ^


The above exception was the direct cause of the following exception:

Traceback (most recent call last):
  File "/usr/local/lib/python3.10/site-packages/django/core/handlers/exception.py", line 55, in inner
    response = get_response(request)
  File "/usr/local/lib/python3.10/site-packages/django/core/handlers/base.py", line 197, in _get_response
    response = wrapped_callback(request, *callback_args, **callback_kwargs)
  File "/usr/local/lib/python3.10/site-packages/django/contrib/admin/options.py", line 683, in wrapper
    return self.admin_site.admin_view(view)(*args, **kwargs)
  File "/usr/local/lib/python3.10/site-packages/django/utils/decorators.py", line 133, in _wrapped_view
    response = view_func(request, *args, **kwargs)
  File "/usr/local/lib/python3.10/site-packages/django/views/decorators/cache.py", line 62, in _wrapped_view_func
    response = view_func(request, *args, **kwargs)
  File "/usr/local/lib/python3.10/site-packages/django/contrib/admin/sites.py", line 242, in inner
    return view(request, *args, **kwargs)
  File "/usr/local/lib/python3.10/site-packages/django/utils/decorators.py", line 46, in _wrapper
    return bound_method(*args, **kwargs)
  File "/usr/local/lib/python3.10/site-packages/django/utils/decorators.py", line 133, in _wrapped_view
    response = view_func(request, *args, **kwargs)
  File "/usr/local/lib/python3.10/site-packages/django/contrib/admin/options.py", line 2063, in changelist_view
    "selection_note": _("0 of %(cnt)s selected") % {"cnt": len(cl.result_list)},
  File "/usr/local/lib/python3.10/site-packages/django/db/models/query.py", line 302, in __len__
    self._fetch_all()
  File "/usr/local/lib/python3.10/site-packages/django/db/models/query.py", line 1507, in _fetch_all
    self._result_cache = list(self._iterable_class(self))
  File "/usr/local/lib/python3.10/site-packages/django/db/models/query.py", line 57, in __iter__
    results = compiler.execute_sql(
  File "/usr/local/lib/python3.10/site-packages/django/db/models/sql/compiler.py", line 1361, in execute_sql
    cursor.execute(sql, params)
  File "/usr/local/lib/python3.10/site-packages/django/db/backends/utils.py", line 103, in execute
    return super().execute(sql, params)
  File "/usr/local/lib/python3.10/site-packages/django/db/backends/utils.py", line 67, in execute
    return self._execute_with_wrappers(
  File "/usr/local/lib/python3.10/site-packages/django/db/backends/utils.py", line 80, in _execute_with_wrappers
    return executor(sql, params, many, context)
  File "/usr/local/lib/python3.10/site-packages/django/db/backends/utils.py", line 84, in _execute
    with self.db.wrap_database_errors:
  File "/usr/local/lib/python3.10/site-packages/django/db/utils.py", line 91, in __exit__
    raise dj_exc_value.with_traceback(traceback) from exc_value
  File "/usr/local/lib/python3.10/site-packages/django/db/backends/utils.py", line 89, in _execute
    return self.cursor.execute(sql, params)
django.db.utils.ProgrammingError: column adds_post.views does not exist
LINE 1: ...ds_post"."wa_number", "adds_post"."is_activated", "adds_post...
                                                             ^

2022-09-21 13:07:36,456 [log | ERROR] Internal Server Error: /admin/adds/post/
Traceback (most recent call last):
  File "/usr/local/lib/python3.10/site-packages/django/db/backends/utils.py", line 89, in _execute
    return self.cursor.execute(sql, params)
psycopg2.errors.UndefinedColumn: column adds_post.views does not exist
LINE 1: ...ds_post"."wa_number", "adds_post"."is_activated", "adds_post...
                                                             ^


The above exception was the direct cause of the following exception:

Traceback (most recent call last):
  File "/usr/local/lib/python3.10/site-packages/django/core/handlers/exception.py", line 55, in inner
    response = get_response(request)
  File "/usr/local/lib/python3.10/site-packages/django/core/handlers/base.py", line 197, in _get_response
    response = wrapped_callback(request, *callback_args, **callback_kwargs)
  File "/usr/local/lib/python3.10/site-packages/django/contrib/admin/options.py", line 683, in wrapper
    return self.admin_site.admin_view(view)(*args, **kwargs)
  File "/usr/local/lib/python3.10/site-packages/django/utils/decorators.py", line 133, in _wrapped_view
    response = view_func(request, *args, **kwargs)
  File "/usr/local/lib/python3.10/site-packages/django/views/decorators/cache.py", line 62, in _wrapped_view_func
    response = view_func(request, *args, **kwargs)
  File "/usr/local/lib/python3.10/site-packages/django/contrib/admin/sites.py", line 242, in inner
    return view(request, *args, **kwargs)
  File "/usr/local/lib/python3.10/site-packages/django/utils/decorators.py", line 46, in _wrapper
    return bound_method(*args, **kwargs)
  File "/usr/local/lib/python3.10/site-packages/django/utils/decorators.py", line 133, in _wrapped_view
    response = view_func(request, *args, **kwargs)
  File "/usr/local/lib/python3.10/site-packages/django/contrib/admin/options.py", line 2063, in changelist_view
    "selection_note": _("0 of %(cnt)s selected") % {"cnt": len(cl.result_list)},
  File "/usr/local/lib/python3.10/site-packages/django/db/models/query.py", line 302, in __len__
    self._fetch_all()
  File "/usr/local/lib/python3.10/site-packages/django/db/models/query.py", line 1507, in _fetch_all
    self._result_cache = list(self._iterable_class(self))
  File "/usr/local/lib/python3.10/site-packages/django/db/models/query.py", line 57, in __iter__
    results = compiler.execute_sql(
  File "/usr/local/lib/python3.10/site-packages/django/db/models/sql/compiler.py", line 1361, in execute_sql
    cursor.execute(sql, params)
  File "/usr/local/lib/python3.10/site-packages/django/db/backends/utils.py", line 103, in execute
    return super().execute(sql, params)
  File "/usr/local/lib/python3.10/site-packages/django/db/backends/utils.py", line 67, in execute
    return self._execute_with_wrappers(
  File "/usr/local/lib/python3.10/site-packages/django/db/backends/utils.py", line 80, in _execute_with_wrappers
    return executor(sql, params, many, context)
  File "/usr/local/lib/python3.10/site-packages/django/db/backends/utils.py", line 84, in _execute
    with self.db.wrap_database_errors:
  File "/usr/local/lib/python3.10/site-packages/django/db/utils.py", line 91, in __exit__
    raise dj_exc_value.with_traceback(traceback) from exc_value
  File "/usr/local/lib/python3.10/site-packages/django/db/backends/utils.py", line 89, in _execute
    return self.cursor.execute(sql, params)
django.db.utils.ProgrammingError: column adds_post.views does not exist
LINE 1: ...ds_post"."wa_number", "adds_post"."is_activated", "adds_post...
                                                             ^

2022-09-21 13:07:36,478 [basehttp | ERROR] "GET /admin/adds/post/ HTTP/1.1" 500 147999 @ /usr/local/lib/python3.10/site-packages/django/core/servers/basehttp.py : 187 : log_message
2022-09-21 13:07:36,478 [basehttp | ERROR] "GET /admin/adds/post/ HTTP/1.1" 500 147999
2022-09-21 13:07:51,119 [basehttp | INFO] "GET /admin/ HTTP/1.1" 200 15083
2022-09-21 13:07:52,974 [basehttp | INFO] "GET /admin/adds/city/ HTTP/1.1" 200 13054
2022-09-21 13:07:53,000 [basehttp | INFO] "GET /static/admin/css/base.css HTTP/1.1" 304 0
2022-09-21 13:07:53,034 [basehttp | INFO] "GET /static/admin/css/changelists.css HTTP/1.1" 200 6932
2022-09-21 13:07:53,056 [basehttp | INFO] "GET /static/admin/css/nav_sidebar.css HTTP/1.1" 304 0
2022-09-21 13:07:53,067 [basehttp | INFO] "GET /static/admin/js/core.js HTTP/1.1" 200 5698
2022-09-21 13:07:53,067 [basehttp | INFO] "GET /static/admin/js/jquery.init.js HTTP/1.1" 200 347
2022-09-21 13:07:53,081 [basehttp | INFO] "GET /static/admin/js/vendor/jquery/jquery.js HTTP/1.1" 200 288580
2022-09-21 13:07:53,089 [basehttp | INFO] "GET /static/admin/css/fonts.css HTTP/1.1" 304 0
2022-09-21 13:07:53,110 [basehttp | INFO] "GET /static/admin/js/admin/RelatedObjectLookups.js HTTP/1.1" 200 5984
2022-09-21 13:07:53,111 [basehttp | INFO] "GET /static/admin/css/responsive.css HTTP/1.1" 304 0
2022-09-21 13:07:53,139 [basehttp | INFO] "GET /static/admin/js/actions.js HTTP/1.1" 200 7872
2022-09-21 13:07:53,144 [basehttp | INFO] "GET /admin/jsi18n/ HTTP/1.1" 200 3343
2022-09-21 13:07:53,156 [basehttp | INFO] "GET /static/admin/js/urlify.js HTTP/1.1" 200 7902
2022-09-21 13:07:53,145 [basehttp | INFO] "GET /static/admin/js/prepopulate.js HTTP/1.1" 200 1531
2022-09-21 13:07:53,183 [basehttp | INFO] "GET /static/admin/js/nav_sidebar.js HTTP/1.1" 304 0
2022-09-21 13:07:53,205 [basehttp | INFO] "GET /static/admin/js/vendor/xregexp/xregexp.js HTTP/1.1" 200 232381
2022-09-21 13:07:53,229 [basehttp | INFO] "GET /static/admin/fonts/Roboto-Regular-webfont.woff HTTP/1.1" 304 0
2022-09-21 13:07:53,231 [basehttp | INFO] "GET /static/admin/img/icon-addlink.svg HTTP/1.1" 304 0
2022-09-21 13:07:53,240 [basehttp | INFO] "GET /static/admin/fonts/Roboto-Light-webfont.woff HTTP/1.1" 304 0
2022-09-21 13:07:53,247 [basehttp | INFO] "GET /static/admin/img/tooltag-add.svg HTTP/1.1" 200 331
2022-09-21 13:07:53,249 [basehttp | INFO] "GET /static/admin/fonts/Roboto-Bold-webfont.woff HTTP/1.1" 304 0
2022-09-21 13:07:55,593 [log | ERROR] Internal Server Error: /admin/adds/post/ @ /usr/local/lib/python3.10/site-packages/django/utils/log.py : 241 : log_response
Traceback (most recent call last):
  File "/usr/local/lib/python3.10/site-packages/django/db/backends/utils.py", line 89, in _execute
    return self.cursor.execute(sql, params)
psycopg2.errors.UndefinedColumn: column adds_post.views does not exist
LINE 1: ...ds_post"."wa_number", "adds_post"."is_activated", "adds_post...
                                                             ^


The above exception was the direct cause of the following exception:

Traceback (most recent call last):
  File "/usr/local/lib/python3.10/site-packages/django/core/handlers/exception.py", line 55, in inner
    response = get_response(request)
  File "/usr/local/lib/python3.10/site-packages/django/core/handlers/base.py", line 197, in _get_response
    response = wrapped_callback(request, *callback_args, **callback_kwargs)
  File "/usr/local/lib/python3.10/site-packages/django/contrib/admin/options.py", line 683, in wrapper
    return self.admin_site.admin_view(view)(*args, **kwargs)
  File "/usr/local/lib/python3.10/site-packages/django/utils/decorators.py", line 133, in _wrapped_view
    response = view_func(request, *args, **kwargs)
  File "/usr/local/lib/python3.10/site-packages/django/views/decorators/cache.py", line 62, in _wrapped_view_func
    response = view_func(request, *args, **kwargs)
  File "/usr/local/lib/python3.10/site-packages/django/contrib/admin/sites.py", line 242, in inner
    return view(request, *args, **kwargs)
  File "/usr/local/lib/python3.10/site-packages/django/utils/decorators.py", line 46, in _wrapper
    return bound_method(*args, **kwargs)
  File "/usr/local/lib/python3.10/site-packages/django/utils/decorators.py", line 133, in _wrapped_view
    response = view_func(request, *args, **kwargs)
  File "/usr/local/lib/python3.10/site-packages/django/contrib/admin/options.py", line 2063, in changelist_view
    "selection_note": _("0 of %(cnt)s selected") % {"cnt": len(cl.result_list)},
  File "/usr/local/lib/python3.10/site-packages/django/db/models/query.py", line 302, in __len__
    self._fetch_all()
  File "/usr/local/lib/python3.10/site-packages/django/db/models/query.py", line 1507, in _fetch_all
    self._result_cache = list(self._iterable_class(self))
  File "/usr/local/lib/python3.10/site-packages/django/db/models/query.py", line 57, in __iter__
    results = compiler.execute_sql(
  File "/usr/local/lib/python3.10/site-packages/django/db/models/sql/compiler.py", line 1361, in execute_sql
    cursor.execute(sql, params)
  File "/usr/local/lib/python3.10/site-packages/django/db/backends/utils.py", line 103, in execute
    return super().execute(sql, params)
  File "/usr/local/lib/python3.10/site-packages/django/db/backends/utils.py", line 67, in execute
    return self._execute_with_wrappers(
  File "/usr/local/lib/python3.10/site-packages/django/db/backends/utils.py", line 80, in _execute_with_wrappers
    return executor(sql, params, many, context)
  File "/usr/local/lib/python3.10/site-packages/django/db/backends/utils.py", line 84, in _execute
    with self.db.wrap_database_errors:
  File "/usr/local/lib/python3.10/site-packages/django/db/utils.py", line 91, in __exit__
    raise dj_exc_value.with_traceback(traceback) from exc_value
  File "/usr/local/lib/python3.10/site-packages/django/db/backends/utils.py", line 89, in _execute
    return self.cursor.execute(sql, params)
django.db.utils.ProgrammingError: column adds_post.views does not exist
LINE 1: ...ds_post"."wa_number", "adds_post"."is_activated", "adds_post...
                                                             ^

2022-09-21 13:07:55,593 [log | ERROR] Internal Server Error: /admin/adds/post/
Traceback (most recent call last):
  File "/usr/local/lib/python3.10/site-packages/django/db/backends/utils.py", line 89, in _execute
    return self.cursor.execute(sql, params)
psycopg2.errors.UndefinedColumn: column adds_post.views does not exist
LINE 1: ...ds_post"."wa_number", "adds_post"."is_activated", "adds_post...
                                                             ^


The above exception was the direct cause of the following exception:

Traceback (most recent call last):
  File "/usr/local/lib/python3.10/site-packages/django/core/handlers/exception.py", line 55, in inner
    response = get_response(request)
  File "/usr/local/lib/python3.10/site-packages/django/core/handlers/base.py", line 197, in _get_response
    response = wrapped_callback(request, *callback_args, **callback_kwargs)
  File "/usr/local/lib/python3.10/site-packages/django/contrib/admin/options.py", line 683, in wrapper
    return self.admin_site.admin_view(view)(*args, **kwargs)
  File "/usr/local/lib/python3.10/site-packages/django/utils/decorators.py", line 133, in _wrapped_view
    response = view_func(request, *args, **kwargs)
  File "/usr/local/lib/python3.10/site-packages/django/views/decorators/cache.py", line 62, in _wrapped_view_func
    response = view_func(request, *args, **kwargs)
  File "/usr/local/lib/python3.10/site-packages/django/contrib/admin/sites.py", line 242, in inner
    return view(request, *args, **kwargs)
  File "/usr/local/lib/python3.10/site-packages/django/utils/decorators.py", line 46, in _wrapper
    return bound_method(*args, **kwargs)
  File "/usr/local/lib/python3.10/site-packages/django/utils/decorators.py", line 133, in _wrapped_view
    response = view_func(request, *args, **kwargs)
  File "/usr/local/lib/python3.10/site-packages/django/contrib/admin/options.py", line 2063, in changelist_view
    "selection_note": _("0 of %(cnt)s selected") % {"cnt": len(cl.result_list)},
  File "/usr/local/lib/python3.10/site-packages/django/db/models/query.py", line 302, in __len__
    self._fetch_all()
  File "/usr/local/lib/python3.10/site-packages/django/db/models/query.py", line 1507, in _fetch_all
    self._result_cache = list(self._iterable_class(self))
  File "/usr/local/lib/python3.10/site-packages/django/db/models/query.py", line 57, in __iter__
    results = compiler.execute_sql(
  File "/usr/local/lib/python3.10/site-packages/django/db/models/sql/compiler.py", line 1361, in execute_sql
    cursor.execute(sql, params)
  File "/usr/local/lib/python3.10/site-packages/django/db/backends/utils.py", line 103, in execute
    return super().execute(sql, params)
  File "/usr/local/lib/python3.10/site-packages/django/db/backends/utils.py", line 67, in execute
    return self._execute_with_wrappers(
  File "/usr/local/lib/python3.10/site-packages/django/db/backends/utils.py", line 80, in _execute_with_wrappers
    return executor(sql, params, many, context)
  File "/usr/local/lib/python3.10/site-packages/django/db/backends/utils.py", line 84, in _execute
    with self.db.wrap_database_errors:
  File "/usr/local/lib/python3.10/site-packages/django/db/utils.py", line 91, in __exit__
    raise dj_exc_value.with_traceback(traceback) from exc_value
  File "/usr/local/lib/python3.10/site-packages/django/db/backends/utils.py", line 89, in _execute
    return self.cursor.execute(sql, params)
django.db.utils.ProgrammingError: column adds_post.views does not exist
LINE 1: ...ds_post"."wa_number", "adds_post"."is_activated", "adds_post...
                                                             ^

2022-09-21 13:07:55,598 [basehttp | ERROR] "GET /admin/adds/post/ HTTP/1.1" 500 148009 @ /usr/local/lib/python3.10/site-packages/django/core/servers/basehttp.py : 187 : log_message
2022-09-21 13:07:55,598 [basehttp | ERROR] "GET /admin/adds/post/ HTTP/1.1" 500 148009
2022-09-21 13:08:49,796 [basehttp | INFO] "GET /admin/adds/city/ HTTP/1.1" 200 13054
2022-09-21 13:08:51,818 [log | ERROR] Internal Server Error: /admin/adds/post/ @ /usr/local/lib/python3.10/site-packages/django/utils/log.py : 241 : log_response
Traceback (most recent call last):
  File "/usr/local/lib/python3.10/site-packages/django/db/backends/utils.py", line 89, in _execute
    return self.cursor.execute(sql, params)
psycopg2.errors.UndefinedColumn: column adds_post.views does not exist
LINE 1: ...ds_post"."wa_number", "adds_post"."is_activated", "adds_post...
                                                             ^


The above exception was the direct cause of the following exception:

Traceback (most recent call last):
  File "/usr/local/lib/python3.10/site-packages/django/core/handlers/exception.py", line 55, in inner
    response = get_response(request)
  File "/usr/local/lib/python3.10/site-packages/django/core/handlers/base.py", line 197, in _get_response
    response = wrapped_callback(request, *callback_args, **callback_kwargs)
  File "/usr/local/lib/python3.10/site-packages/django/contrib/admin/options.py", line 683, in wrapper
    return self.admin_site.admin_view(view)(*args, **kwargs)
  File "/usr/local/lib/python3.10/site-packages/django/utils/decorators.py", line 133, in _wrapped_view
    response = view_func(request, *args, **kwargs)
  File "/usr/local/lib/python3.10/site-packages/django/views/decorators/cache.py", line 62, in _wrapped_view_func
    response = view_func(request, *args, **kwargs)
  File "/usr/local/lib/python3.10/site-packages/django/contrib/admin/sites.py", line 242, in inner
    return view(request, *args, **kwargs)
  File "/usr/local/lib/python3.10/site-packages/django/utils/decorators.py", line 46, in _wrapper
    return bound_method(*args, **kwargs)
  File "/usr/local/lib/python3.10/site-packages/django/utils/decorators.py", line 133, in _wrapped_view
    response = view_func(request, *args, **kwargs)
  File "/usr/local/lib/python3.10/site-packages/django/contrib/admin/options.py", line 2063, in changelist_view
    "selection_note": _("0 of %(cnt)s selected") % {"cnt": len(cl.result_list)},
  File "/usr/local/lib/python3.10/site-packages/django/db/models/query.py", line 302, in __len__
    self._fetch_all()
  File "/usr/local/lib/python3.10/site-packages/django/db/models/query.py", line 1507, in _fetch_all
    self._result_cache = list(self._iterable_class(self))
  File "/usr/local/lib/python3.10/site-packages/django/db/models/query.py", line 57, in __iter__
    results = compiler.execute_sql(
  File "/usr/local/lib/python3.10/site-packages/django/db/models/sql/compiler.py", line 1361, in execute_sql
    cursor.execute(sql, params)
  File "/usr/local/lib/python3.10/site-packages/django/db/backends/utils.py", line 103, in execute
    return super().execute(sql, params)
  File "/usr/local/lib/python3.10/site-packages/django/db/backends/utils.py", line 67, in execute
    return self._execute_with_wrappers(
  File "/usr/local/lib/python3.10/site-packages/django/db/backends/utils.py", line 80, in _execute_with_wrappers
    return executor(sql, params, many, context)
  File "/usr/local/lib/python3.10/site-packages/django/db/backends/utils.py", line 84, in _execute
    with self.db.wrap_database_errors:
  File "/usr/local/lib/python3.10/site-packages/django/db/utils.py", line 91, in __exit__
    raise dj_exc_value.with_traceback(traceback) from exc_value
  File "/usr/local/lib/python3.10/site-packages/django/db/backends/utils.py", line 89, in _execute
    return self.cursor.execute(sql, params)
django.db.utils.ProgrammingError: column adds_post.views does not exist
LINE 1: ...ds_post"."wa_number", "adds_post"."is_activated", "adds_post...
                                                             ^

2022-09-21 13:08:51,818 [log | ERROR] Internal Server Error: /admin/adds/post/
Traceback (most recent call last):
  File "/usr/local/lib/python3.10/site-packages/django/db/backends/utils.py", line 89, in _execute
    return self.cursor.execute(sql, params)
psycopg2.errors.UndefinedColumn: column adds_post.views does not exist
LINE 1: ...ds_post"."wa_number", "adds_post"."is_activated", "adds_post...
                                                             ^


The above exception was the direct cause of the following exception:

Traceback (most recent call last):
  File "/usr/local/lib/python3.10/site-packages/django/core/handlers/exception.py", line 55, in inner
    response = get_response(request)
  File "/usr/local/lib/python3.10/site-packages/django/core/handlers/base.py", line 197, in _get_response
    response = wrapped_callback(request, *callback_args, **callback_kwargs)
  File "/usr/local/lib/python3.10/site-packages/django/contrib/admin/options.py", line 683, in wrapper
    return self.admin_site.admin_view(view)(*args, **kwargs)
  File "/usr/local/lib/python3.10/site-packages/django/utils/decorators.py", line 133, in _wrapped_view
    response = view_func(request, *args, **kwargs)
  File "/usr/local/lib/python3.10/site-packages/django/views/decorators/cache.py", line 62, in _wrapped_view_func
    response = view_func(request, *args, **kwargs)
  File "/usr/local/lib/python3.10/site-packages/django/contrib/admin/sites.py", line 242, in inner
    return view(request, *args, **kwargs)
  File "/usr/local/lib/python3.10/site-packages/django/utils/decorators.py", line 46, in _wrapper
    return bound_method(*args, **kwargs)
  File "/usr/local/lib/python3.10/site-packages/django/utils/decorators.py", line 133, in _wrapped_view
    response = view_func(request, *args, **kwargs)
  File "/usr/local/lib/python3.10/site-packages/django/contrib/admin/options.py", line 2063, in changelist_view
    "selection_note": _("0 of %(cnt)s selected") % {"cnt": len(cl.result_list)},
  File "/usr/local/lib/python3.10/site-packages/django/db/models/query.py", line 302, in __len__
    self._fetch_all()
  File "/usr/local/lib/python3.10/site-packages/django/db/models/query.py", line 1507, in _fetch_all
    self._result_cache = list(self._iterable_class(self))
  File "/usr/local/lib/python3.10/site-packages/django/db/models/query.py", line 57, in __iter__
    results = compiler.execute_sql(
  File "/usr/local/lib/python3.10/site-packages/django/db/models/sql/compiler.py", line 1361, in execute_sql
    cursor.execute(sql, params)
  File "/usr/local/lib/python3.10/site-packages/django/db/backends/utils.py", line 103, in execute
    return super().execute(sql, params)
  File "/usr/local/lib/python3.10/site-packages/django/db/backends/utils.py", line 67, in execute
    return self._execute_with_wrappers(
  File "/usr/local/lib/python3.10/site-packages/django/db/backends/utils.py", line 80, in _execute_with_wrappers
    return executor(sql, params, many, context)
  File "/usr/local/lib/python3.10/site-packages/django/db/backends/utils.py", line 84, in _execute
    with self.db.wrap_database_errors:
  File "/usr/local/lib/python3.10/site-packages/django/db/utils.py", line 91, in __exit__
    raise dj_exc_value.with_traceback(traceback) from exc_value
  File "/usr/local/lib/python3.10/site-packages/django/db/backends/utils.py", line 89, in _execute
    return self.cursor.execute(sql, params)
django.db.utils.ProgrammingError: column adds_post.views does not exist
LINE 1: ...ds_post"."wa_number", "adds_post"."is_activated", "adds_post...
                                                             ^

2022-09-21 13:08:51,831 [basehttp | ERROR] "GET /admin/adds/post/ HTTP/1.1" 500 148009 @ /usr/local/lib/python3.10/site-packages/django/core/servers/basehttp.py : 187 : log_message
2022-09-21 13:08:51,831 [basehttp | ERROR] "GET /admin/adds/post/ HTTP/1.1" 500 148009
2022-09-21 13:10:57,318 [log | ERROR] Internal Server Error: /admin/adds/post/ @ /usr/local/lib/python3.10/site-packages/django/utils/log.py : 241 : log_response
Traceback (most recent call last):
  File "/usr/local/lib/python3.10/site-packages/django/db/backends/utils.py", line 89, in _execute
    return self.cursor.execute(sql, params)
psycopg2.errors.UndefinedColumn: column adds_post.views does not exist
LINE 1: ...ds_post"."wa_number", "adds_post"."is_activated", "adds_post...
                                                             ^


The above exception was the direct cause of the following exception:

Traceback (most recent call last):
  File "/usr/local/lib/python3.10/site-packages/django/core/handlers/exception.py", line 55, in inner
    response = get_response(request)
  File "/usr/local/lib/python3.10/site-packages/django/core/handlers/base.py", line 197, in _get_response
    response = wrapped_callback(request, *callback_args, **callback_kwargs)
  File "/usr/local/lib/python3.10/site-packages/django/contrib/admin/options.py", line 683, in wrapper
    return self.admin_site.admin_view(view)(*args, **kwargs)
  File "/usr/local/lib/python3.10/site-packages/django/utils/decorators.py", line 133, in _wrapped_view
    response = view_func(request, *args, **kwargs)
  File "/usr/local/lib/python3.10/site-packages/django/views/decorators/cache.py", line 62, in _wrapped_view_func
    response = view_func(request, *args, **kwargs)
  File "/usr/local/lib/python3.10/site-packages/django/contrib/admin/sites.py", line 242, in inner
    return view(request, *args, **kwargs)
  File "/usr/local/lib/python3.10/site-packages/django/utils/decorators.py", line 46, in _wrapper
    return bound_method(*args, **kwargs)
  File "/usr/local/lib/python3.10/site-packages/django/utils/decorators.py", line 133, in _wrapped_view
    response = view_func(request, *args, **kwargs)
  File "/usr/local/lib/python3.10/site-packages/django/contrib/admin/options.py", line 2063, in changelist_view
    "selection_note": _("0 of %(cnt)s selected") % {"cnt": len(cl.result_list)},
  File "/usr/local/lib/python3.10/site-packages/django/db/models/query.py", line 302, in __len__
    self._fetch_all()
  File "/usr/local/lib/python3.10/site-packages/django/db/models/query.py", line 1507, in _fetch_all
    self._result_cache = list(self._iterable_class(self))
  File "/usr/local/lib/python3.10/site-packages/django/db/models/query.py", line 57, in __iter__
    results = compiler.execute_sql(
  File "/usr/local/lib/python3.10/site-packages/django/db/models/sql/compiler.py", line 1361, in execute_sql
    cursor.execute(sql, params)
  File "/usr/local/lib/python3.10/site-packages/django/db/backends/utils.py", line 103, in execute
    return super().execute(sql, params)
  File "/usr/local/lib/python3.10/site-packages/django/db/backends/utils.py", line 67, in execute
    return self._execute_with_wrappers(
  File "/usr/local/lib/python3.10/site-packages/django/db/backends/utils.py", line 80, in _execute_with_wrappers
    return executor(sql, params, many, context)
  File "/usr/local/lib/python3.10/site-packages/django/db/backends/utils.py", line 84, in _execute
    with self.db.wrap_database_errors:
  File "/usr/local/lib/python3.10/site-packages/django/db/utils.py", line 91, in __exit__
    raise dj_exc_value.with_traceback(traceback) from exc_value
  File "/usr/local/lib/python3.10/site-packages/django/db/backends/utils.py", line 89, in _execute
    return self.cursor.execute(sql, params)
django.db.utils.ProgrammingError: column adds_post.views does not exist
LINE 1: ...ds_post"."wa_number", "adds_post"."is_activated", "adds_post...
                                                             ^

2022-09-21 13:10:57,318 [log | ERROR] Internal Server Error: /admin/adds/post/
Traceback (most recent call last):
  File "/usr/local/lib/python3.10/site-packages/django/db/backends/utils.py", line 89, in _execute
    return self.cursor.execute(sql, params)
psycopg2.errors.UndefinedColumn: column adds_post.views does not exist
LINE 1: ...ds_post"."wa_number", "adds_post"."is_activated", "adds_post...
                                                             ^


The above exception was the direct cause of the following exception:

Traceback (most recent call last):
  File "/usr/local/lib/python3.10/site-packages/django/core/handlers/exception.py", line 55, in inner
    response = get_response(request)
  File "/usr/local/lib/python3.10/site-packages/django/core/handlers/base.py", line 197, in _get_response
    response = wrapped_callback(request, *callback_args, **callback_kwargs)
  File "/usr/local/lib/python3.10/site-packages/django/contrib/admin/options.py", line 683, in wrapper
    return self.admin_site.admin_view(view)(*args, **kwargs)
  File "/usr/local/lib/python3.10/site-packages/django/utils/decorators.py", line 133, in _wrapped_view
    response = view_func(request, *args, **kwargs)
  File "/usr/local/lib/python3.10/site-packages/django/views/decorators/cache.py", line 62, in _wrapped_view_func
    response = view_func(request, *args, **kwargs)
  File "/usr/local/lib/python3.10/site-packages/django/contrib/admin/sites.py", line 242, in inner
    return view(request, *args, **kwargs)
  File "/usr/local/lib/python3.10/site-packages/django/utils/decorators.py", line 46, in _wrapper
    return bound_method(*args, **kwargs)
  File "/usr/local/lib/python3.10/site-packages/django/utils/decorators.py", line 133, in _wrapped_view
    response = view_func(request, *args, **kwargs)
  File "/usr/local/lib/python3.10/site-packages/django/contrib/admin/options.py", line 2063, in changelist_view
    "selection_note": _("0 of %(cnt)s selected") % {"cnt": len(cl.result_list)},
  File "/usr/local/lib/python3.10/site-packages/django/db/models/query.py", line 302, in __len__
    self._fetch_all()
  File "/usr/local/lib/python3.10/site-packages/django/db/models/query.py", line 1507, in _fetch_all
    self._result_cache = list(self._iterable_class(self))
  File "/usr/local/lib/python3.10/site-packages/django/db/models/query.py", line 57, in __iter__
    results = compiler.execute_sql(
  File "/usr/local/lib/python3.10/site-packages/django/db/models/sql/compiler.py", line 1361, in execute_sql
    cursor.execute(sql, params)
  File "/usr/local/lib/python3.10/site-packages/django/db/backends/utils.py", line 103, in execute
    return super().execute(sql, params)
  File "/usr/local/lib/python3.10/site-packages/django/db/backends/utils.py", line 67, in execute
    return self._execute_with_wrappers(
  File "/usr/local/lib/python3.10/site-packages/django/db/backends/utils.py", line 80, in _execute_with_wrappers
    return executor(sql, params, many, context)
  File "/usr/local/lib/python3.10/site-packages/django/db/backends/utils.py", line 84, in _execute
    with self.db.wrap_database_errors:
  File "/usr/local/lib/python3.10/site-packages/django/db/utils.py", line 91, in __exit__
    raise dj_exc_value.with_traceback(traceback) from exc_value
  File "/usr/local/lib/python3.10/site-packages/django/db/backends/utils.py", line 89, in _execute
    return self.cursor.execute(sql, params)
django.db.utils.ProgrammingError: column adds_post.views does not exist
LINE 1: ...ds_post"."wa_number", "adds_post"."is_activated", "adds_post...
                                                             ^

2022-09-21 13:10:57,346 [basehttp | ERROR] "GET /admin/adds/post/ HTTP/1.1" 500 148146 @ /usr/local/lib/python3.10/site-packages/django/core/servers/basehttp.py : 187 : log_message
2022-09-21 13:10:57,346 [basehttp | ERROR] "GET /admin/adds/post/ HTTP/1.1" 500 148146
2022-09-21 13:10:59,537 [log | ERROR] Internal Server Error: /admin/adds/post/ @ /usr/local/lib/python3.10/site-packages/django/utils/log.py : 241 : log_response
Traceback (most recent call last):
  File "/usr/local/lib/python3.10/site-packages/django/db/backends/utils.py", line 89, in _execute
    return self.cursor.execute(sql, params)
psycopg2.errors.UndefinedColumn: column adds_post.views does not exist
LINE 1: ...ds_post"."wa_number", "adds_post"."is_activated", "adds_post...
                                                             ^


The above exception was the direct cause of the following exception:

Traceback (most recent call last):
  File "/usr/local/lib/python3.10/site-packages/django/core/handlers/exception.py", line 55, in inner
    response = get_response(request)
  File "/usr/local/lib/python3.10/site-packages/django/core/handlers/base.py", line 197, in _get_response
    response = wrapped_callback(request, *callback_args, **callback_kwargs)
  File "/usr/local/lib/python3.10/site-packages/django/contrib/admin/options.py", line 683, in wrapper
    return self.admin_site.admin_view(view)(*args, **kwargs)
  File "/usr/local/lib/python3.10/site-packages/django/utils/decorators.py", line 133, in _wrapped_view
    response = view_func(request, *args, **kwargs)
  File "/usr/local/lib/python3.10/site-packages/django/views/decorators/cache.py", line 62, in _wrapped_view_func
    response = view_func(request, *args, **kwargs)
  File "/usr/local/lib/python3.10/site-packages/django/contrib/admin/sites.py", line 242, in inner
    return view(request, *args, **kwargs)
  File "/usr/local/lib/python3.10/site-packages/django/utils/decorators.py", line 46, in _wrapper
    return bound_method(*args, **kwargs)
  File "/usr/local/lib/python3.10/site-packages/django/utils/decorators.py", line 133, in _wrapped_view
    response = view_func(request, *args, **kwargs)
  File "/usr/local/lib/python3.10/site-packages/django/contrib/admin/options.py", line 2063, in changelist_view
    "selection_note": _("0 of %(cnt)s selected") % {"cnt": len(cl.result_list)},
  File "/usr/local/lib/python3.10/site-packages/django/db/models/query.py", line 302, in __len__
    self._fetch_all()
  File "/usr/local/lib/python3.10/site-packages/django/db/models/query.py", line 1507, in _fetch_all
    self._result_cache = list(self._iterable_class(self))
  File "/usr/local/lib/python3.10/site-packages/django/db/models/query.py", line 57, in __iter__
    results = compiler.execute_sql(
  File "/usr/local/lib/python3.10/site-packages/django/db/models/sql/compiler.py", line 1361, in execute_sql
    cursor.execute(sql, params)
  File "/usr/local/lib/python3.10/site-packages/django/db/backends/utils.py", line 103, in execute
    return super().execute(sql, params)
  File "/usr/local/lib/python3.10/site-packages/django/db/backends/utils.py", line 67, in execute
    return self._execute_with_wrappers(
  File "/usr/local/lib/python3.10/site-packages/django/db/backends/utils.py", line 80, in _execute_with_wrappers
    return executor(sql, params, many, context)
  File "/usr/local/lib/python3.10/site-packages/django/db/backends/utils.py", line 84, in _execute
    with self.db.wrap_database_errors:
  File "/usr/local/lib/python3.10/site-packages/django/db/utils.py", line 91, in __exit__
    raise dj_exc_value.with_traceback(traceback) from exc_value
  File "/usr/local/lib/python3.10/site-packages/django/db/backends/utils.py", line 89, in _execute
    return self.cursor.execute(sql, params)
django.db.utils.ProgrammingError: column adds_post.views does not exist
LINE 1: ...ds_post"."wa_number", "adds_post"."is_activated", "adds_post...
                                                             ^

2022-09-21 13:10:59,537 [log | ERROR] Internal Server Error: /admin/adds/post/
Traceback (most recent call last):
  File "/usr/local/lib/python3.10/site-packages/django/db/backends/utils.py", line 89, in _execute
    return self.cursor.execute(sql, params)
psycopg2.errors.UndefinedColumn: column adds_post.views does not exist
LINE 1: ...ds_post"."wa_number", "adds_post"."is_activated", "adds_post...
                                                             ^


The above exception was the direct cause of the following exception:

Traceback (most recent call last):
  File "/usr/local/lib/python3.10/site-packages/django/core/handlers/exception.py", line 55, in inner
    response = get_response(request)
  File "/usr/local/lib/python3.10/site-packages/django/core/handlers/base.py", line 197, in _get_response
    response = wrapped_callback(request, *callback_args, **callback_kwargs)
  File "/usr/local/lib/python3.10/site-packages/django/contrib/admin/options.py", line 683, in wrapper
    return self.admin_site.admin_view(view)(*args, **kwargs)
  File "/usr/local/lib/python3.10/site-packages/django/utils/decorators.py", line 133, in _wrapped_view
    response = view_func(request, *args, **kwargs)
  File "/usr/local/lib/python3.10/site-packages/django/views/decorators/cache.py", line 62, in _wrapped_view_func
    response = view_func(request, *args, **kwargs)
  File "/usr/local/lib/python3.10/site-packages/django/contrib/admin/sites.py", line 242, in inner
    return view(request, *args, **kwargs)
  File "/usr/local/lib/python3.10/site-packages/django/utils/decorators.py", line 46, in _wrapper
    return bound_method(*args, **kwargs)
  File "/usr/local/lib/python3.10/site-packages/django/utils/decorators.py", line 133, in _wrapped_view
    response = view_func(request, *args, **kwargs)
  File "/usr/local/lib/python3.10/site-packages/django/contrib/admin/options.py", line 2063, in changelist_view
    "selection_note": _("0 of %(cnt)s selected") % {"cnt": len(cl.result_list)},
  File "/usr/local/lib/python3.10/site-packages/django/db/models/query.py", line 302, in __len__
    self._fetch_all()
  File "/usr/local/lib/python3.10/site-packages/django/db/models/query.py", line 1507, in _fetch_all
    self._result_cache = list(self._iterable_class(self))
  File "/usr/local/lib/python3.10/site-packages/django/db/models/query.py", line 57, in __iter__
    results = compiler.execute_sql(
  File "/usr/local/lib/python3.10/site-packages/django/db/models/sql/compiler.py", line 1361, in execute_sql
    cursor.execute(sql, params)
  File "/usr/local/lib/python3.10/site-packages/django/db/backends/utils.py", line 103, in execute
    return super().execute(sql, params)
  File "/usr/local/lib/python3.10/site-packages/django/db/backends/utils.py", line 67, in execute
    return self._execute_with_wrappers(
  File "/usr/local/lib/python3.10/site-packages/django/db/backends/utils.py", line 80, in _execute_with_wrappers
    return executor(sql, params, many, context)
  File "/usr/local/lib/python3.10/site-packages/django/db/backends/utils.py", line 84, in _execute
    with self.db.wrap_database_errors:
  File "/usr/local/lib/python3.10/site-packages/django/db/utils.py", line 91, in __exit__
    raise dj_exc_value.with_traceback(traceback) from exc_value
  File "/usr/local/lib/python3.10/site-packages/django/db/backends/utils.py", line 89, in _execute
    return self.cursor.execute(sql, params)
django.db.utils.ProgrammingError: column adds_post.views does not exist
LINE 1: ...ds_post"."wa_number", "adds_post"."is_activated", "adds_post...
                                                             ^

2022-09-21 13:10:59,557 [basehttp | ERROR] "GET /admin/adds/post/ HTTP/1.1" 500 148146 @ /usr/local/lib/python3.10/site-packages/django/core/servers/basehttp.py : 187 : log_message
2022-09-21 13:10:59,557 [basehttp | ERROR] "GET /admin/adds/post/ HTTP/1.1" 500 148146
2022-09-21 13:11:00,576 [log | ERROR] Internal Server Error: /admin/adds/post/ @ /usr/local/lib/python3.10/site-packages/django/utils/log.py : 241 : log_response
Traceback (most recent call last):
  File "/usr/local/lib/python3.10/site-packages/django/db/backends/utils.py", line 89, in _execute
    return self.cursor.execute(sql, params)
psycopg2.errors.UndefinedColumn: column adds_post.views does not exist
LINE 1: ...ds_post"."wa_number", "adds_post"."is_activated", "adds_post...
                                                             ^


The above exception was the direct cause of the following exception:

Traceback (most recent call last):
  File "/usr/local/lib/python3.10/site-packages/django/core/handlers/exception.py", line 55, in inner
    response = get_response(request)
  File "/usr/local/lib/python3.10/site-packages/django/core/handlers/base.py", line 197, in _get_response
    response = wrapped_callback(request, *callback_args, **callback_kwargs)
  File "/usr/local/lib/python3.10/site-packages/django/contrib/admin/options.py", line 683, in wrapper
    return self.admin_site.admin_view(view)(*args, **kwargs)
  File "/usr/local/lib/python3.10/site-packages/django/utils/decorators.py", line 133, in _wrapped_view
    response = view_func(request, *args, **kwargs)
  File "/usr/local/lib/python3.10/site-packages/django/views/decorators/cache.py", line 62, in _wrapped_view_func
    response = view_func(request, *args, **kwargs)
  File "/usr/local/lib/python3.10/site-packages/django/contrib/admin/sites.py", line 242, in inner
    return view(request, *args, **kwargs)
  File "/usr/local/lib/python3.10/site-packages/django/utils/decorators.py", line 46, in _wrapper
    return bound_method(*args, **kwargs)
  File "/usr/local/lib/python3.10/site-packages/django/utils/decorators.py", line 133, in _wrapped_view
    response = view_func(request, *args, **kwargs)
  File "/usr/local/lib/python3.10/site-packages/django/contrib/admin/options.py", line 2063, in changelist_view
    "selection_note": _("0 of %(cnt)s selected") % {"cnt": len(cl.result_list)},
  File "/usr/local/lib/python3.10/site-packages/django/db/models/query.py", line 302, in __len__
    self._fetch_all()
  File "/usr/local/lib/python3.10/site-packages/django/db/models/query.py", line 1507, in _fetch_all
    self._result_cache = list(self._iterable_class(self))
  File "/usr/local/lib/python3.10/site-packages/django/db/models/query.py", line 57, in __iter__
    results = compiler.execute_sql(
  File "/usr/local/lib/python3.10/site-packages/django/db/models/sql/compiler.py", line 1361, in execute_sql
    cursor.execute(sql, params)
  File "/usr/local/lib/python3.10/site-packages/django/db/backends/utils.py", line 103, in execute
    return super().execute(sql, params)
  File "/usr/local/lib/python3.10/site-packages/django/db/backends/utils.py", line 67, in execute
    return self._execute_with_wrappers(
  File "/usr/local/lib/python3.10/site-packages/django/db/backends/utils.py", line 80, in _execute_with_wrappers
    return executor(sql, params, many, context)
  File "/usr/local/lib/python3.10/site-packages/django/db/backends/utils.py", line 84, in _execute
    with self.db.wrap_database_errors:
  File "/usr/local/lib/python3.10/site-packages/django/db/utils.py", line 91, in __exit__
    raise dj_exc_value.with_traceback(traceback) from exc_value
  File "/usr/local/lib/python3.10/site-packages/django/db/backends/utils.py", line 89, in _execute
    return self.cursor.execute(sql, params)
django.db.utils.ProgrammingError: column adds_post.views does not exist
LINE 1: ...ds_post"."wa_number", "adds_post"."is_activated", "adds_post...
                                                             ^

2022-09-21 13:11:00,576 [log | ERROR] Internal Server Error: /admin/adds/post/
Traceback (most recent call last):
  File "/usr/local/lib/python3.10/site-packages/django/db/backends/utils.py", line 89, in _execute
    return self.cursor.execute(sql, params)
psycopg2.errors.UndefinedColumn: column adds_post.views does not exist
LINE 1: ...ds_post"."wa_number", "adds_post"."is_activated", "adds_post...
                                                             ^


The above exception was the direct cause of the following exception:

Traceback (most recent call last):
  File "/usr/local/lib/python3.10/site-packages/django/core/handlers/exception.py", line 55, in inner
    response = get_response(request)
  File "/usr/local/lib/python3.10/site-packages/django/core/handlers/base.py", line 197, in _get_response
    response = wrapped_callback(request, *callback_args, **callback_kwargs)
  File "/usr/local/lib/python3.10/site-packages/django/contrib/admin/options.py", line 683, in wrapper
    return self.admin_site.admin_view(view)(*args, **kwargs)
  File "/usr/local/lib/python3.10/site-packages/django/utils/decorators.py", line 133, in _wrapped_view
    response = view_func(request, *args, **kwargs)
  File "/usr/local/lib/python3.10/site-packages/django/views/decorators/cache.py", line 62, in _wrapped_view_func
    response = view_func(request, *args, **kwargs)
  File "/usr/local/lib/python3.10/site-packages/django/contrib/admin/sites.py", line 242, in inner
    return view(request, *args, **kwargs)
  File "/usr/local/lib/python3.10/site-packages/django/utils/decorators.py", line 46, in _wrapper
    return bound_method(*args, **kwargs)
  File "/usr/local/lib/python3.10/site-packages/django/utils/decorators.py", line 133, in _wrapped_view
    response = view_func(request, *args, **kwargs)
  File "/usr/local/lib/python3.10/site-packages/django/contrib/admin/options.py", line 2063, in changelist_view
    "selection_note": _("0 of %(cnt)s selected") % {"cnt": len(cl.result_list)},
  File "/usr/local/lib/python3.10/site-packages/django/db/models/query.py", line 302, in __len__
    self._fetch_all()
  File "/usr/local/lib/python3.10/site-packages/django/db/models/query.py", line 1507, in _fetch_all
    self._result_cache = list(self._iterable_class(self))
  File "/usr/local/lib/python3.10/site-packages/django/db/models/query.py", line 57, in __iter__
    results = compiler.execute_sql(
  File "/usr/local/lib/python3.10/site-packages/django/db/models/sql/compiler.py", line 1361, in execute_sql
    cursor.execute(sql, params)
  File "/usr/local/lib/python3.10/site-packages/django/db/backends/utils.py", line 103, in execute
    return super().execute(sql, params)
  File "/usr/local/lib/python3.10/site-packages/django/db/backends/utils.py", line 67, in execute
    return self._execute_with_wrappers(
  File "/usr/local/lib/python3.10/site-packages/django/db/backends/utils.py", line 80, in _execute_with_wrappers
    return executor(sql, params, many, context)
  File "/usr/local/lib/python3.10/site-packages/django/db/backends/utils.py", line 84, in _execute
    with self.db.wrap_database_errors:
  File "/usr/local/lib/python3.10/site-packages/django/db/utils.py", line 91, in __exit__
    raise dj_exc_value.with_traceback(traceback) from exc_value
  File "/usr/local/lib/python3.10/site-packages/django/db/backends/utils.py", line 89, in _execute
    return self.cursor.execute(sql, params)
django.db.utils.ProgrammingError: column adds_post.views does not exist
LINE 1: ...ds_post"."wa_number", "adds_post"."is_activated", "adds_post...
                                                             ^

2022-09-21 13:11:00,601 [basehttp | ERROR] "GET /admin/adds/post/ HTTP/1.1" 500 148146 @ /usr/local/lib/python3.10/site-packages/django/core/servers/basehttp.py : 187 : log_message
2022-09-21 13:11:00,601 [basehttp | ERROR] "GET /admin/adds/post/ HTTP/1.1" 500 148146
2022-09-21 13:11:02,041 [log | ERROR] Internal Server Error: /admin/adds/post/ @ /usr/local/lib/python3.10/site-packages/django/utils/log.py : 241 : log_response
Traceback (most recent call last):
  File "/usr/local/lib/python3.10/site-packages/django/db/backends/utils.py", line 89, in _execute
    return self.cursor.execute(sql, params)
psycopg2.errors.UndefinedColumn: column adds_post.views does not exist
LINE 1: ...ds_post"."wa_number", "adds_post"."is_activated", "adds_post...
                                                             ^


The above exception was the direct cause of the following exception:

Traceback (most recent call last):
  File "/usr/local/lib/python3.10/site-packages/django/core/handlers/exception.py", line 55, in inner
    response = get_response(request)
  File "/usr/local/lib/python3.10/site-packages/django/core/handlers/base.py", line 197, in _get_response
    response = wrapped_callback(request, *callback_args, **callback_kwargs)
  File "/usr/local/lib/python3.10/site-packages/django/contrib/admin/options.py", line 683, in wrapper
    return self.admin_site.admin_view(view)(*args, **kwargs)
  File "/usr/local/lib/python3.10/site-packages/django/utils/decorators.py", line 133, in _wrapped_view
    response = view_func(request, *args, **kwargs)
  File "/usr/local/lib/python3.10/site-packages/django/views/decorators/cache.py", line 62, in _wrapped_view_func
    response = view_func(request, *args, **kwargs)
  File "/usr/local/lib/python3.10/site-packages/django/contrib/admin/sites.py", line 242, in inner
    return view(request, *args, **kwargs)
  File "/usr/local/lib/python3.10/site-packages/django/utils/decorators.py", line 46, in _wrapper
    return bound_method(*args, **kwargs)
  File "/usr/local/lib/python3.10/site-packages/django/utils/decorators.py", line 133, in _wrapped_view
    response = view_func(request, *args, **kwargs)
  File "/usr/local/lib/python3.10/site-packages/django/contrib/admin/options.py", line 2063, in changelist_view
    "selection_note": _("0 of %(cnt)s selected") % {"cnt": len(cl.result_list)},
  File "/usr/local/lib/python3.10/site-packages/django/db/models/query.py", line 302, in __len__
    self._fetch_all()
  File "/usr/local/lib/python3.10/site-packages/django/db/models/query.py", line 1507, in _fetch_all
    self._result_cache = list(self._iterable_class(self))
  File "/usr/local/lib/python3.10/site-packages/django/db/models/query.py", line 57, in __iter__
    results = compiler.execute_sql(
  File "/usr/local/lib/python3.10/site-packages/django/db/models/sql/compiler.py", line 1361, in execute_sql
    cursor.execute(sql, params)
  File "/usr/local/lib/python3.10/site-packages/django/db/backends/utils.py", line 103, in execute
    return super().execute(sql, params)
  File "/usr/local/lib/python3.10/site-packages/django/db/backends/utils.py", line 67, in execute
    return self._execute_with_wrappers(
  File "/usr/local/lib/python3.10/site-packages/django/db/backends/utils.py", line 80, in _execute_with_wrappers
    return executor(sql, params, many, context)
  File "/usr/local/lib/python3.10/site-packages/django/db/backends/utils.py", line 84, in _execute
    with self.db.wrap_database_errors:
  File "/usr/local/lib/python3.10/site-packages/django/db/utils.py", line 91, in __exit__
    raise dj_exc_value.with_traceback(traceback) from exc_value
  File "/usr/local/lib/python3.10/site-packages/django/db/backends/utils.py", line 89, in _execute
    return self.cursor.execute(sql, params)
django.db.utils.ProgrammingError: column adds_post.views does not exist
LINE 1: ...ds_post"."wa_number", "adds_post"."is_activated", "adds_post...
                                                             ^

2022-09-21 13:11:02,041 [log | ERROR] Internal Server Error: /admin/adds/post/
Traceback (most recent call last):
  File "/usr/local/lib/python3.10/site-packages/django/db/backends/utils.py", line 89, in _execute
    return self.cursor.execute(sql, params)
psycopg2.errors.UndefinedColumn: column adds_post.views does not exist
LINE 1: ...ds_post"."wa_number", "adds_post"."is_activated", "adds_post...
                                                             ^


The above exception was the direct cause of the following exception:

Traceback (most recent call last):
  File "/usr/local/lib/python3.10/site-packages/django/core/handlers/exception.py", line 55, in inner
    response = get_response(request)
  File "/usr/local/lib/python3.10/site-packages/django/core/handlers/base.py", line 197, in _get_response
    response = wrapped_callback(request, *callback_args, **callback_kwargs)
  File "/usr/local/lib/python3.10/site-packages/django/contrib/admin/options.py", line 683, in wrapper
    return self.admin_site.admin_view(view)(*args, **kwargs)
  File "/usr/local/lib/python3.10/site-packages/django/utils/decorators.py", line 133, in _wrapped_view
    response = view_func(request, *args, **kwargs)
  File "/usr/local/lib/python3.10/site-packages/django/views/decorators/cache.py", line 62, in _wrapped_view_func
    response = view_func(request, *args, **kwargs)
  File "/usr/local/lib/python3.10/site-packages/django/contrib/admin/sites.py", line 242, in inner
    return view(request, *args, **kwargs)
  File "/usr/local/lib/python3.10/site-packages/django/utils/decorators.py", line 46, in _wrapper
    return bound_method(*args, **kwargs)
  File "/usr/local/lib/python3.10/site-packages/django/utils/decorators.py", line 133, in _wrapped_view
    response = view_func(request, *args, **kwargs)
  File "/usr/local/lib/python3.10/site-packages/django/contrib/admin/options.py", line 2063, in changelist_view
    "selection_note": _("0 of %(cnt)s selected") % {"cnt": len(cl.result_list)},
  File "/usr/local/lib/python3.10/site-packages/django/db/models/query.py", line 302, in __len__
    self._fetch_all()
  File "/usr/local/lib/python3.10/site-packages/django/db/models/query.py", line 1507, in _fetch_all
    self._result_cache = list(self._iterable_class(self))
  File "/usr/local/lib/python3.10/site-packages/django/db/models/query.py", line 57, in __iter__
    results = compiler.execute_sql(
  File "/usr/local/lib/python3.10/site-packages/django/db/models/sql/compiler.py", line 1361, in execute_sql
    cursor.execute(sql, params)
  File "/usr/local/lib/python3.10/site-packages/django/db/backends/utils.py", line 103, in execute
    return super().execute(sql, params)
  File "/usr/local/lib/python3.10/site-packages/django/db/backends/utils.py", line 67, in execute
    return self._execute_with_wrappers(
  File "/usr/local/lib/python3.10/site-packages/django/db/backends/utils.py", line 80, in _execute_with_wrappers
    return executor(sql, params, many, context)
  File "/usr/local/lib/python3.10/site-packages/django/db/backends/utils.py", line 84, in _execute
    with self.db.wrap_database_errors:
  File "/usr/local/lib/python3.10/site-packages/django/db/utils.py", line 91, in __exit__
    raise dj_exc_value.with_traceback(traceback) from exc_value
  File "/usr/local/lib/python3.10/site-packages/django/db/backends/utils.py", line 89, in _execute
    return self.cursor.execute(sql, params)
django.db.utils.ProgrammingError: column adds_post.views does not exist
LINE 1: ...ds_post"."wa_number", "adds_post"."is_activated", "adds_post...
                                                             ^

2022-09-21 13:11:02,054 [basehttp | ERROR] "GET /admin/adds/post/ HTTP/1.1" 500 148146 @ /usr/local/lib/python3.10/site-packages/django/core/servers/basehttp.py : 187 : log_message
2022-09-21 13:11:02,054 [basehttp | ERROR] "GET /admin/adds/post/ HTTP/1.1" 500 148146
2022-09-21 13:11:03,521 [basehttp | INFO] "GET /admin/adds/city/ HTTP/1.1" 200 13054
2022-09-21 13:11:05,733 [basehttp | INFO] "GET /admin/adds/city/ HTTP/1.1" 200 13054
2022-09-21 13:11:05,787 [basehttp | INFO] "GET /static/admin/css/base.css HTTP/1.1" 304 0
2022-09-21 13:11:05,811 [basehttp | INFO] "GET /static/admin/js/vendor/jquery/jquery.js HTTP/1.1" 304 0
2022-09-21 13:11:05,826 [basehttp | INFO] "GET /static/admin/css/changelists.css HTTP/1.1" 304 0
2022-09-21 13:11:05,849 [basehttp | INFO] "GET /static/admin/css/fonts.css HTTP/1.1" 304 0
2022-09-21 13:11:05,852 [basehttp | INFO] "GET /static/admin/css/nav_sidebar.css HTTP/1.1" 304 0
2022-09-21 13:11:05,857 [basehttp | INFO] "GET /static/admin/js/core.js HTTP/1.1" 304 0
2022-09-21 13:11:05,857 [basehttp | INFO] "GET /static/admin/js/jquery.init.js HTTP/1.1" 304 0
2022-09-21 13:11:05,860 [basehttp | INFO] "GET /static/admin/css/responsive.css HTTP/1.1" 304 0
2022-09-21 13:11:05,875 [basehttp | INFO] "GET /static/admin/js/admin/RelatedObjectLookups.js HTTP/1.1" 304 0
2022-09-21 13:11:05,881 [basehttp | INFO] "GET /static/admin/js/prepopulate.js HTTP/1.1" 304 0
2022-09-21 13:11:05,887 [basehttp | INFO] "GET /static/admin/js/urlify.js HTTP/1.1" 304 0
2022-09-21 13:11:05,895 [basehttp | INFO] "GET /static/admin/js/vendor/xregexp/xregexp.js HTTP/1.1" 304 0
2022-09-21 13:11:05,907 [basehttp | INFO] "GET /static/admin/js/actions.js HTTP/1.1" 304 0
2022-09-21 13:11:05,922 [basehttp | INFO] "GET /admin/jsi18n/ HTTP/1.1" 200 3343
2022-09-21 13:11:05,935 [basehttp | INFO] "GET /static/admin/js/nav_sidebar.js HTTP/1.1" 304 0
2022-09-21 13:11:05,953 [basehttp | INFO] "GET /static/admin/fonts/Roboto-Regular-webfont.woff HTTP/1.1" 304 0
2022-09-21 13:11:05,966 [basehttp | INFO] "GET /static/admin/img/icon-addlink.svg HTTP/1.1" 304 0
2022-09-21 13:11:05,966 [basehttp | INFO] "GET /static/admin/fonts/Roboto-Bold-webfont.woff HTTP/1.1" 304 0
2022-09-21 13:11:05,966 [basehttp | INFO] "GET /static/admin/fonts/Roboto-Light-webfont.woff HTTP/1.1" 304 0
2022-09-21 13:11:05,970 [basehttp | INFO] "GET /static/admin/img/tooltag-add.svg HTTP/1.1" 304 0
2022-09-21 13:11:07,922 [log | ERROR] Internal Server Error: /admin/adds/post/ @ /usr/local/lib/python3.10/site-packages/django/utils/log.py : 241 : log_response
Traceback (most recent call last):
  File "/usr/local/lib/python3.10/site-packages/django/db/backends/utils.py", line 89, in _execute
    return self.cursor.execute(sql, params)
psycopg2.errors.UndefinedColumn: column adds_post.views does not exist
LINE 1: ...ds_post"."wa_number", "adds_post"."is_activated", "adds_post...
                                                             ^


The above exception was the direct cause of the following exception:

Traceback (most recent call last):
  File "/usr/local/lib/python3.10/site-packages/django/core/handlers/exception.py", line 55, in inner
    response = get_response(request)
  File "/usr/local/lib/python3.10/site-packages/django/core/handlers/base.py", line 197, in _get_response
    response = wrapped_callback(request, *callback_args, **callback_kwargs)
  File "/usr/local/lib/python3.10/site-packages/django/contrib/admin/options.py", line 683, in wrapper
    return self.admin_site.admin_view(view)(*args, **kwargs)
  File "/usr/local/lib/python3.10/site-packages/django/utils/decorators.py", line 133, in _wrapped_view
    response = view_func(request, *args, **kwargs)
  File "/usr/local/lib/python3.10/site-packages/django/views/decorators/cache.py", line 62, in _wrapped_view_func
    response = view_func(request, *args, **kwargs)
  File "/usr/local/lib/python3.10/site-packages/django/contrib/admin/sites.py", line 242, in inner
    return view(request, *args, **kwargs)
  File "/usr/local/lib/python3.10/site-packages/django/utils/decorators.py", line 46, in _wrapper
    return bound_method(*args, **kwargs)
  File "/usr/local/lib/python3.10/site-packages/django/utils/decorators.py", line 133, in _wrapped_view
    response = view_func(request, *args, **kwargs)
  File "/usr/local/lib/python3.10/site-packages/django/contrib/admin/options.py", line 2063, in changelist_view
    "selection_note": _("0 of %(cnt)s selected") % {"cnt": len(cl.result_list)},
  File "/usr/local/lib/python3.10/site-packages/django/db/models/query.py", line 302, in __len__
    self._fetch_all()
  File "/usr/local/lib/python3.10/site-packages/django/db/models/query.py", line 1507, in _fetch_all
    self._result_cache = list(self._iterable_class(self))
  File "/usr/local/lib/python3.10/site-packages/django/db/models/query.py", line 57, in __iter__
    results = compiler.execute_sql(
  File "/usr/local/lib/python3.10/site-packages/django/db/models/sql/compiler.py", line 1361, in execute_sql
    cursor.execute(sql, params)
  File "/usr/local/lib/python3.10/site-packages/django/db/backends/utils.py", line 103, in execute
    return super().execute(sql, params)
  File "/usr/local/lib/python3.10/site-packages/django/db/backends/utils.py", line 67, in execute
    return self._execute_with_wrappers(
  File "/usr/local/lib/python3.10/site-packages/django/db/backends/utils.py", line 80, in _execute_with_wrappers
    return executor(sql, params, many, context)
  File "/usr/local/lib/python3.10/site-packages/django/db/backends/utils.py", line 84, in _execute
    with self.db.wrap_database_errors:
  File "/usr/local/lib/python3.10/site-packages/django/db/utils.py", line 91, in __exit__
    raise dj_exc_value.with_traceback(traceback) from exc_value
  File "/usr/local/lib/python3.10/site-packages/django/db/backends/utils.py", line 89, in _execute
    return self.cursor.execute(sql, params)
django.db.utils.ProgrammingError: column adds_post.views does not exist
LINE 1: ...ds_post"."wa_number", "adds_post"."is_activated", "adds_post...
                                                             ^

2022-09-21 13:11:07,922 [log | ERROR] Internal Server Error: /admin/adds/post/
Traceback (most recent call last):
  File "/usr/local/lib/python3.10/site-packages/django/db/backends/utils.py", line 89, in _execute
    return self.cursor.execute(sql, params)
psycopg2.errors.UndefinedColumn: column adds_post.views does not exist
LINE 1: ...ds_post"."wa_number", "adds_post"."is_activated", "adds_post...
                                                             ^


The above exception was the direct cause of the following exception:

Traceback (most recent call last):
  File "/usr/local/lib/python3.10/site-packages/django/core/handlers/exception.py", line 55, in inner
    response = get_response(request)
  File "/usr/local/lib/python3.10/site-packages/django/core/handlers/base.py", line 197, in _get_response
    response = wrapped_callback(request, *callback_args, **callback_kwargs)
  File "/usr/local/lib/python3.10/site-packages/django/contrib/admin/options.py", line 683, in wrapper
    return self.admin_site.admin_view(view)(*args, **kwargs)
  File "/usr/local/lib/python3.10/site-packages/django/utils/decorators.py", line 133, in _wrapped_view
    response = view_func(request, *args, **kwargs)
  File "/usr/local/lib/python3.10/site-packages/django/views/decorators/cache.py", line 62, in _wrapped_view_func
    response = view_func(request, *args, **kwargs)
  File "/usr/local/lib/python3.10/site-packages/django/contrib/admin/sites.py", line 242, in inner
    return view(request, *args, **kwargs)
  File "/usr/local/lib/python3.10/site-packages/django/utils/decorators.py", line 46, in _wrapper
    return bound_method(*args, **kwargs)
  File "/usr/local/lib/python3.10/site-packages/django/utils/decorators.py", line 133, in _wrapped_view
    response = view_func(request, *args, **kwargs)
  File "/usr/local/lib/python3.10/site-packages/django/contrib/admin/options.py", line 2063, in changelist_view
    "selection_note": _("0 of %(cnt)s selected") % {"cnt": len(cl.result_list)},
  File "/usr/local/lib/python3.10/site-packages/django/db/models/query.py", line 302, in __len__
    self._fetch_all()
  File "/usr/local/lib/python3.10/site-packages/django/db/models/query.py", line 1507, in _fetch_all
    self._result_cache = list(self._iterable_class(self))
  File "/usr/local/lib/python3.10/site-packages/django/db/models/query.py", line 57, in __iter__
    results = compiler.execute_sql(
  File "/usr/local/lib/python3.10/site-packages/django/db/models/sql/compiler.py", line 1361, in execute_sql
    cursor.execute(sql, params)
  File "/usr/local/lib/python3.10/site-packages/django/db/backends/utils.py", line 103, in execute
    return super().execute(sql, params)
  File "/usr/local/lib/python3.10/site-packages/django/db/backends/utils.py", line 67, in execute
    return self._execute_with_wrappers(
  File "/usr/local/lib/python3.10/site-packages/django/db/backends/utils.py", line 80, in _execute_with_wrappers
    return executor(sql, params, many, context)
  File "/usr/local/lib/python3.10/site-packages/django/db/backends/utils.py", line 84, in _execute
    with self.db.wrap_database_errors:
  File "/usr/local/lib/python3.10/site-packages/django/db/utils.py", line 91, in __exit__
    raise dj_exc_value.with_traceback(traceback) from exc_value
  File "/usr/local/lib/python3.10/site-packages/django/db/backends/utils.py", line 89, in _execute
    return self.cursor.execute(sql, params)
django.db.utils.ProgrammingError: column adds_post.views does not exist
LINE 1: ...ds_post"."wa_number", "adds_post"."is_activated", "adds_post...
                                                             ^

2022-09-21 13:11:07,930 [basehttp | ERROR] "GET /admin/adds/post/ HTTP/1.1" 500 148009 @ /usr/local/lib/python3.10/site-packages/django/core/servers/basehttp.py : 187 : log_message
2022-09-21 13:11:07,930 [basehttp | ERROR] "GET /admin/adds/post/ HTTP/1.1" 500 148009
2022-09-21 13:11:14,148 [log | ERROR] Internal Server Error: /admin/adds/post/ @ /usr/local/lib/python3.10/site-packages/django/utils/log.py : 241 : log_response
Traceback (most recent call last):
  File "/usr/local/lib/python3.10/site-packages/django/db/backends/utils.py", line 89, in _execute
    return self.cursor.execute(sql, params)
psycopg2.errors.UndefinedColumn: column adds_post.views does not exist
LINE 1: ...ds_post"."wa_number", "adds_post"."is_activated", "adds_post...
                                                             ^


The above exception was the direct cause of the following exception:

Traceback (most recent call last):
  File "/usr/local/lib/python3.10/site-packages/django/core/handlers/exception.py", line 55, in inner
    response = get_response(request)
  File "/usr/local/lib/python3.10/site-packages/django/core/handlers/base.py", line 197, in _get_response
    response = wrapped_callback(request, *callback_args, **callback_kwargs)
  File "/usr/local/lib/python3.10/site-packages/django/contrib/admin/options.py", line 683, in wrapper
    return self.admin_site.admin_view(view)(*args, **kwargs)
  File "/usr/local/lib/python3.10/site-packages/django/utils/decorators.py", line 133, in _wrapped_view
    response = view_func(request, *args, **kwargs)
  File "/usr/local/lib/python3.10/site-packages/django/views/decorators/cache.py", line 62, in _wrapped_view_func
    response = view_func(request, *args, **kwargs)
  File "/usr/local/lib/python3.10/site-packages/django/contrib/admin/sites.py", line 242, in inner
    return view(request, *args, **kwargs)
  File "/usr/local/lib/python3.10/site-packages/django/utils/decorators.py", line 46, in _wrapper
    return bound_method(*args, **kwargs)
  File "/usr/local/lib/python3.10/site-packages/django/utils/decorators.py", line 133, in _wrapped_view
    response = view_func(request, *args, **kwargs)
  File "/usr/local/lib/python3.10/site-packages/django/contrib/admin/options.py", line 2063, in changelist_view
    "selection_note": _("0 of %(cnt)s selected") % {"cnt": len(cl.result_list)},
  File "/usr/local/lib/python3.10/site-packages/django/db/models/query.py", line 302, in __len__
    self._fetch_all()
  File "/usr/local/lib/python3.10/site-packages/django/db/models/query.py", line 1507, in _fetch_all
    self._result_cache = list(self._iterable_class(self))
  File "/usr/local/lib/python3.10/site-packages/django/db/models/query.py", line 57, in __iter__
    results = compiler.execute_sql(
  File "/usr/local/lib/python3.10/site-packages/django/db/models/sql/compiler.py", line 1361, in execute_sql
    cursor.execute(sql, params)
  File "/usr/local/lib/python3.10/site-packages/django/db/backends/utils.py", line 103, in execute
    return super().execute(sql, params)
  File "/usr/local/lib/python3.10/site-packages/django/db/backends/utils.py", line 67, in execute
    return self._execute_with_wrappers(
  File "/usr/local/lib/python3.10/site-packages/django/db/backends/utils.py", line 80, in _execute_with_wrappers
    return executor(sql, params, many, context)
  File "/usr/local/lib/python3.10/site-packages/django/db/backends/utils.py", line 84, in _execute
    with self.db.wrap_database_errors:
  File "/usr/local/lib/python3.10/site-packages/django/db/utils.py", line 91, in __exit__
    raise dj_exc_value.with_traceback(traceback) from exc_value
  File "/usr/local/lib/python3.10/site-packages/django/db/backends/utils.py", line 89, in _execute
    return self.cursor.execute(sql, params)
django.db.utils.ProgrammingError: column adds_post.views does not exist
LINE 1: ...ds_post"."wa_number", "adds_post"."is_activated", "adds_post...
                                                             ^

2022-09-21 13:11:14,148 [log | ERROR] Internal Server Error: /admin/adds/post/
Traceback (most recent call last):
  File "/usr/local/lib/python3.10/site-packages/django/db/backends/utils.py", line 89, in _execute
    return self.cursor.execute(sql, params)
psycopg2.errors.UndefinedColumn: column adds_post.views does not exist
LINE 1: ...ds_post"."wa_number", "adds_post"."is_activated", "adds_post...
                                                             ^


The above exception was the direct cause of the following exception:

Traceback (most recent call last):
  File "/usr/local/lib/python3.10/site-packages/django/core/handlers/exception.py", line 55, in inner
    response = get_response(request)
  File "/usr/local/lib/python3.10/site-packages/django/core/handlers/base.py", line 197, in _get_response
    response = wrapped_callback(request, *callback_args, **callback_kwargs)
  File "/usr/local/lib/python3.10/site-packages/django/contrib/admin/options.py", line 683, in wrapper
    return self.admin_site.admin_view(view)(*args, **kwargs)
  File "/usr/local/lib/python3.10/site-packages/django/utils/decorators.py", line 133, in _wrapped_view
    response = view_func(request, *args, **kwargs)
  File "/usr/local/lib/python3.10/site-packages/django/views/decorators/cache.py", line 62, in _wrapped_view_func
    response = view_func(request, *args, **kwargs)
  File "/usr/local/lib/python3.10/site-packages/django/contrib/admin/sites.py", line 242, in inner
    return view(request, *args, **kwargs)
  File "/usr/local/lib/python3.10/site-packages/django/utils/decorators.py", line 46, in _wrapper
    return bound_method(*args, **kwargs)
  File "/usr/local/lib/python3.10/site-packages/django/utils/decorators.py", line 133, in _wrapped_view
    response = view_func(request, *args, **kwargs)
  File "/usr/local/lib/python3.10/site-packages/django/contrib/admin/options.py", line 2063, in changelist_view
    "selection_note": _("0 of %(cnt)s selected") % {"cnt": len(cl.result_list)},
  File "/usr/local/lib/python3.10/site-packages/django/db/models/query.py", line 302, in __len__
    self._fetch_all()
  File "/usr/local/lib/python3.10/site-packages/django/db/models/query.py", line 1507, in _fetch_all
    self._result_cache = list(self._iterable_class(self))
  File "/usr/local/lib/python3.10/site-packages/django/db/models/query.py", line 57, in __iter__
    results = compiler.execute_sql(
  File "/usr/local/lib/python3.10/site-packages/django/db/models/sql/compiler.py", line 1361, in execute_sql
    cursor.execute(sql, params)
  File "/usr/local/lib/python3.10/site-packages/django/db/backends/utils.py", line 103, in execute
    return super().execute(sql, params)
  File "/usr/local/lib/python3.10/site-packages/django/db/backends/utils.py", line 67, in execute
    return self._execute_with_wrappers(
  File "/usr/local/lib/python3.10/site-packages/django/db/backends/utils.py", line 80, in _execute_with_wrappers
    return executor(sql, params, many, context)
  File "/usr/local/lib/python3.10/site-packages/django/db/backends/utils.py", line 84, in _execute
    with self.db.wrap_database_errors:
  File "/usr/local/lib/python3.10/site-packages/django/db/utils.py", line 91, in __exit__
    raise dj_exc_value.with_traceback(traceback) from exc_value
  File "/usr/local/lib/python3.10/site-packages/django/db/backends/utils.py", line 89, in _execute
    return self.cursor.execute(sql, params)
django.db.utils.ProgrammingError: column adds_post.views does not exist
LINE 1: ...ds_post"."wa_number", "adds_post"."is_activated", "adds_post...
                                                             ^

2022-09-21 13:11:14,157 [basehttp | ERROR] "GET /admin/adds/post/ HTTP/1.1" 500 148146 @ /usr/local/lib/python3.10/site-packages/django/core/servers/basehttp.py : 187 : log_message
2022-09-21 13:11:14,157 [basehttp | ERROR] "GET /admin/adds/post/ HTTP/1.1" 500 148146
2022-09-21 13:11:40,308 [basehttp | INFO] "GET /admin/adds/city/ HTTP/1.1" 200 13054
2022-09-21 13:11:42,171 [log | ERROR] Internal Server Error: /admin/adds/post/ @ /usr/local/lib/python3.10/site-packages/django/utils/log.py : 241 : log_response
Traceback (most recent call last):
  File "/usr/local/lib/python3.10/site-packages/django/db/backends/utils.py", line 89, in _execute
    return self.cursor.execute(sql, params)
psycopg2.errors.UndefinedColumn: column adds_post.views does not exist
LINE 1: ...ds_post"."wa_number", "adds_post"."is_activated", "adds_post...
                                                             ^


The above exception was the direct cause of the following exception:

Traceback (most recent call last):
  File "/usr/local/lib/python3.10/site-packages/django/core/handlers/exception.py", line 55, in inner
    response = get_response(request)
  File "/usr/local/lib/python3.10/site-packages/django/core/handlers/base.py", line 197, in _get_response
    response = wrapped_callback(request, *callback_args, **callback_kwargs)
  File "/usr/local/lib/python3.10/site-packages/django/contrib/admin/options.py", line 683, in wrapper
    return self.admin_site.admin_view(view)(*args, **kwargs)
  File "/usr/local/lib/python3.10/site-packages/django/utils/decorators.py", line 133, in _wrapped_view
    response = view_func(request, *args, **kwargs)
  File "/usr/local/lib/python3.10/site-packages/django/views/decorators/cache.py", line 62, in _wrapped_view_func
    response = view_func(request, *args, **kwargs)
  File "/usr/local/lib/python3.10/site-packages/django/contrib/admin/sites.py", line 242, in inner
    return view(request, *args, **kwargs)
  File "/usr/local/lib/python3.10/site-packages/django/utils/decorators.py", line 46, in _wrapper
    return bound_method(*args, **kwargs)
  File "/usr/local/lib/python3.10/site-packages/django/utils/decorators.py", line 133, in _wrapped_view
    response = view_func(request, *args, **kwargs)
  File "/usr/local/lib/python3.10/site-packages/django/contrib/admin/options.py", line 2063, in changelist_view
    "selection_note": _("0 of %(cnt)s selected") % {"cnt": len(cl.result_list)},
  File "/usr/local/lib/python3.10/site-packages/django/db/models/query.py", line 302, in __len__
    self._fetch_all()
  File "/usr/local/lib/python3.10/site-packages/django/db/models/query.py", line 1507, in _fetch_all
    self._result_cache = list(self._iterable_class(self))
  File "/usr/local/lib/python3.10/site-packages/django/db/models/query.py", line 57, in __iter__
    results = compiler.execute_sql(
  File "/usr/local/lib/python3.10/site-packages/django/db/models/sql/compiler.py", line 1361, in execute_sql
    cursor.execute(sql, params)
  File "/usr/local/lib/python3.10/site-packages/django/db/backends/utils.py", line 103, in execute
    return super().execute(sql, params)
  File "/usr/local/lib/python3.10/site-packages/django/db/backends/utils.py", line 67, in execute
    return self._execute_with_wrappers(
  File "/usr/local/lib/python3.10/site-packages/django/db/backends/utils.py", line 80, in _execute_with_wrappers
    return executor(sql, params, many, context)
  File "/usr/local/lib/python3.10/site-packages/django/db/backends/utils.py", line 84, in _execute
    with self.db.wrap_database_errors:
  File "/usr/local/lib/python3.10/site-packages/django/db/utils.py", line 91, in __exit__
    raise dj_exc_value.with_traceback(traceback) from exc_value
  File "/usr/local/lib/python3.10/site-packages/django/db/backends/utils.py", line 89, in _execute
    return self.cursor.execute(sql, params)
django.db.utils.ProgrammingError: column adds_post.views does not exist
LINE 1: ...ds_post"."wa_number", "adds_post"."is_activated", "adds_post...
                                                             ^

2022-09-21 13:11:42,171 [log | ERROR] Internal Server Error: /admin/adds/post/
Traceback (most recent call last):
  File "/usr/local/lib/python3.10/site-packages/django/db/backends/utils.py", line 89, in _execute
    return self.cursor.execute(sql, params)
psycopg2.errors.UndefinedColumn: column adds_post.views does not exist
LINE 1: ...ds_post"."wa_number", "adds_post"."is_activated", "adds_post...
                                                             ^


The above exception was the direct cause of the following exception:

Traceback (most recent call last):
  File "/usr/local/lib/python3.10/site-packages/django/core/handlers/exception.py", line 55, in inner
    response = get_response(request)
  File "/usr/local/lib/python3.10/site-packages/django/core/handlers/base.py", line 197, in _get_response
    response = wrapped_callback(request, *callback_args, **callback_kwargs)
  File "/usr/local/lib/python3.10/site-packages/django/contrib/admin/options.py", line 683, in wrapper
    return self.admin_site.admin_view(view)(*args, **kwargs)
  File "/usr/local/lib/python3.10/site-packages/django/utils/decorators.py", line 133, in _wrapped_view
    response = view_func(request, *args, **kwargs)
  File "/usr/local/lib/python3.10/site-packages/django/views/decorators/cache.py", line 62, in _wrapped_view_func
    response = view_func(request, *args, **kwargs)
  File "/usr/local/lib/python3.10/site-packages/django/contrib/admin/sites.py", line 242, in inner
    return view(request, *args, **kwargs)
  File "/usr/local/lib/python3.10/site-packages/django/utils/decorators.py", line 46, in _wrapper
    return bound_method(*args, **kwargs)
  File "/usr/local/lib/python3.10/site-packages/django/utils/decorators.py", line 133, in _wrapped_view
    response = view_func(request, *args, **kwargs)
  File "/usr/local/lib/python3.10/site-packages/django/contrib/admin/options.py", line 2063, in changelist_view
    "selection_note": _("0 of %(cnt)s selected") % {"cnt": len(cl.result_list)},
  File "/usr/local/lib/python3.10/site-packages/django/db/models/query.py", line 302, in __len__
    self._fetch_all()
  File "/usr/local/lib/python3.10/site-packages/django/db/models/query.py", line 1507, in _fetch_all
    self._result_cache = list(self._iterable_class(self))
  File "/usr/local/lib/python3.10/site-packages/django/db/models/query.py", line 57, in __iter__
    results = compiler.execute_sql(
  File "/usr/local/lib/python3.10/site-packages/django/db/models/sql/compiler.py", line 1361, in execute_sql
    cursor.execute(sql, params)
  File "/usr/local/lib/python3.10/site-packages/django/db/backends/utils.py", line 103, in execute
    return super().execute(sql, params)
  File "/usr/local/lib/python3.10/site-packages/django/db/backends/utils.py", line 67, in execute
    return self._execute_with_wrappers(
  File "/usr/local/lib/python3.10/site-packages/django/db/backends/utils.py", line 80, in _execute_with_wrappers
    return executor(sql, params, many, context)
  File "/usr/local/lib/python3.10/site-packages/django/db/backends/utils.py", line 84, in _execute
    with self.db.wrap_database_errors:
  File "/usr/local/lib/python3.10/site-packages/django/db/utils.py", line 91, in __exit__
    raise dj_exc_value.with_traceback(traceback) from exc_value
  File "/usr/local/lib/python3.10/site-packages/django/db/backends/utils.py", line 89, in _execute
    return self.cursor.execute(sql, params)
django.db.utils.ProgrammingError: column adds_post.views does not exist
LINE 1: ...ds_post"."wa_number", "adds_post"."is_activated", "adds_post...
                                                             ^

2022-09-21 13:11:42,201 [basehttp | ERROR] "GET /admin/adds/post/ HTTP/1.1" 500 148009 @ /usr/local/lib/python3.10/site-packages/django/core/servers/basehttp.py : 187 : log_message
2022-09-21 13:11:42,201 [basehttp | ERROR] "GET /admin/adds/post/ HTTP/1.1" 500 148009
2022-09-21 13:20:34,852 [basehttp | INFO] "GET /admin/adds/city/ HTTP/1.1" 200 13054
2022-09-21 13:20:36,849 [log | ERROR] Internal Server Error: /admin/adds/post/ @ /usr/local/lib/python3.10/site-packages/django/utils/log.py : 241 : log_response
Traceback (most recent call last):
  File "/usr/local/lib/python3.10/site-packages/django/db/backends/utils.py", line 89, in _execute
    return self.cursor.execute(sql, params)
psycopg2.errors.UndefinedColumn: column adds_post.views does not exist
LINE 1: ...ds_post"."wa_number", "adds_post"."is_activated", "adds_post...
                                                             ^


The above exception was the direct cause of the following exception:

Traceback (most recent call last):
  File "/usr/local/lib/python3.10/site-packages/django/core/handlers/exception.py", line 55, in inner
    response = get_response(request)
  File "/usr/local/lib/python3.10/site-packages/django/core/handlers/base.py", line 197, in _get_response
    response = wrapped_callback(request, *callback_args, **callback_kwargs)
  File "/usr/local/lib/python3.10/site-packages/django/contrib/admin/options.py", line 683, in wrapper
    return self.admin_site.admin_view(view)(*args, **kwargs)
  File "/usr/local/lib/python3.10/site-packages/django/utils/decorators.py", line 133, in _wrapped_view
    response = view_func(request, *args, **kwargs)
  File "/usr/local/lib/python3.10/site-packages/django/views/decorators/cache.py", line 62, in _wrapped_view_func
    response = view_func(request, *args, **kwargs)
  File "/usr/local/lib/python3.10/site-packages/django/contrib/admin/sites.py", line 242, in inner
    return view(request, *args, **kwargs)
  File "/usr/local/lib/python3.10/site-packages/django/utils/decorators.py", line 46, in _wrapper
    return bound_method(*args, **kwargs)
  File "/usr/local/lib/python3.10/site-packages/django/utils/decorators.py", line 133, in _wrapped_view
    response = view_func(request, *args, **kwargs)
  File "/usr/local/lib/python3.10/site-packages/django/contrib/admin/options.py", line 2063, in changelist_view
    "selection_note": _("0 of %(cnt)s selected") % {"cnt": len(cl.result_list)},
  File "/usr/local/lib/python3.10/site-packages/django/db/models/query.py", line 302, in __len__
    self._fetch_all()
  File "/usr/local/lib/python3.10/site-packages/django/db/models/query.py", line 1507, in _fetch_all
    self._result_cache = list(self._iterable_class(self))
  File "/usr/local/lib/python3.10/site-packages/django/db/models/query.py", line 57, in __iter__
    results = compiler.execute_sql(
  File "/usr/local/lib/python3.10/site-packages/django/db/models/sql/compiler.py", line 1361, in execute_sql
    cursor.execute(sql, params)
  File "/usr/local/lib/python3.10/site-packages/django/db/backends/utils.py", line 103, in execute
    return super().execute(sql, params)
  File "/usr/local/lib/python3.10/site-packages/django/db/backends/utils.py", line 67, in execute
    return self._execute_with_wrappers(
  File "/usr/local/lib/python3.10/site-packages/django/db/backends/utils.py", line 80, in _execute_with_wrappers
    return executor(sql, params, many, context)
  File "/usr/local/lib/python3.10/site-packages/django/db/backends/utils.py", line 84, in _execute
    with self.db.wrap_database_errors:
  File "/usr/local/lib/python3.10/site-packages/django/db/utils.py", line 91, in __exit__
    raise dj_exc_value.with_traceback(traceback) from exc_value
  File "/usr/local/lib/python3.10/site-packages/django/db/backends/utils.py", line 89, in _execute
    return self.cursor.execute(sql, params)
django.db.utils.ProgrammingError: column adds_post.views does not exist
LINE 1: ...ds_post"."wa_number", "adds_post"."is_activated", "adds_post...
                                                             ^

2022-09-21 13:20:36,849 [log | ERROR] Internal Server Error: /admin/adds/post/
Traceback (most recent call last):
  File "/usr/local/lib/python3.10/site-packages/django/db/backends/utils.py", line 89, in _execute
    return self.cursor.execute(sql, params)
psycopg2.errors.UndefinedColumn: column adds_post.views does not exist
LINE 1: ...ds_post"."wa_number", "adds_post"."is_activated", "adds_post...
                                                             ^


The above exception was the direct cause of the following exception:

Traceback (most recent call last):
  File "/usr/local/lib/python3.10/site-packages/django/core/handlers/exception.py", line 55, in inner
    response = get_response(request)
  File "/usr/local/lib/python3.10/site-packages/django/core/handlers/base.py", line 197, in _get_response
    response = wrapped_callback(request, *callback_args, **callback_kwargs)
  File "/usr/local/lib/python3.10/site-packages/django/contrib/admin/options.py", line 683, in wrapper
    return self.admin_site.admin_view(view)(*args, **kwargs)
  File "/usr/local/lib/python3.10/site-packages/django/utils/decorators.py", line 133, in _wrapped_view
    response = view_func(request, *args, **kwargs)
  File "/usr/local/lib/python3.10/site-packages/django/views/decorators/cache.py", line 62, in _wrapped_view_func
    response = view_func(request, *args, **kwargs)
  File "/usr/local/lib/python3.10/site-packages/django/contrib/admin/sites.py", line 242, in inner
    return view(request, *args, **kwargs)
  File "/usr/local/lib/python3.10/site-packages/django/utils/decorators.py", line 46, in _wrapper
    return bound_method(*args, **kwargs)
  File "/usr/local/lib/python3.10/site-packages/django/utils/decorators.py", line 133, in _wrapped_view
    response = view_func(request, *args, **kwargs)
  File "/usr/local/lib/python3.10/site-packages/django/contrib/admin/options.py", line 2063, in changelist_view
    "selection_note": _("0 of %(cnt)s selected") % {"cnt": len(cl.result_list)},
  File "/usr/local/lib/python3.10/site-packages/django/db/models/query.py", line 302, in __len__
    self._fetch_all()
  File "/usr/local/lib/python3.10/site-packages/django/db/models/query.py", line 1507, in _fetch_all
    self._result_cache = list(self._iterable_class(self))
  File "/usr/local/lib/python3.10/site-packages/django/db/models/query.py", line 57, in __iter__
    results = compiler.execute_sql(
  File "/usr/local/lib/python3.10/site-packages/django/db/models/sql/compiler.py", line 1361, in execute_sql
    cursor.execute(sql, params)
  File "/usr/local/lib/python3.10/site-packages/django/db/backends/utils.py", line 103, in execute
    return super().execute(sql, params)
  File "/usr/local/lib/python3.10/site-packages/django/db/backends/utils.py", line 67, in execute
    return self._execute_with_wrappers(
  File "/usr/local/lib/python3.10/site-packages/django/db/backends/utils.py", line 80, in _execute_with_wrappers
    return executor(sql, params, many, context)
  File "/usr/local/lib/python3.10/site-packages/django/db/backends/utils.py", line 84, in _execute
    with self.db.wrap_database_errors:
  File "/usr/local/lib/python3.10/site-packages/django/db/utils.py", line 91, in __exit__
    raise dj_exc_value.with_traceback(traceback) from exc_value
  File "/usr/local/lib/python3.10/site-packages/django/db/backends/utils.py", line 89, in _execute
    return self.cursor.execute(sql, params)
django.db.utils.ProgrammingError: column adds_post.views does not exist
LINE 1: ...ds_post"."wa_number", "adds_post"."is_activated", "adds_post...
                                                             ^

2022-09-21 13:20:36,888 [basehttp | ERROR] "GET /admin/adds/post/ HTTP/1.1" 500 148009 @ /usr/local/lib/python3.10/site-packages/django/core/servers/basehttp.py : 187 : log_message
2022-09-21 13:20:36,888 [basehttp | ERROR] "GET /admin/adds/post/ HTTP/1.1" 500 148009
2022-09-21 13:23:29,480 [autoreload | INFO] Watching for file changes with StatReloader
2022-09-21 13:23:38,772 [log | ERROR] Internal Server Error: /admin/adds/city/ @ /usr/local/lib/python3.10/site-packages/django/utils/log.py : 241 : log_response
Traceback (most recent call last):
  File "/usr/local/lib/python3.10/site-packages/django/contrib/sessions/backends/base.py", line 187, in _get_session
    return self._session_cache
AttributeError: 'SessionStore' object has no attribute '_session_cache'

During handling of the above exception, another exception occurred:

Traceback (most recent call last):
  File "/usr/local/lib/python3.10/site-packages/django/db/backends/utils.py", line 89, in _execute
    return self.cursor.execute(sql, params)
psycopg2.errors.UndefinedTable: relation "django_session" does not exist
LINE 1: ...ession_data", "django_session"."expire_date" FROM "django_se...
                                                             ^


The above exception was the direct cause of the following exception:

Traceback (most recent call last):
  File "/usr/local/lib/python3.10/site-packages/django/core/handlers/exception.py", line 55, in inner
    response = get_response(request)
  File "/usr/local/lib/python3.10/site-packages/django/core/handlers/base.py", line 197, in _get_response
    response = wrapped_callback(request, *callback_args, **callback_kwargs)
  File "/usr/local/lib/python3.10/site-packages/django/contrib/admin/options.py", line 683, in wrapper
    return self.admin_site.admin_view(view)(*args, **kwargs)
  File "/usr/local/lib/python3.10/site-packages/django/utils/decorators.py", line 133, in _wrapped_view
    response = view_func(request, *args, **kwargs)
  File "/usr/local/lib/python3.10/site-packages/django/views/decorators/cache.py", line 62, in _wrapped_view_func
    response = view_func(request, *args, **kwargs)
  File "/usr/local/lib/python3.10/site-packages/django/contrib/admin/sites.py", line 230, in inner
    if not self.has_permission(request):
  File "/usr/local/lib/python3.10/site-packages/django/contrib/admin/sites.py", line 203, in has_permission
    return request.user.is_active and request.user.is_staff
  File "/usr/local/lib/python3.10/site-packages/django/utils/functional.py", line 258, in inner
    self._setup()
  File "/usr/local/lib/python3.10/site-packages/django/utils/functional.py", line 398, in _setup
    self._wrapped = self._setupfunc()
  File "/usr/local/lib/python3.10/site-packages/django/contrib/auth/middleware.py", line 25, in <lambda>
    request.user = SimpleLazyObject(lambda: get_user(request))
  File "/usr/local/lib/python3.10/site-packages/django/contrib/auth/middleware.py", line 11, in get_user
    request._cached_user = auth.get_user(request)
  File "/usr/local/lib/python3.10/site-packages/django/contrib/auth/__init__.py", line 191, in get_user
    user_id = _get_user_session_key(request)
  File "/usr/local/lib/python3.10/site-packages/django/contrib/auth/__init__.py", line 60, in _get_user_session_key
    return get_user_model()._meta.pk.to_python(request.session[SESSION_KEY])
  File "/usr/local/lib/python3.10/site-packages/django/contrib/sessions/backends/base.py", line 53, in __getitem__
    return self._session[key]
  File "/usr/local/lib/python3.10/site-packages/django/contrib/sessions/backends/base.py", line 192, in _get_session
    self._session_cache = self.load()
  File "/usr/local/lib/python3.10/site-packages/django/contrib/sessions/backends/db.py", line 42, in load
    s = self._get_session_from_db()
  File "/usr/local/lib/python3.10/site-packages/django/contrib/sessions/backends/db.py", line 32, in _get_session_from_db
    return self.model.objects.get(
  File "/usr/local/lib/python3.10/site-packages/django/db/models/manager.py", line 85, in manager_method
    return getattr(self.get_queryset(), name)(*args, **kwargs)
  File "/usr/local/lib/python3.10/site-packages/django/db/models/query.py", line 492, in get
    num = len(clone)
  File "/usr/local/lib/python3.10/site-packages/django/db/models/query.py", line 302, in __len__
    self._fetch_all()
  File "/usr/local/lib/python3.10/site-packages/django/db/models/query.py", line 1507, in _fetch_all
    self._result_cache = list(self._iterable_class(self))
  File "/usr/local/lib/python3.10/site-packages/django/db/models/query.py", line 57, in __iter__
    results = compiler.execute_sql(
  File "/usr/local/lib/python3.10/site-packages/django/db/models/sql/compiler.py", line 1361, in execute_sql
    cursor.execute(sql, params)
  File "/usr/local/lib/python3.10/site-packages/django/db/backends/utils.py", line 103, in execute
    return super().execute(sql, params)
  File "/usr/local/lib/python3.10/site-packages/django/db/backends/utils.py", line 67, in execute
    return self._execute_with_wrappers(
  File "/usr/local/lib/python3.10/site-packages/django/db/backends/utils.py", line 80, in _execute_with_wrappers
    return executor(sql, params, many, context)
  File "/usr/local/lib/python3.10/site-packages/django/db/backends/utils.py", line 84, in _execute
    with self.db.wrap_database_errors:
  File "/usr/local/lib/python3.10/site-packages/django/db/utils.py", line 91, in __exit__
    raise dj_exc_value.with_traceback(traceback) from exc_value
  File "/usr/local/lib/python3.10/site-packages/django/db/backends/utils.py", line 89, in _execute
    return self.cursor.execute(sql, params)
django.db.utils.ProgrammingError: relation "django_session" does not exist
LINE 1: ...ession_data", "django_session"."expire_date" FROM "django_se...
                                                             ^

2022-09-21 13:23:38,772 [log | ERROR] Internal Server Error: /admin/adds/city/
Traceback (most recent call last):
  File "/usr/local/lib/python3.10/site-packages/django/contrib/sessions/backends/base.py", line 187, in _get_session
    return self._session_cache
AttributeError: 'SessionStore' object has no attribute '_session_cache'

During handling of the above exception, another exception occurred:

Traceback (most recent call last):
  File "/usr/local/lib/python3.10/site-packages/django/db/backends/utils.py", line 89, in _execute
    return self.cursor.execute(sql, params)
psycopg2.errors.UndefinedTable: relation "django_session" does not exist
LINE 1: ...ession_data", "django_session"."expire_date" FROM "django_se...
                                                             ^


The above exception was the direct cause of the following exception:

Traceback (most recent call last):
  File "/usr/local/lib/python3.10/site-packages/django/core/handlers/exception.py", line 55, in inner
    response = get_response(request)
  File "/usr/local/lib/python3.10/site-packages/django/core/handlers/base.py", line 197, in _get_response
    response = wrapped_callback(request, *callback_args, **callback_kwargs)
  File "/usr/local/lib/python3.10/site-packages/django/contrib/admin/options.py", line 683, in wrapper
    return self.admin_site.admin_view(view)(*args, **kwargs)
  File "/usr/local/lib/python3.10/site-packages/django/utils/decorators.py", line 133, in _wrapped_view
    response = view_func(request, *args, **kwargs)
  File "/usr/local/lib/python3.10/site-packages/django/views/decorators/cache.py", line 62, in _wrapped_view_func
    response = view_func(request, *args, **kwargs)
  File "/usr/local/lib/python3.10/site-packages/django/contrib/admin/sites.py", line 230, in inner
    if not self.has_permission(request):
  File "/usr/local/lib/python3.10/site-packages/django/contrib/admin/sites.py", line 203, in has_permission
    return request.user.is_active and request.user.is_staff
  File "/usr/local/lib/python3.10/site-packages/django/utils/functional.py", line 258, in inner
    self._setup()
  File "/usr/local/lib/python3.10/site-packages/django/utils/functional.py", line 398, in _setup
    self._wrapped = self._setupfunc()
  File "/usr/local/lib/python3.10/site-packages/django/contrib/auth/middleware.py", line 25, in <lambda>
    request.user = SimpleLazyObject(lambda: get_user(request))
  File "/usr/local/lib/python3.10/site-packages/django/contrib/auth/middleware.py", line 11, in get_user
    request._cached_user = auth.get_user(request)
  File "/usr/local/lib/python3.10/site-packages/django/contrib/auth/__init__.py", line 191, in get_user
    user_id = _get_user_session_key(request)
  File "/usr/local/lib/python3.10/site-packages/django/contrib/auth/__init__.py", line 60, in _get_user_session_key
    return get_user_model()._meta.pk.to_python(request.session[SESSION_KEY])
  File "/usr/local/lib/python3.10/site-packages/django/contrib/sessions/backends/base.py", line 53, in __getitem__
    return self._session[key]
  File "/usr/local/lib/python3.10/site-packages/django/contrib/sessions/backends/base.py", line 192, in _get_session
    self._session_cache = self.load()
  File "/usr/local/lib/python3.10/site-packages/django/contrib/sessions/backends/db.py", line 42, in load
    s = self._get_session_from_db()
  File "/usr/local/lib/python3.10/site-packages/django/contrib/sessions/backends/db.py", line 32, in _get_session_from_db
    return self.model.objects.get(
  File "/usr/local/lib/python3.10/site-packages/django/db/models/manager.py", line 85, in manager_method
    return getattr(self.get_queryset(), name)(*args, **kwargs)
  File "/usr/local/lib/python3.10/site-packages/django/db/models/query.py", line 492, in get
    num = len(clone)
  File "/usr/local/lib/python3.10/site-packages/django/db/models/query.py", line 302, in __len__
    self._fetch_all()
  File "/usr/local/lib/python3.10/site-packages/django/db/models/query.py", line 1507, in _fetch_all
    self._result_cache = list(self._iterable_class(self))
  File "/usr/local/lib/python3.10/site-packages/django/db/models/query.py", line 57, in __iter__
    results = compiler.execute_sql(
  File "/usr/local/lib/python3.10/site-packages/django/db/models/sql/compiler.py", line 1361, in execute_sql
    cursor.execute(sql, params)
  File "/usr/local/lib/python3.10/site-packages/django/db/backends/utils.py", line 103, in execute
    return super().execute(sql, params)
  File "/usr/local/lib/python3.10/site-packages/django/db/backends/utils.py", line 67, in execute
    return self._execute_with_wrappers(
  File "/usr/local/lib/python3.10/site-packages/django/db/backends/utils.py", line 80, in _execute_with_wrappers
    return executor(sql, params, many, context)
  File "/usr/local/lib/python3.10/site-packages/django/db/backends/utils.py", line 84, in _execute
    with self.db.wrap_database_errors:
  File "/usr/local/lib/python3.10/site-packages/django/db/utils.py", line 91, in __exit__
    raise dj_exc_value.with_traceback(traceback) from exc_value
  File "/usr/local/lib/python3.10/site-packages/django/db/backends/utils.py", line 89, in _execute
    return self.cursor.execute(sql, params)
django.db.utils.ProgrammingError: relation "django_session" does not exist
LINE 1: ...ession_data", "django_session"."expire_date" FROM "django_se...
                                                             ^

2022-09-21 13:23:38,800 [basehttp | ERROR] "GET /admin/adds/city/ HTTP/1.1" 500 183343 @ /usr/local/lib/python3.10/site-packages/django/core/servers/basehttp.py : 187 : log_message
2022-09-21 13:23:38,800 [basehttp | ERROR] "GET /admin/adds/city/ HTTP/1.1" 500 183343
2022-09-21 13:23:41,091 [log | ERROR] Internal Server Error: /admin/ @ /usr/local/lib/python3.10/site-packages/django/utils/log.py : 241 : log_response
Traceback (most recent call last):
  File "/usr/local/lib/python3.10/site-packages/django/contrib/sessions/backends/base.py", line 187, in _get_session
    return self._session_cache
AttributeError: 'SessionStore' object has no attribute '_session_cache'

During handling of the above exception, another exception occurred:

Traceback (most recent call last):
  File "/usr/local/lib/python3.10/site-packages/django/db/backends/utils.py", line 89, in _execute
    return self.cursor.execute(sql, params)
psycopg2.errors.UndefinedTable: relation "django_session" does not exist
LINE 1: ...ession_data", "django_session"."expire_date" FROM "django_se...
                                                             ^


The above exception was the direct cause of the following exception:

Traceback (most recent call last):
  File "/usr/local/lib/python3.10/site-packages/django/core/handlers/exception.py", line 55, in inner
    response = get_response(request)
  File "/usr/local/lib/python3.10/site-packages/django/core/handlers/base.py", line 197, in _get_response
    response = wrapped_callback(request, *callback_args, **callback_kwargs)
  File "/usr/local/lib/python3.10/site-packages/django/contrib/admin/sites.py", line 261, in wrapper
    return self.admin_view(view, cacheable)(*args, **kwargs)
  File "/usr/local/lib/python3.10/site-packages/django/utils/decorators.py", line 133, in _wrapped_view
    response = view_func(request, *args, **kwargs)
  File "/usr/local/lib/python3.10/site-packages/django/views/decorators/cache.py", line 62, in _wrapped_view_func
    response = view_func(request, *args, **kwargs)
  File "/usr/local/lib/python3.10/site-packages/django/contrib/admin/sites.py", line 230, in inner
    if not self.has_permission(request):
  File "/usr/local/lib/python3.10/site-packages/django/contrib/admin/sites.py", line 203, in has_permission
    return request.user.is_active and request.user.is_staff
  File "/usr/local/lib/python3.10/site-packages/django/utils/functional.py", line 258, in inner
    self._setup()
  File "/usr/local/lib/python3.10/site-packages/django/utils/functional.py", line 398, in _setup
    self._wrapped = self._setupfunc()
  File "/usr/local/lib/python3.10/site-packages/django/contrib/auth/middleware.py", line 25, in <lambda>
    request.user = SimpleLazyObject(lambda: get_user(request))
  File "/usr/local/lib/python3.10/site-packages/django/contrib/auth/middleware.py", line 11, in get_user
    request._cached_user = auth.get_user(request)
  File "/usr/local/lib/python3.10/site-packages/django/contrib/auth/__init__.py", line 191, in get_user
    user_id = _get_user_session_key(request)
  File "/usr/local/lib/python3.10/site-packages/django/contrib/auth/__init__.py", line 60, in _get_user_session_key
    return get_user_model()._meta.pk.to_python(request.session[SESSION_KEY])
  File "/usr/local/lib/python3.10/site-packages/django/contrib/sessions/backends/base.py", line 53, in __getitem__
    return self._session[key]
  File "/usr/local/lib/python3.10/site-packages/django/contrib/sessions/backends/base.py", line 192, in _get_session
    self._session_cache = self.load()
  File "/usr/local/lib/python3.10/site-packages/django/contrib/sessions/backends/db.py", line 42, in load
    s = self._get_session_from_db()
  File "/usr/local/lib/python3.10/site-packages/django/contrib/sessions/backends/db.py", line 32, in _get_session_from_db
    return self.model.objects.get(
  File "/usr/local/lib/python3.10/site-packages/django/db/models/manager.py", line 85, in manager_method
    return getattr(self.get_queryset(), name)(*args, **kwargs)
  File "/usr/local/lib/python3.10/site-packages/django/db/models/query.py", line 492, in get
    num = len(clone)
  File "/usr/local/lib/python3.10/site-packages/django/db/models/query.py", line 302, in __len__
    self._fetch_all()
  File "/usr/local/lib/python3.10/site-packages/django/db/models/query.py", line 1507, in _fetch_all
    self._result_cache = list(self._iterable_class(self))
  File "/usr/local/lib/python3.10/site-packages/django/db/models/query.py", line 57, in __iter__
    results = compiler.execute_sql(
  File "/usr/local/lib/python3.10/site-packages/django/db/models/sql/compiler.py", line 1361, in execute_sql
    cursor.execute(sql, params)
  File "/usr/local/lib/python3.10/site-packages/django/db/backends/utils.py", line 103, in execute
    return super().execute(sql, params)
  File "/usr/local/lib/python3.10/site-packages/django/db/backends/utils.py", line 67, in execute
    return self._execute_with_wrappers(
  File "/usr/local/lib/python3.10/site-packages/django/db/backends/utils.py", line 80, in _execute_with_wrappers
    return executor(sql, params, many, context)
  File "/usr/local/lib/python3.10/site-packages/django/db/backends/utils.py", line 84, in _execute
    with self.db.wrap_database_errors:
  File "/usr/local/lib/python3.10/site-packages/django/db/utils.py", line 91, in __exit__
    raise dj_exc_value.with_traceback(traceback) from exc_value
  File "/usr/local/lib/python3.10/site-packages/django/db/backends/utils.py", line 89, in _execute
    return self.cursor.execute(sql, params)
django.db.utils.ProgrammingError: relation "django_session" does not exist
LINE 1: ...ession_data", "django_session"."expire_date" FROM "django_se...
                                                             ^

2022-09-21 13:23:41,091 [log | ERROR] Internal Server Error: /admin/
Traceback (most recent call last):
  File "/usr/local/lib/python3.10/site-packages/django/contrib/sessions/backends/base.py", line 187, in _get_session
    return self._session_cache
AttributeError: 'SessionStore' object has no attribute '_session_cache'

During handling of the above exception, another exception occurred:

Traceback (most recent call last):
  File "/usr/local/lib/python3.10/site-packages/django/db/backends/utils.py", line 89, in _execute
    return self.cursor.execute(sql, params)
psycopg2.errors.UndefinedTable: relation "django_session" does not exist
LINE 1: ...ession_data", "django_session"."expire_date" FROM "django_se...
                                                             ^


The above exception was the direct cause of the following exception:

Traceback (most recent call last):
  File "/usr/local/lib/python3.10/site-packages/django/core/handlers/exception.py", line 55, in inner
    response = get_response(request)
  File "/usr/local/lib/python3.10/site-packages/django/core/handlers/base.py", line 197, in _get_response
    response = wrapped_callback(request, *callback_args, **callback_kwargs)
  File "/usr/local/lib/python3.10/site-packages/django/contrib/admin/sites.py", line 261, in wrapper
    return self.admin_view(view, cacheable)(*args, **kwargs)
  File "/usr/local/lib/python3.10/site-packages/django/utils/decorators.py", line 133, in _wrapped_view
    response = view_func(request, *args, **kwargs)
  File "/usr/local/lib/python3.10/site-packages/django/views/decorators/cache.py", line 62, in _wrapped_view_func
    response = view_func(request, *args, **kwargs)
  File "/usr/local/lib/python3.10/site-packages/django/contrib/admin/sites.py", line 230, in inner
    if not self.has_permission(request):
  File "/usr/local/lib/python3.10/site-packages/django/contrib/admin/sites.py", line 203, in has_permission
    return request.user.is_active and request.user.is_staff
  File "/usr/local/lib/python3.10/site-packages/django/utils/functional.py", line 258, in inner
    self._setup()
  File "/usr/local/lib/python3.10/site-packages/django/utils/functional.py", line 398, in _setup
    self._wrapped = self._setupfunc()
  File "/usr/local/lib/python3.10/site-packages/django/contrib/auth/middleware.py", line 25, in <lambda>
    request.user = SimpleLazyObject(lambda: get_user(request))
  File "/usr/local/lib/python3.10/site-packages/django/contrib/auth/middleware.py", line 11, in get_user
    request._cached_user = auth.get_user(request)
  File "/usr/local/lib/python3.10/site-packages/django/contrib/auth/__init__.py", line 191, in get_user
    user_id = _get_user_session_key(request)
  File "/usr/local/lib/python3.10/site-packages/django/contrib/auth/__init__.py", line 60, in _get_user_session_key
    return get_user_model()._meta.pk.to_python(request.session[SESSION_KEY])
  File "/usr/local/lib/python3.10/site-packages/django/contrib/sessions/backends/base.py", line 53, in __getitem__
    return self._session[key]
  File "/usr/local/lib/python3.10/site-packages/django/contrib/sessions/backends/base.py", line 192, in _get_session
    self._session_cache = self.load()
  File "/usr/local/lib/python3.10/site-packages/django/contrib/sessions/backends/db.py", line 42, in load
    s = self._get_session_from_db()
  File "/usr/local/lib/python3.10/site-packages/django/contrib/sessions/backends/db.py", line 32, in _get_session_from_db
    return self.model.objects.get(
  File "/usr/local/lib/python3.10/site-packages/django/db/models/manager.py", line 85, in manager_method
    return getattr(self.get_queryset(), name)(*args, **kwargs)
  File "/usr/local/lib/python3.10/site-packages/django/db/models/query.py", line 492, in get
    num = len(clone)
  File "/usr/local/lib/python3.10/site-packages/django/db/models/query.py", line 302, in __len__
    self._fetch_all()
  File "/usr/local/lib/python3.10/site-packages/django/db/models/query.py", line 1507, in _fetch_all
    self._result_cache = list(self._iterable_class(self))
  File "/usr/local/lib/python3.10/site-packages/django/db/models/query.py", line 57, in __iter__
    results = compiler.execute_sql(
  File "/usr/local/lib/python3.10/site-packages/django/db/models/sql/compiler.py", line 1361, in execute_sql
    cursor.execute(sql, params)
  File "/usr/local/lib/python3.10/site-packages/django/db/backends/utils.py", line 103, in execute
    return super().execute(sql, params)
  File "/usr/local/lib/python3.10/site-packages/django/db/backends/utils.py", line 67, in execute
    return self._execute_with_wrappers(
  File "/usr/local/lib/python3.10/site-packages/django/db/backends/utils.py", line 80, in _execute_with_wrappers
    return executor(sql, params, many, context)
  File "/usr/local/lib/python3.10/site-packages/django/db/backends/utils.py", line 84, in _execute
    with self.db.wrap_database_errors:
  File "/usr/local/lib/python3.10/site-packages/django/db/utils.py", line 91, in __exit__
    raise dj_exc_value.with_traceback(traceback) from exc_value
  File "/usr/local/lib/python3.10/site-packages/django/db/backends/utils.py", line 89, in _execute
    return self.cursor.execute(sql, params)
django.db.utils.ProgrammingError: relation "django_session" does not exist
LINE 1: ...ession_data", "django_session"."expire_date" FROM "django_se...
                                                             ^

2022-09-21 13:23:41,112 [basehttp | ERROR] "GET /admin/ HTTP/1.1" 500 183206 @ /usr/local/lib/python3.10/site-packages/django/core/servers/basehttp.py : 187 : log_message
2022-09-21 13:23:41,112 [basehttp | ERROR] "GET /admin/ HTTP/1.1" 500 183206
2022-09-21 13:23:49,484 [log | ERROR] Internal Server Error: /admin/ @ /usr/local/lib/python3.10/site-packages/django/utils/log.py : 241 : log_response
Traceback (most recent call last):
  File "/usr/local/lib/python3.10/site-packages/django/contrib/sessions/backends/base.py", line 187, in _get_session
    return self._session_cache
AttributeError: 'SessionStore' object has no attribute '_session_cache'

During handling of the above exception, another exception occurred:

Traceback (most recent call last):
  File "/usr/local/lib/python3.10/site-packages/django/db/backends/utils.py", line 89, in _execute
    return self.cursor.execute(sql, params)
psycopg2.errors.UndefinedTable: relation "django_session" does not exist
LINE 1: ...ession_data", "django_session"."expire_date" FROM "django_se...
                                                             ^


The above exception was the direct cause of the following exception:

Traceback (most recent call last):
  File "/usr/local/lib/python3.10/site-packages/django/core/handlers/exception.py", line 55, in inner
    response = get_response(request)
  File "/usr/local/lib/python3.10/site-packages/django/core/handlers/base.py", line 197, in _get_response
    response = wrapped_callback(request, *callback_args, **callback_kwargs)
  File "/usr/local/lib/python3.10/site-packages/django/contrib/admin/sites.py", line 261, in wrapper
    return self.admin_view(view, cacheable)(*args, **kwargs)
  File "/usr/local/lib/python3.10/site-packages/django/utils/decorators.py", line 133, in _wrapped_view
    response = view_func(request, *args, **kwargs)
  File "/usr/local/lib/python3.10/site-packages/django/views/decorators/cache.py", line 62, in _wrapped_view_func
    response = view_func(request, *args, **kwargs)
  File "/usr/local/lib/python3.10/site-packages/django/contrib/admin/sites.py", line 230, in inner
    if not self.has_permission(request):
  File "/usr/local/lib/python3.10/site-packages/django/contrib/admin/sites.py", line 203, in has_permission
    return request.user.is_active and request.user.is_staff
  File "/usr/local/lib/python3.10/site-packages/django/utils/functional.py", line 258, in inner
    self._setup()
  File "/usr/local/lib/python3.10/site-packages/django/utils/functional.py", line 398, in _setup
    self._wrapped = self._setupfunc()
  File "/usr/local/lib/python3.10/site-packages/django/contrib/auth/middleware.py", line 25, in <lambda>
    request.user = SimpleLazyObject(lambda: get_user(request))
  File "/usr/local/lib/python3.10/site-packages/django/contrib/auth/middleware.py", line 11, in get_user
    request._cached_user = auth.get_user(request)
  File "/usr/local/lib/python3.10/site-packages/django/contrib/auth/__init__.py", line 191, in get_user
    user_id = _get_user_session_key(request)
  File "/usr/local/lib/python3.10/site-packages/django/contrib/auth/__init__.py", line 60, in _get_user_session_key
    return get_user_model()._meta.pk.to_python(request.session[SESSION_KEY])
  File "/usr/local/lib/python3.10/site-packages/django/contrib/sessions/backends/base.py", line 53, in __getitem__
    return self._session[key]
  File "/usr/local/lib/python3.10/site-packages/django/contrib/sessions/backends/base.py", line 192, in _get_session
    self._session_cache = self.load()
  File "/usr/local/lib/python3.10/site-packages/django/contrib/sessions/backends/db.py", line 42, in load
    s = self._get_session_from_db()
  File "/usr/local/lib/python3.10/site-packages/django/contrib/sessions/backends/db.py", line 32, in _get_session_from_db
    return self.model.objects.get(
  File "/usr/local/lib/python3.10/site-packages/django/db/models/manager.py", line 85, in manager_method
    return getattr(self.get_queryset(), name)(*args, **kwargs)
  File "/usr/local/lib/python3.10/site-packages/django/db/models/query.py", line 492, in get
    num = len(clone)
  File "/usr/local/lib/python3.10/site-packages/django/db/models/query.py", line 302, in __len__
    self._fetch_all()
  File "/usr/local/lib/python3.10/site-packages/django/db/models/query.py", line 1507, in _fetch_all
    self._result_cache = list(self._iterable_class(self))
  File "/usr/local/lib/python3.10/site-packages/django/db/models/query.py", line 57, in __iter__
    results = compiler.execute_sql(
  File "/usr/local/lib/python3.10/site-packages/django/db/models/sql/compiler.py", line 1361, in execute_sql
    cursor.execute(sql, params)
  File "/usr/local/lib/python3.10/site-packages/django/db/backends/utils.py", line 103, in execute
    return super().execute(sql, params)
  File "/usr/local/lib/python3.10/site-packages/django/db/backends/utils.py", line 67, in execute
    return self._execute_with_wrappers(
  File "/usr/local/lib/python3.10/site-packages/django/db/backends/utils.py", line 80, in _execute_with_wrappers
    return executor(sql, params, many, context)
  File "/usr/local/lib/python3.10/site-packages/django/db/backends/utils.py", line 84, in _execute
    with self.db.wrap_database_errors:
  File "/usr/local/lib/python3.10/site-packages/django/db/utils.py", line 91, in __exit__
    raise dj_exc_value.with_traceback(traceback) from exc_value
  File "/usr/local/lib/python3.10/site-packages/django/db/backends/utils.py", line 89, in _execute
    return self.cursor.execute(sql, params)
django.db.utils.ProgrammingError: relation "django_session" does not exist
LINE 1: ...ession_data", "django_session"."expire_date" FROM "django_se...
                                                             ^

2022-09-21 13:23:49,484 [log | ERROR] Internal Server Error: /admin/
Traceback (most recent call last):
  File "/usr/local/lib/python3.10/site-packages/django/contrib/sessions/backends/base.py", line 187, in _get_session
    return self._session_cache
AttributeError: 'SessionStore' object has no attribute '_session_cache'

During handling of the above exception, another exception occurred:

Traceback (most recent call last):
  File "/usr/local/lib/python3.10/site-packages/django/db/backends/utils.py", line 89, in _execute
    return self.cursor.execute(sql, params)
psycopg2.errors.UndefinedTable: relation "django_session" does not exist
LINE 1: ...ession_data", "django_session"."expire_date" FROM "django_se...
                                                             ^


The above exception was the direct cause of the following exception:

Traceback (most recent call last):
  File "/usr/local/lib/python3.10/site-packages/django/core/handlers/exception.py", line 55, in inner
    response = get_response(request)
  File "/usr/local/lib/python3.10/site-packages/django/core/handlers/base.py", line 197, in _get_response
    response = wrapped_callback(request, *callback_args, **callback_kwargs)
  File "/usr/local/lib/python3.10/site-packages/django/contrib/admin/sites.py", line 261, in wrapper
    return self.admin_view(view, cacheable)(*args, **kwargs)
  File "/usr/local/lib/python3.10/site-packages/django/utils/decorators.py", line 133, in _wrapped_view
    response = view_func(request, *args, **kwargs)
  File "/usr/local/lib/python3.10/site-packages/django/views/decorators/cache.py", line 62, in _wrapped_view_func
    response = view_func(request, *args, **kwargs)
  File "/usr/local/lib/python3.10/site-packages/django/contrib/admin/sites.py", line 230, in inner
    if not self.has_permission(request):
  File "/usr/local/lib/python3.10/site-packages/django/contrib/admin/sites.py", line 203, in has_permission
    return request.user.is_active and request.user.is_staff
  File "/usr/local/lib/python3.10/site-packages/django/utils/functional.py", line 258, in inner
    self._setup()
  File "/usr/local/lib/python3.10/site-packages/django/utils/functional.py", line 398, in _setup
    self._wrapped = self._setupfunc()
  File "/usr/local/lib/python3.10/site-packages/django/contrib/auth/middleware.py", line 25, in <lambda>
    request.user = SimpleLazyObject(lambda: get_user(request))
  File "/usr/local/lib/python3.10/site-packages/django/contrib/auth/middleware.py", line 11, in get_user
    request._cached_user = auth.get_user(request)
  File "/usr/local/lib/python3.10/site-packages/django/contrib/auth/__init__.py", line 191, in get_user
    user_id = _get_user_session_key(request)
  File "/usr/local/lib/python3.10/site-packages/django/contrib/auth/__init__.py", line 60, in _get_user_session_key
    return get_user_model()._meta.pk.to_python(request.session[SESSION_KEY])
  File "/usr/local/lib/python3.10/site-packages/django/contrib/sessions/backends/base.py", line 53, in __getitem__
    return self._session[key]
  File "/usr/local/lib/python3.10/site-packages/django/contrib/sessions/backends/base.py", line 192, in _get_session
    self._session_cache = self.load()
  File "/usr/local/lib/python3.10/site-packages/django/contrib/sessions/backends/db.py", line 42, in load
    s = self._get_session_from_db()
  File "/usr/local/lib/python3.10/site-packages/django/contrib/sessions/backends/db.py", line 32, in _get_session_from_db
    return self.model.objects.get(
  File "/usr/local/lib/python3.10/site-packages/django/db/models/manager.py", line 85, in manager_method
    return getattr(self.get_queryset(), name)(*args, **kwargs)
  File "/usr/local/lib/python3.10/site-packages/django/db/models/query.py", line 492, in get
    num = len(clone)
  File "/usr/local/lib/python3.10/site-packages/django/db/models/query.py", line 302, in __len__
    self._fetch_all()
  File "/usr/local/lib/python3.10/site-packages/django/db/models/query.py", line 1507, in _fetch_all
    self._result_cache = list(self._iterable_class(self))
  File "/usr/local/lib/python3.10/site-packages/django/db/models/query.py", line 57, in __iter__
    results = compiler.execute_sql(
  File "/usr/local/lib/python3.10/site-packages/django/db/models/sql/compiler.py", line 1361, in execute_sql
    cursor.execute(sql, params)
  File "/usr/local/lib/python3.10/site-packages/django/db/backends/utils.py", line 103, in execute
    return super().execute(sql, params)
  File "/usr/local/lib/python3.10/site-packages/django/db/backends/utils.py", line 67, in execute
    return self._execute_with_wrappers(
  File "/usr/local/lib/python3.10/site-packages/django/db/backends/utils.py", line 80, in _execute_with_wrappers
    return executor(sql, params, many, context)
  File "/usr/local/lib/python3.10/site-packages/django/db/backends/utils.py", line 84, in _execute
    with self.db.wrap_database_errors:
  File "/usr/local/lib/python3.10/site-packages/django/db/utils.py", line 91, in __exit__
    raise dj_exc_value.with_traceback(traceback) from exc_value
  File "/usr/local/lib/python3.10/site-packages/django/db/backends/utils.py", line 89, in _execute
    return self.cursor.execute(sql, params)
django.db.utils.ProgrammingError: relation "django_session" does not exist
LINE 1: ...ession_data", "django_session"."expire_date" FROM "django_se...
                                                             ^

2022-09-21 13:23:49,503 [basehttp | ERROR] "GET /admin/ HTTP/1.1" 500 183206 @ /usr/local/lib/python3.10/site-packages/django/core/servers/basehttp.py : 187 : log_message
2022-09-21 13:23:49,503 [basehttp | ERROR] "GET /admin/ HTTP/1.1" 500 183206
2022-09-21 13:25:44,305 [basehttp | INFO] "GET /admin/ HTTP/1.1" 302 0
2022-09-21 13:25:44,440 [basehttp | INFO] "GET /admin/login/?next=/admin/ HTTP/1.1" 200 2216
2022-09-21 13:25:44,559 [basehttp | INFO] "GET /static/admin/css/base.css HTTP/1.1" 304 0
2022-09-21 13:25:44,582 [basehttp | INFO] "GET /static/admin/css/nav_sidebar.css HTTP/1.1" 304 0
2022-09-21 13:25:44,592 [basehttp | INFO] "GET /static/admin/css/responsive.css HTTP/1.1" 304 0
2022-09-21 13:25:44,614 [basehttp | INFO] "GET /static/admin/js/nav_sidebar.js HTTP/1.1" 304 0
2022-09-21 13:25:44,615 [basehttp | INFO] "GET /static/admin/css/fonts.css HTTP/1.1" 304 0
2022-09-21 13:25:44,638 [basehttp | INFO] "GET /static/admin/css/login.css HTTP/1.1" 200 954
2022-09-21 13:25:44,692 [basehttp | INFO] "GET /static/admin/fonts/Roboto-Regular-webfont.woff HTTP/1.1" 304 0
2022-09-21 13:25:44,723 [basehttp | INFO] "GET /static/admin/fonts/Roboto-Light-webfont.woff HTTP/1.1" 304 0
2022-09-21 13:26:22,316 [basehttp | INFO] "POST /admin/login/?next=/admin/ HTTP/1.1" 302 0
2022-09-21 13:26:22,424 [basehttp | INFO] "GET /admin/ HTTP/1.1" 200 15083
2022-09-21 13:26:22,471 [basehttp | INFO] "GET /static/admin/css/dashboard.css HTTP/1.1" 304 0
2022-09-21 13:26:22,495 [basehttp | INFO] "GET /static/admin/img/icon-changelink.svg HTTP/1.1" 304 0
2022-09-21 13:26:22,512 [basehttp | INFO] "GET /static/admin/fonts/Roboto-Bold-webfont.woff HTTP/1.1" 304 0
2022-09-21 13:26:22,495 [basehttp | INFO] "GET /static/admin/img/icon-addlink.svg HTTP/1.1" 304 0
2022-09-21 13:26:35,597 [basehttp | INFO] "GET /admin/adds/post/ HTTP/1.1" 200 13054
2022-09-21 13:26:35,653 [basehttp | INFO] "GET /static/admin/js/core.js HTTP/1.1" 304 0
2022-09-21 13:26:35,657 [basehttp | INFO] "GET /static/admin/js/jquery.init.js HTTP/1.1" 304 0
2022-09-21 13:26:35,659 [basehttp | INFO] "GET /static/admin/css/changelists.css HTTP/1.1" 304 0
2022-09-21 13:26:35,666 [basehttp | INFO] "GET /static/admin/js/actions.js HTTP/1.1" 304 0
2022-09-21 13:26:35,670 [basehttp | INFO] "GET /static/admin/js/prepopulate.js HTTP/1.1" 304 0
2022-09-21 13:26:35,668 [basehttp | INFO] "GET /static/admin/js/vendor/jquery/jquery.js HTTP/1.1" 304 0
2022-09-21 13:26:35,671 [basehttp | INFO] "GET /static/admin/js/admin/RelatedObjectLookups.js HTTP/1.1" 304 0
2022-09-21 13:26:35,685 [basehttp | INFO] "GET /static/admin/js/urlify.js HTTP/1.1" 304 0
2022-09-21 13:26:35,688 [basehttp | INFO] "GET /admin/jsi18n/ HTTP/1.1" 200 3343
2022-09-21 13:26:35,700 [basehttp | INFO] "GET /static/admin/js/vendor/xregexp/xregexp.js HTTP/1.1" 304 0
2022-09-21 13:26:35,774 [basehttp | INFO] "GET /static/admin/img/tooltag-add.svg HTTP/1.1" 304 0
2022-09-21 13:37:47,519 [basehttp | INFO] "GET /admin/adds/postimages/ HTTP/1.1" 200 13101
2022-09-21 13:37:47,661 [basehttp | INFO] "GET /static/admin/css/base.css HTTP/1.1" 304 0
2022-09-21 13:37:47,681 [basehttp | INFO] "GET /static/admin/css/nav_sidebar.css HTTP/1.1" 304 0
2022-09-21 13:37:47,695 [basehttp | INFO] "GET /static/admin/css/responsive.css HTTP/1.1" 304 0
2022-09-21 13:37:47,697 [basehttp | INFO] "GET /static/admin/css/changelists.css HTTP/1.1" 304 0
2022-09-21 13:37:47,727 [basehttp | INFO] "GET /static/admin/js/admin/RelatedObjectLookups.js HTTP/1.1" 304 0
2022-09-21 13:37:47,736 [basehttp | INFO] "GET /static/admin/css/fonts.css HTTP/1.1" 304 0
2022-09-21 13:37:47,729 [basehttp | INFO] "GET /static/admin/js/actions.js HTTP/1.1" 304 0
2022-09-21 13:37:47,741 [basehttp | INFO] "GET /static/admin/js/core.js HTTP/1.1" 304 0
2022-09-21 13:37:47,754 [basehttp | INFO] "GET /static/admin/js/jquery.init.js HTTP/1.1" 304 0
2022-09-21 13:37:47,756 [basehttp | INFO] "GET /static/admin/js/vendor/jquery/jquery.js HTTP/1.1" 304 0
2022-09-21 13:37:47,757 [basehttp | INFO] "GET /static/admin/js/prepopulate.js HTTP/1.1" 304 0
2022-09-21 13:37:47,772 [basehttp | INFO] "GET /admin/jsi18n/ HTTP/1.1" 200 3343
2022-09-21 13:37:47,780 [basehttp | INFO] "GET /static/admin/js/urlify.js HTTP/1.1" 304 0
2022-09-21 13:37:47,783 [basehttp | INFO] "GET /static/admin/js/vendor/xregexp/xregexp.js HTTP/1.1" 304 0
2022-09-21 13:37:47,812 [basehttp | INFO] "GET /static/admin/js/nav_sidebar.js HTTP/1.1" 304 0
2022-09-21 13:37:47,830 [basehttp | INFO] "GET /static/admin/fonts/Roboto-Regular-webfont.woff HTTP/1.1" 304 0
2022-09-21 13:37:47,834 [basehttp | INFO] "GET /static/admin/fonts/Roboto-Bold-webfont.woff HTTP/1.1" 304 0
2022-09-21 13:37:47,839 [basehttp | INFO] "GET /static/admin/img/icon-addlink.svg HTTP/1.1" 304 0
2022-09-21 13:37:47,848 [basehttp | INFO] "GET /static/admin/fonts/Roboto-Light-webfont.woff HTTP/1.1" 304 0
2022-09-21 13:37:47,876 [basehttp | INFO] "GET /static/admin/img/tooltag-add.svg HTTP/1.1" 304 0
2022-09-21 13:37:49,070 [basehttp | INFO] "GET /admin/adds/post/ HTTP/1.1" 200 13054
2022-09-21 13:37:49,107 [basehttp | INFO] "GET /admin/jsi18n/ HTTP/1.1" 200 3343
2022-09-21 13:44:23,446 [basehttp | INFO] "GET /admin/account/user/ HTTP/1.1" 200 14804
2022-09-21 13:44:23,576 [basehttp | INFO] "GET /static/admin/css/base.css HTTP/1.1" 304 0
2022-09-21 13:44:23,584 [basehttp | INFO] "GET /static/admin/js/vendor/jquery/jquery.js HTTP/1.1" 304 0
2022-09-21 13:44:23,589 [basehttp | INFO] "GET /static/admin/css/responsive.css HTTP/1.1" 304 0
2022-09-21 13:44:23,592 [basehttp | INFO] "GET /static/admin/css/changelists.css HTTP/1.1" 304 0
2022-09-21 13:44:23,624 [basehttp | INFO] "GET /static/admin/css/nav_sidebar.css HTTP/1.1" 304 0
2022-09-21 13:44:23,626 [basehttp | INFO] "GET /static/admin/js/core.js HTTP/1.1" 304 0
2022-09-21 13:44:23,634 [basehttp | INFO] "GET /admin/jsi18n/ HTTP/1.1" 200 3343
2022-09-21 13:44:23,648 [basehttp | INFO] "GET /static/admin/js/admin/RelatedObjectLookups.js HTTP/1.1" 304 0
2022-09-21 13:44:23,651 [basehttp | INFO] "GET /static/admin/css/fonts.css HTTP/1.1" 304 0
2022-09-21 13:44:23,661 [basehttp | INFO] "GET /static/admin/js/jquery.init.js HTTP/1.1" 304 0
2022-09-21 13:44:23,663 [basehttp | INFO] "GET /static/admin/js/urlify.js HTTP/1.1" 304 0
2022-09-21 13:44:23,668 [basehttp | INFO] "GET /static/admin/js/actions.js HTTP/1.1" 304 0
2022-09-21 13:44:23,676 [basehttp | INFO] "GET /static/admin/js/vendor/xregexp/xregexp.js HTTP/1.1" 304 0
2022-09-21 13:44:23,683 [basehttp | INFO] "GET /static/admin/js/prepopulate.js HTTP/1.1" 304 0
2022-09-21 13:44:23,707 [basehttp | INFO] "GET /static/admin/js/nav_sidebar.js HTTP/1.1" 304 0
2022-09-21 13:44:23,752 [basehttp | INFO] "GET /static/admin/fonts/Roboto-Regular-webfont.woff HTTP/1.1" 304 0
2022-09-21 13:44:23,758 [basehttp | INFO] "GET /static/admin/fonts/Roboto-Light-webfont.woff HTTP/1.1" 304 0
2022-09-21 13:44:23,762 [basehttp | INFO] "GET /static/admin/fonts/Roboto-Bold-webfont.woff HTTP/1.1" 304 0
2022-09-21 13:44:23,763 [basehttp | INFO] "GET /static/admin/img/icon-addlink.svg HTTP/1.1" 304 0
2022-09-21 13:44:23,779 [basehttp | INFO] "GET /static/admin/img/tooltag-add.svg HTTP/1.1" 304 0
2022-09-21 13:48:56,606 [basehttp | INFO] "GET /admin/adds/postcontacts/ HTTP/1.1" 200 13115
2022-09-21 13:48:56,659 [basehttp | INFO] "GET /static/admin/css/base.css HTTP/1.1" 304 0
2022-09-21 13:48:56,694 [basehttp | INFO] "GET /static/admin/css/changelists.css HTTP/1.1" 304 0
2022-09-21 13:48:56,704 [basehttp | INFO] "GET /static/admin/css/responsive.css HTTP/1.1" 304 0
2022-09-21 13:48:56,712 [basehttp | INFO] "GET /static/admin/js/core.js HTTP/1.1" 304 0
2022-09-21 13:48:56,738 [basehttp | INFO] "GET /static/admin/css/nav_sidebar.css HTTP/1.1" 304 0
2022-09-21 13:48:56,742 [basehttp | INFO] "GET /static/admin/js/vendor/jquery/jquery.js HTTP/1.1" 304 0
2022-09-21 13:48:56,760 [basehttp | INFO] "GET /static/admin/js/actions.js HTTP/1.1" 304 0
2022-09-21 13:48:57,015 [basehttp | INFO] "GET /static/admin/js/vendor/xregexp/xregexp.js HTTP/1.1" 304 0
2022-09-21 13:48:56,793 [basehttp | INFO] "GET /static/admin/css/fonts.css HTTP/1.1" 304 0
2022-09-21 13:48:57,022 [basehttp | INFO] "GET /static/admin/js/jquery.init.js HTTP/1.1" 304 0
2022-09-21 13:48:56,795 [basehttp | INFO] "GET /static/admin/js/urlify.js HTTP/1.1" 304 0
2022-09-21 13:48:57,032 [basehttp | INFO] "GET /static/admin/js/prepopulate.js HTTP/1.1" 304 0
2022-09-21 13:48:57,033 [basehttp | INFO] "GET /static/admin/js/admin/RelatedObjectLookups.js HTTP/1.1" 304 0
2022-09-21 13:48:57,054 [basehttp | INFO] "GET /admin/jsi18n/ HTTP/1.1" 200 3343
2022-09-21 13:48:57,160 [basehttp | INFO] "GET /static/admin/fonts/Roboto-Light-webfont.woff HTTP/1.1" 304 0
2022-09-21 13:48:57,208 [basehttp | INFO] "GET /static/admin/img/tooltag-add.svg HTTP/1.1" 304 0
2022-09-21 13:48:57,212 [basehttp | INFO] "GET /static/admin/js/nav_sidebar.js HTTP/1.1" 304 0
2022-09-21 13:48:57,219 [basehttp | INFO] "GET /static/admin/img/icon-addlink.svg HTTP/1.1" 304 0
2022-09-21 13:48:57,230 [basehttp | INFO] "GET /static/admin/fonts/Roboto-Regular-webfont.woff HTTP/1.1" 304 0
2022-09-21 13:48:57,231 [basehttp | INFO] "GET /static/admin/fonts/Roboto-Bold-webfont.woff HTTP/1.1" 304 0
2022-09-21 13:48:58,431 [basehttp | INFO] "GET /admin/adds/post/ HTTP/1.1" 200 13054
2022-09-21 13:48:58,603 [basehttp | INFO] "GET /admin/jsi18n/ HTTP/1.1" 200 3343
2022-09-21 13:49:00,363 [basehttp | INFO] "GET /admin/adds/post/ HTTP/1.1" 200 13054
2022-09-21 13:49:00,411 [basehttp | INFO] "GET /admin/jsi18n/ HTTP/1.1" 200 3343
2022-09-21 13:49:01,280 [basehttp | INFO] "GET /admin/adds/post/ HTTP/1.1" 200 13054
2022-09-21 13:49:01,342 [basehttp | INFO] "GET /admin/jsi18n/ HTTP/1.1" 200 3343
