2022-09-17 15:27:49,371 [autoreload | INFO] Watching for file changes with StatReloader
2022-09-17 15:28:15,177 [basehttp | INFO] "GET /admin/account/user/ HTTP/1.1" 302 0
2022-09-17 15:28:15,220 [basehttp | INFO] "GET /admin/login/?next=/admin/account/user/ HTTP/1.1" 200 2242
2022-09-17 15:28:17,265 [basehttp | INFO] "POST /admin/login/?next=/admin/account/user/ HTTP/1.1" 200 2410
2022-09-17 15:29:04,011 [autoreload | INFO] Watching for file changes with StatReloader
2022-09-17 15:29:06,657 [basehttp | INFO] "GET /admin/ HTTP/1.1" 302 0
2022-09-17 15:29:07,003 [basehttp | INFO] "GET /admin/login/?next=/admin/ HTTP/1.1" 200 2216
2022-09-17 15:29:08,560 [basehttp | INFO] "POST /admin/login/?next=/admin/ HTTP/1.1" 302 0
2022-09-17 15:29:08,600 [basehttp | INFO] "GET /admin/ HTTP/1.1" 200 10996
2022-09-17 15:29:12,932 [basehttp | INFO] "GET /admin/account/user/ HTTP/1.1" 200 11892
2022-09-17 15:29:12,968 [basehttp | INFO] "GET /admin/jsi18n/ HTTP/1.1" 200 3343
2022-09-17 15:29:44,857 [basehttp | INFO] "POST /api/v1/account/register/ HTTP/1.1" 201 54
2022-09-17 15:30:46,526 [autoreload | INFO] /Users/timur/Desktop/ZEON/zmall_restapi/account/admin.py changed, reloading.
2022-09-17 15:30:49,485 [autoreload | INFO] Watching for file changes with StatReloader
2022-09-17 15:31:03,465 [basehttp | INFO] "POST /api/v1/account/activate/ HTTP/1.1" 200 38
2022-09-17 15:31:07,711 [basehttp | INFO] "POST /api/v1/account/login/ HTTP/1.1" 200 583
2022-09-17 15:31:20,677 [log | WARNING] Not Found: /api/v1/account/forgot_password/
2022-09-17 15:31:20,678 [basehttp | WARNING] "POST /api/v1/account/forgot_password/ HTTP/1.1" 404 3675
2022-09-17 15:31:24,683 [log | WARNING] Not Found: /api/v1/account/forgot_password/
2022-09-17 15:31:24,684 [basehttp | WARNING] "POST /api/v1/account/forgot_password/ HTTP/1.1" 404 3675
2022-09-17 15:32:50,096 [autoreload | INFO] /Users/timur/Desktop/ZEON/zmall_restapi/account/admin.py changed, reloading.
2022-09-17 15:32:52,472 [autoreload | INFO] Watching for file changes with StatReloader
2022-09-17 15:34:23,477 [autoreload | INFO] Watching for file changes with StatReloader
2022-09-17 15:34:29,373 [basehttp | INFO] "GET /admin/account/user/ HTTP/1.1" 302 0
2022-09-17 15:34:29,430 [basehttp | INFO] "GET /admin/login/?next=/admin/account/user/ HTTP/1.1" 200 2242
2022-09-17 15:34:30,626 [basehttp | INFO] "POST /admin/login/?next=/admin/account/user/ HTTP/1.1" 302 0
2022-09-17 15:34:30,714 [basehttp | INFO] "GET /admin/account/user/ HTTP/1.1" 200 11897
2022-09-17 15:34:30,768 [basehttp | INFO] "GET /admin/jsi18n/ HTTP/1.1" 200 3343
2022-09-17 15:35:46,275 [autoreload | INFO] /Users/timur/Desktop/ZEON/zmall_restapi/account/serializers.py changed, reloading.
2022-09-17 15:35:55,619 [autoreload | INFO] Watching for file changes with StatReloader
2022-09-17 15:36:06,599 [autoreload | INFO] /Users/timur/Desktop/ZEON/zmall_restapi/account/views.py changed, reloading.
2022-09-17 15:36:08,051 [autoreload | INFO] Watching for file changes with StatReloader
2022-09-17 15:37:20,277 [autoreload | INFO] /Users/timur/Desktop/ZEON/zmall_restapi/account/urls.py changed, reloading.
2022-09-17 15:37:22,914 [autoreload | INFO] Watching for file changes with StatReloader
2022-09-17 15:37:29,855 [basehttp | INFO] "POST /api/v1/account/register/ HTTP/1.1" 201 54
2022-09-17 15:37:55,257 [basehttp | INFO] "POST /api/v1/account/activate/ HTTP/1.1" 200 38
2022-09-17 15:38:01,996 [basehttp | INFO] "POST /api/v1/account/login/ HTTP/1.1" 200 583
2022-09-17 15:38:08,920 [log | ERROR] Internal Server Error: /api/v1/account/forgot_password/ @ /Users/timur/Desktop/ZEON/zmall_restapi/venv/lib/python3.10/site-packages/django/utils/log.py : 241 : log_response
Traceback (most recent call last):
  File "/Users/timur/Desktop/ZEON/zmall_restapi/venv/lib/python3.10/site-packages/django/core/handlers/exception.py", line 55, in inner
    response = get_response(request)
  File "/Users/timur/Desktop/ZEON/zmall_restapi/venv/lib/python3.10/site-packages/django/core/handlers/base.py", line 197, in _get_response
    response = wrapped_callback(request, *callback_args, **callback_kwargs)
  File "/Users/timur/Desktop/ZEON/zmall_restapi/venv/lib/python3.10/site-packages/django/views/decorators/csrf.py", line 54, in wrapped_view
    return view_func(*args, **kwargs)
  File "/Users/timur/Desktop/ZEON/zmall_restapi/venv/lib/python3.10/site-packages/django/views/generic/base.py", line 84, in view
    return self.dispatch(request, *args, **kwargs)
  File "/Users/timur/Desktop/ZEON/zmall_restapi/venv/lib/python3.10/site-packages/rest_framework/views.py", line 509, in dispatch
    response = self.handle_exception(exc)
  File "/Users/timur/Desktop/ZEON/zmall_restapi/venv/lib/python3.10/site-packages/rest_framework/views.py", line 469, in handle_exception
    self.raise_uncaught_exception(exc)
  File "/Users/timur/Desktop/ZEON/zmall_restapi/venv/lib/python3.10/site-packages/rest_framework/views.py", line 480, in raise_uncaught_exception
    raise exc
  File "/Users/timur/Desktop/ZEON/zmall_restapi/venv/lib/python3.10/site-packages/rest_framework/views.py", line 506, in dispatch
    response = handler(request, *args, **kwargs)
  File "/Users/timur/Desktop/ZEON/zmall_restapi/account/views.py", line 54, in post
    serializer.is_valid(raise_exception=True)
  File "/Users/timur/Desktop/ZEON/zmall_restapi/venv/lib/python3.10/site-packages/rest_framework/serializers.py", line 227, in is_valid
    self._validated_data = self.run_validation(self.initial_data)
  File "/Users/timur/Desktop/ZEON/zmall_restapi/venv/lib/python3.10/site-packages/rest_framework/serializers.py", line 426, in run_validation
    value = self.to_internal_value(data)
  File "/Users/timur/Desktop/ZEON/zmall_restapi/venv/lib/python3.10/site-packages/rest_framework/serializers.py", line 485, in to_internal_value
    validated_value = validate_method(validated_value)
  File "/Users/timur/Desktop/ZEON/zmall_restapi/account/serializers.py", line 146, in validate_email
    if not User.objects.get(email=email).exists():
AttributeError: 'User' object has no attribute 'exists'
2022-09-17 15:38:08,920 [log | ERROR] Internal Server Error: /api/v1/account/forgot_password/
Traceback (most recent call last):
  File "/Users/timur/Desktop/ZEON/zmall_restapi/venv/lib/python3.10/site-packages/django/core/handlers/exception.py", line 55, in inner
    response = get_response(request)
  File "/Users/timur/Desktop/ZEON/zmall_restapi/venv/lib/python3.10/site-packages/django/core/handlers/base.py", line 197, in _get_response
    response = wrapped_callback(request, *callback_args, **callback_kwargs)
  File "/Users/timur/Desktop/ZEON/zmall_restapi/venv/lib/python3.10/site-packages/django/views/decorators/csrf.py", line 54, in wrapped_view
    return view_func(*args, **kwargs)
  File "/Users/timur/Desktop/ZEON/zmall_restapi/venv/lib/python3.10/site-packages/django/views/generic/base.py", line 84, in view
    return self.dispatch(request, *args, **kwargs)
  File "/Users/timur/Desktop/ZEON/zmall_restapi/venv/lib/python3.10/site-packages/rest_framework/views.py", line 509, in dispatch
    response = self.handle_exception(exc)
  File "/Users/timur/Desktop/ZEON/zmall_restapi/venv/lib/python3.10/site-packages/rest_framework/views.py", line 469, in handle_exception
    self.raise_uncaught_exception(exc)
  File "/Users/timur/Desktop/ZEON/zmall_restapi/venv/lib/python3.10/site-packages/rest_framework/views.py", line 480, in raise_uncaught_exception
    raise exc
  File "/Users/timur/Desktop/ZEON/zmall_restapi/venv/lib/python3.10/site-packages/rest_framework/views.py", line 506, in dispatch
    response = handler(request, *args, **kwargs)
  File "/Users/timur/Desktop/ZEON/zmall_restapi/account/views.py", line 54, in post
    serializer.is_valid(raise_exception=True)
  File "/Users/timur/Desktop/ZEON/zmall_restapi/venv/lib/python3.10/site-packages/rest_framework/serializers.py", line 227, in is_valid
    self._validated_data = self.run_validation(self.initial_data)
  File "/Users/timur/Desktop/ZEON/zmall_restapi/venv/lib/python3.10/site-packages/rest_framework/serializers.py", line 426, in run_validation
    value = self.to_internal_value(data)
  File "/Users/timur/Desktop/ZEON/zmall_restapi/venv/lib/python3.10/site-packages/rest_framework/serializers.py", line 485, in to_internal_value
    validated_value = validate_method(validated_value)
  File "/Users/timur/Desktop/ZEON/zmall_restapi/account/serializers.py", line 146, in validate_email
    if not User.objects.get(email=email).exists():
AttributeError: 'User' object has no attribute 'exists'
2022-09-17 15:38:08,921 [basehttp | ERROR] "POST /api/v1/account/forgot_password/ HTTP/1.1" 500 104861 @ /Users/timur/Desktop/ZEON/zmall_restapi/venv/lib/python3.10/site-packages/django/core/servers/basehttp.py : 187 : log_message
2022-09-17 15:38:08,921 [basehttp | ERROR] "POST /api/v1/account/forgot_password/ HTTP/1.1" 500 104861
2022-09-17 15:38:14,275 [log | ERROR] Internal Server Error: /api/v1/account/forgot_password/ @ /Users/timur/Desktop/ZEON/zmall_restapi/venv/lib/python3.10/site-packages/django/utils/log.py : 241 : log_response
Traceback (most recent call last):
  File "/Users/timur/Desktop/ZEON/zmall_restapi/venv/lib/python3.10/site-packages/django/core/handlers/exception.py", line 55, in inner
    response = get_response(request)
  File "/Users/timur/Desktop/ZEON/zmall_restapi/venv/lib/python3.10/site-packages/django/core/handlers/base.py", line 197, in _get_response
    response = wrapped_callback(request, *callback_args, **callback_kwargs)
  File "/Users/timur/Desktop/ZEON/zmall_restapi/venv/lib/python3.10/site-packages/django/views/decorators/csrf.py", line 54, in wrapped_view
    return view_func(*args, **kwargs)
  File "/Users/timur/Desktop/ZEON/zmall_restapi/venv/lib/python3.10/site-packages/django/views/generic/base.py", line 84, in view
    return self.dispatch(request, *args, **kwargs)
  File "/Users/timur/Desktop/ZEON/zmall_restapi/venv/lib/python3.10/site-packages/rest_framework/views.py", line 509, in dispatch
    response = self.handle_exception(exc)
  File "/Users/timur/Desktop/ZEON/zmall_restapi/venv/lib/python3.10/site-packages/rest_framework/views.py", line 469, in handle_exception
    self.raise_uncaught_exception(exc)
  File "/Users/timur/Desktop/ZEON/zmall_restapi/venv/lib/python3.10/site-packages/rest_framework/views.py", line 480, in raise_uncaught_exception
    raise exc
  File "/Users/timur/Desktop/ZEON/zmall_restapi/venv/lib/python3.10/site-packages/rest_framework/views.py", line 506, in dispatch
    response = handler(request, *args, **kwargs)
  File "/Users/timur/Desktop/ZEON/zmall_restapi/account/views.py", line 54, in post
    serializer.is_valid(raise_exception=True)
  File "/Users/timur/Desktop/ZEON/zmall_restapi/venv/lib/python3.10/site-packages/rest_framework/serializers.py", line 227, in is_valid
    self._validated_data = self.run_validation(self.initial_data)
  File "/Users/timur/Desktop/ZEON/zmall_restapi/venv/lib/python3.10/site-packages/rest_framework/serializers.py", line 426, in run_validation
    value = self.to_internal_value(data)
  File "/Users/timur/Desktop/ZEON/zmall_restapi/venv/lib/python3.10/site-packages/rest_framework/serializers.py", line 485, in to_internal_value
    validated_value = validate_method(validated_value)
  File "/Users/timur/Desktop/ZEON/zmall_restapi/account/serializers.py", line 146, in validate_email
    if not User.objects.get(email=email).exists():
AttributeError: 'User' object has no attribute 'exists'
2022-09-17 15:38:14,275 [log | ERROR] Internal Server Error: /api/v1/account/forgot_password/
Traceback (most recent call last):
  File "/Users/timur/Desktop/ZEON/zmall_restapi/venv/lib/python3.10/site-packages/django/core/handlers/exception.py", line 55, in inner
    response = get_response(request)
  File "/Users/timur/Desktop/ZEON/zmall_restapi/venv/lib/python3.10/site-packages/django/core/handlers/base.py", line 197, in _get_response
    response = wrapped_callback(request, *callback_args, **callback_kwargs)
  File "/Users/timur/Desktop/ZEON/zmall_restapi/venv/lib/python3.10/site-packages/django/views/decorators/csrf.py", line 54, in wrapped_view
    return view_func(*args, **kwargs)
  File "/Users/timur/Desktop/ZEON/zmall_restapi/venv/lib/python3.10/site-packages/django/views/generic/base.py", line 84, in view
    return self.dispatch(request, *args, **kwargs)
  File "/Users/timur/Desktop/ZEON/zmall_restapi/venv/lib/python3.10/site-packages/rest_framework/views.py", line 509, in dispatch
    response = self.handle_exception(exc)
  File "/Users/timur/Desktop/ZEON/zmall_restapi/venv/lib/python3.10/site-packages/rest_framework/views.py", line 469, in handle_exception
    self.raise_uncaught_exception(exc)
  File "/Users/timur/Desktop/ZEON/zmall_restapi/venv/lib/python3.10/site-packages/rest_framework/views.py", line 480, in raise_uncaught_exception
    raise exc
  File "/Users/timur/Desktop/ZEON/zmall_restapi/venv/lib/python3.10/site-packages/rest_framework/views.py", line 506, in dispatch
    response = handler(request, *args, **kwargs)
  File "/Users/timur/Desktop/ZEON/zmall_restapi/account/views.py", line 54, in post
    serializer.is_valid(raise_exception=True)
  File "/Users/timur/Desktop/ZEON/zmall_restapi/venv/lib/python3.10/site-packages/rest_framework/serializers.py", line 227, in is_valid
    self._validated_data = self.run_validation(self.initial_data)
  File "/Users/timur/Desktop/ZEON/zmall_restapi/venv/lib/python3.10/site-packages/rest_framework/serializers.py", line 426, in run_validation
    value = self.to_internal_value(data)
  File "/Users/timur/Desktop/ZEON/zmall_restapi/venv/lib/python3.10/site-packages/rest_framework/serializers.py", line 485, in to_internal_value
    validated_value = validate_method(validated_value)
  File "/Users/timur/Desktop/ZEON/zmall_restapi/account/serializers.py", line 146, in validate_email
    if not User.objects.get(email=email).exists():
AttributeError: 'User' object has no attribute 'exists'
2022-09-17 15:38:14,276 [basehttp | ERROR] "POST /api/v1/account/forgot_password/ HTTP/1.1" 500 104861 @ /Users/timur/Desktop/ZEON/zmall_restapi/venv/lib/python3.10/site-packages/django/core/servers/basehttp.py : 187 : log_message
2022-09-17 15:38:14,276 [basehttp | ERROR] "POST /api/v1/account/forgot_password/ HTTP/1.1" 500 104861
2022-09-17 15:40:08,406 [autoreload | INFO] /Users/timur/Desktop/ZEON/zmall_restapi/account/serializers.py changed, reloading.
2022-09-17 15:40:11,090 [autoreload | INFO] Watching for file changes with StatReloader
2022-09-17 15:40:51,012 [basehttp | INFO] "POST /api/v1/account/forgot_password/ HTTP/1.1" 200 42
2022-09-17 15:41:27,090 [basehttp | INFO] "POST /api/v1/account/login/ HTTP/1.1" 200 583
2022-09-17 15:42:07,505 [log | WARNING] Bad Request: /api/v1/account/change_password/
2022-09-17 15:42:07,505 [basehttp | WARNING] "POST /api/v1/account/change_password/ HTTP/1.1" 400 37
2022-09-17 15:42:35,856 [log | WARNING] Bad Request: /api/v1/account/change_password/
2022-09-17 15:42:35,856 [basehttp | WARNING] "POST /api/v1/account/change_password/ HTTP/1.1" 400 37
2022-09-17 15:42:57,811 [log | WARNING] Bad Request: /api/v1/account/change_password/
2022-09-17 15:42:57,811 [basehttp | WARNING] "POST /api/v1/account/change_password/ HTTP/1.1" 400 40
2022-09-17 15:43:10,157 [basehttp | INFO] "POST /api/v1/account/change_password/ HTTP/1.1" 200 45
2022-09-17 15:43:42,208 [basehttp | INFO] "POST /api/v1/account/login/ HTTP/1.1" 200 583
2022-09-17 15:44:07,270 [autoreload | INFO] /Users/timur/Desktop/ZEON/zmall_restapi/account/serializers.py changed, reloading.
2022-09-17 15:44:10,586 [autoreload | INFO] Watching for file changes with StatReloader
2022-09-17 15:44:45,684 [autoreload | INFO] /Users/timur/Desktop/ZEON/zmall_restapi/account/serializers.py changed, reloading.
2022-09-17 15:44:47,734 [autoreload | INFO] Watching for file changes with StatReloader
2022-09-17 15:44:53,356 [autoreload | INFO] /Users/timur/Desktop/ZEON/zmall_restapi/account/serializers.py changed, reloading.
2022-09-17 15:44:54,424 [autoreload | INFO] Watching for file changes with StatReloader
2022-09-17 15:45:07,253 [autoreload | INFO] /Users/timur/Desktop/ZEON/zmall_restapi/account/serializers.py changed, reloading.
2022-09-17 15:45:08,429 [autoreload | INFO] Watching for file changes with StatReloader
2022-09-17 15:46:25,995 [autoreload | INFO] /Users/timur/Desktop/ZEON/zmall_restapi/account/serializers.py changed, reloading.
2022-09-17 15:46:28,500 [autoreload | INFO] Watching for file changes with StatReloader
2022-09-17 15:49:04,244 [autoreload | INFO] /Users/timur/Desktop/ZEON/zmall_restapi/account/views.py changed, reloading.
2022-09-17 15:49:07,349 [autoreload | INFO] Watching for file changes with StatReloader
2022-09-17 15:52:02,434 [autoreload | INFO] /Users/timur/Desktop/ZEON/zmall_restapi/account/views.py changed, reloading.
2022-09-17 15:52:04,832 [autoreload | INFO] Watching for file changes with StatReloader
2022-09-17 15:53:30,509 [autoreload | INFO] /Users/timur/Desktop/ZEON/zmall_restapi/account/views.py changed, reloading.
2022-09-17 15:53:32,925 [autoreload | INFO] Watching for file changes with StatReloader
2022-09-17 15:53:39,118 [autoreload | INFO] /Users/timur/Desktop/ZEON/zmall_restapi/account/views.py changed, reloading.
2022-09-17 15:53:40,593 [autoreload | INFO] Watching for file changes with StatReloader
2022-09-17 15:55:21,463 [autoreload | INFO] /Users/timur/Desktop/ZEON/zmall_restapi/account/views.py changed, reloading.
2022-09-17 15:55:22,480 [autoreload | INFO] Watching for file changes with StatReloader
2022-09-17 15:55:41,480 [log | WARNING] Not Found: /api/v1/account/userview/
2022-09-17 15:55:41,480 [basehttp | WARNING] "GET /api/v1/account/userview/ HTTP/1.1" 404 4041
2022-09-17 15:55:45,431 [log | WARNING] Not Found: /api/v1/account/userview/1/
2022-09-17 15:55:45,432 [basehttp | WARNING] "GET /api/v1/account/userview/1/ HTTP/1.1" 404 4047
2022-09-17 15:55:51,374 [log | WARNING] Not Found: /api/v1/account/userview/3
2022-09-17 15:55:51,375 [basehttp | WARNING] "GET /api/v1/account/userview/3 HTTP/1.1" 404 4044
2022-09-17 15:56:01,171 [basehttp | INFO] "GET /admin/ HTTP/1.1" 200 10996
2022-09-17 15:56:02,662 [basehttp | INFO] "GET /admin/account/user/ HTTP/1.1" 200 12229
2022-09-17 15:56:02,700 [basehttp | INFO] "GET /admin/jsi18n/ HTTP/1.1" 200 3343
2022-09-17 15:56:06,892 [basehttp | INFO] "GET /admin/ HTTP/1.1" 200 10996
2022-09-17 15:56:10,677 [log | WARNING] Not Found: /api/v1/account/userview/2/
2022-09-17 15:56:10,677 [basehttp | WARNING] "GET /api/v1/account/userview/2/ HTTP/1.1" 404 4047
2022-09-17 15:56:39,975 [log | WARNING] Not Found: /api/v1/account/userview/2
2022-09-17 15:56:39,976 [basehttp | WARNING] "GET /api/v1/account/userview/2 HTTP/1.1" 404 4044
2022-09-17 15:57:15,481 [log | WARNING] Not Found: /api/v1/account/userview/2/
2022-09-17 15:57:15,481 [basehttp | WARNING] "GET /api/v1/account/userview/2/ HTTP/1.1" 404 4047
2022-09-17 15:57:18,761 [log | WARNING] Not Found: /api/v1/account/userview/2/
2022-09-17 15:57:18,761 [basehttp | WARNING] "GET /api/v1/account/userview/2/ HTTP/1.1" 404 4047
2022-09-17 15:57:19,817 [log | WARNING] Not Found: /api/v1/account/userview/2/
2022-09-17 15:57:19,818 [basehttp | WARNING] "GET /api/v1/account/userview/2/ HTTP/1.1" 404 4047
2022-09-17 15:57:49,353 [autoreload | INFO] /Users/timur/Desktop/ZEON/zmall_restapi/account/urls.py changed, reloading.
2022-09-17 15:57:52,047 [autoreload | INFO] Watching for file changes with StatReloader
2022-09-17 15:58:11,784 [autoreload | INFO] /Users/timur/Desktop/ZEON/zmall_restapi/account/urls.py changed, reloading.
2022-09-17 15:58:13,881 [autoreload | INFO] Watching for file changes with StatReloader
2022-09-17 15:58:15,336 [log | WARNING] Not Found: /api/v1/account/userview/2/
2022-09-17 15:58:15,337 [basehttp | WARNING] "GET /api/v1/account/userview/2/ HTTP/1.1" 404 4062
2022-09-17 15:58:16,863 [log | WARNING] Not Found: /api/v1/account/userview/2/
2022-09-17 15:58:16,864 [basehttp | WARNING] "GET /api/v1/account/userview/2/ HTTP/1.1" 404 4062
2022-09-17 15:58:34,546 [log | WARNING] Not Found: /api/v1/account/userview/2/
2022-09-17 15:58:34,548 [basehttp | WARNING] "GET /api/v1/account/userview/2/ HTTP/1.1" 404 4062
2022-09-17 15:58:59,882 [autoreload | INFO] /Users/timur/Desktop/ZEON/zmall_restapi/account/urls.py changed, reloading.
2022-09-17 15:59:01,001 [autoreload | INFO] Watching for file changes with StatReloader
2022-09-17 15:59:05,424 [basehttp | INFO] "GET /api/v1/account/userview/2/ HTTP/1.1" 200 5219
2022-09-17 15:59:12,097 [basehttp | INFO] "GET /api/v1/account/userview/2/ HTTP/1.1" 200 2
2022-09-17 15:59:14,074 [basehttp | INFO] "GET /api/v1/account/userview/2/ HTTP/1.1" 200 2
2022-09-17 15:59:30,274 [basehttp | INFO] "GET /api/v1/account/userview/2/ HTTP/1.1" 200 2
2022-09-17 16:00:19,321 [basehttp | INFO] "GET /api/v1/account/userview/2/ HTTP/1.1" 200 2
2022-09-17 16:00:20,239 [basehttp | INFO] "GET /api/v1/account/userview/2/ HTTP/1.1" 200 2
2022-09-17 16:00:54,702 [autoreload | INFO] /Users/timur/Desktop/ZEON/zmall_restapi/account/urls.py changed, reloading.
2022-09-17 16:00:57,907 [autoreload | INFO] Watching for file changes with StatReloader
2022-09-17 16:04:56,244 [autoreload | INFO] /Users/timur/Desktop/ZEON/zmall_restapi/account/views.py changed, reloading.
2022-09-17 16:04:58,434 [autoreload | INFO] Watching for file changes with StatReloader
2022-09-17 16:05:18,090 [autoreload | INFO] /Users/timur/Desktop/ZEON/zmall_restapi/account/urls.py changed, reloading.
2022-09-17 16:05:19,112 [autoreload | INFO] Watching for file changes with StatReloader
2022-09-17 16:05:26,345 [basehttp | INFO] "GET /api/v1/account/useraccount HTTP/1.1" 301 0
2022-09-17 16:05:26,435 [basehttp | INFO] "GET /api/v1/account/useraccount/ HTTP/1.1" 200 2
2022-09-17 16:05:27,923 [basehttp | INFO] "GET /api/v1/account/useraccount HTTP/1.1" 301 0
2022-09-17 16:05:27,929 [basehttp | INFO] "GET /api/v1/account/useraccount/ HTTP/1.1" 200 2
2022-09-17 16:05:28,945 [basehttp | INFO] "GET /api/v1/account/useraccount HTTP/1.1" 301 0
2022-09-17 16:05:28,950 [basehttp | INFO] "GET /api/v1/account/useraccount/ HTTP/1.1" 200 2
2022-09-17 16:05:41,383 [basehttp | INFO] "GET /api/v1/account/useraccount HTTP/1.1" 301 0
2022-09-17 16:05:41,441 [log | WARNING] Unauthorized: /api/v1/account/useraccount/
2022-09-17 16:05:41,441 [basehttp | WARNING] "GET /api/v1/account/useraccount/ HTTP/1.1" 401 5181
2022-09-17 16:05:53,546 [basehttp | INFO] "POST /api/v1/account/login/ HTTP/1.1" 200 583
2022-09-17 16:06:07,060 [basehttp | INFO] "GET /api/v1/account/useraccount HTTP/1.1" 301 0
2022-09-17 16:06:07,069 [basehttp | INFO] "GET /api/v1/account/useraccount/ HTTP/1.1" 200 2
2022-09-17 16:06:09,921 [basehttp | INFO] "GET /api/v1/account/useraccount/ HTTP/1.1" 200 2
2022-09-17 16:06:11,509 [basehttp | INFO] "GET /api/v1/account/useraccount/ HTTP/1.1" 200 2
2022-09-17 16:07:02,364 [autoreload | INFO] /Users/timur/Desktop/ZEON/zmall_restapi/account/urls.py changed, reloading.
2022-09-17 16:07:05,084 [autoreload | INFO] Watching for file changes with StatReloader
2022-09-17 16:07:09,621 [log | WARNING] Not Found: /api/v1/account/userview/3
2022-09-17 16:07:09,621 [basehttp | WARNING] "GET /api/v1/account/userview/3 HTTP/1.1" 404 23
2022-09-17 16:07:15,400 [basehttp | INFO] "GET /api/v1/account/userview/2 HTTP/1.1" 200 2
2022-09-17 16:07:18,566 [log | WARNING] Not Found: /api/v1/account/userview/4
2022-09-17 16:07:18,567 [basehttp | WARNING] "GET /api/v1/account/userview/4 HTTP/1.1" 404 23
2022-09-17 16:07:36,279 [basehttp | INFO] "GET /swagger/ HTTP/1.1" 200 2160
2022-09-17 16:07:36,591 [basehttp | INFO] "GET /swagger/?format=openapi HTTP/1.1" 200 4260
2022-09-17 16:07:37,764 [basehttp | INFO] "GET /swagger/ HTTP/1.1" 200 2160
2022-09-17 16:07:37,935 [basehttp | INFO] "GET /swagger/?format=openapi HTTP/1.1" 200 4260
2022-09-17 16:08:37,243 [autoreload | INFO] /Users/timur/Desktop/ZEON/zmall_restapi/account/serializers.py changed, reloading.
2022-09-17 16:08:39,687 [autoreload | INFO] Watching for file changes with StatReloader
2022-09-17 16:08:41,035 [log | WARNING] Not Found: /api/v1/account/userview/4
2022-09-17 16:08:41,036 [basehttp | WARNING] "GET /api/v1/account/userview/4 HTTP/1.1" 404 23
2022-09-17 16:08:42,540 [log | WARNING] Not Found: /api/v1/account/userview/4
2022-09-17 16:08:42,540 [basehttp | WARNING] "GET /api/v1/account/userview/4 HTTP/1.1" 404 23
2022-09-17 16:08:47,056 [basehttp | INFO] "GET /api/v1/account/userview/2 HTTP/1.1" 200 424
2022-09-17 16:33:51,866 [autoreload | INFO] /Users/timur/Desktop/ZEON/zmall_restapi/account/serializers.py changed, reloading.
2022-09-17 16:33:55,300 [autoreload | INFO] Watching for file changes with StatReloader
2022-09-17 16:34:12,602 [basehttp | INFO] "GET /api/v1/account/userview/2 HTTP/1.1" 200 83
2022-09-17 16:36:06,524 [autoreload | INFO] /Users/timur/Desktop/ZEON/zmall_restapi/account/views.py changed, reloading.
2022-09-17 16:36:08,662 [autoreload | INFO] Watching for file changes with StatReloader
2022-09-17 16:37:10,630 [autoreload | INFO] /Users/timur/Desktop/ZEON/zmall_restapi/account/urls.py changed, reloading.
2022-09-17 16:37:12,062 [autoreload | INFO] Watching for file changes with StatReloader
2022-09-17 16:38:34,312 [basehttp | INFO] "GET /api/v1/account/usercrud/ HTTP/1.1" 200 83
2022-09-17 16:39:32,656 [log | WARNING] Unsupported Media Type: /api/v1/account/usercrud/
2022-09-17 16:39:32,656 [basehttp | WARNING] "PATCH /api/v1/account/usercrud/ HTTP/1.1" 415 62
2022-09-17 16:40:24,780 [basehttp | INFO] "PATCH /api/v1/account/usercrud/ HTTP/1.1" 200 83
2022-09-17 16:40:34,806 [basehttp | INFO] "DELETE /api/v1/account/usercrud/ HTTP/1.1" 204 0
2022-09-17 16:40:45,687 [basehttp | INFO] "GET /admin/ HTTP/1.1" 200 10996
2022-09-17 16:40:46,860 [basehttp | INFO] "GET /admin/account/user/ HTTP/1.1" 200 11897
2022-09-17 16:40:46,881 [basehttp | INFO] "GET /admin/jsi18n/ HTTP/1.1" 200 3343
2022-09-17 16:42:12,186 [basehttp | INFO] "GET /swagger/ HTTP/1.1" 200 2160
2022-09-17 16:42:12,805 [basehttp | INFO] "GET /swagger/?format=openapi HTTP/1.1" 200 5624
2022-09-17 16:44:39,694 [basehttp | INFO] "GET /swagger/ HTTP/1.1" 200 2160
2022-09-17 16:44:39,884 [basehttp | INFO] "GET /swagger/?format=openapi HTTP/1.1" 200 5624
2022-09-17 16:44:40,717 [basehttp | INFO] "GET /swagger/ HTTP/1.1" 200 2160
2022-09-17 16:44:40,842 [basehttp | INFO] "GET /swagger/?format=openapi HTTP/1.1" 200 5624
2022-09-17 16:45:05,216 [autoreload | INFO] /Users/timur/Desktop/ZEON/zmall_restapi/config/urls.py changed, reloading.
2022-09-17 16:45:08,002 [autoreload | INFO] Watching for file changes with StatReloader
2022-09-17 16:45:11,509 [basehttp | INFO] "GET /swagger/ HTTP/1.1" 200 2160
2022-09-17 16:45:11,840 [basehttp | INFO] "GET /swagger/?format=openapi HTTP/1.1" 200 21701
2022-09-17 16:45:12,753 [basehttp | INFO] "GET /swagger/ HTTP/1.1" 200 2160
2022-09-17 16:45:12,876 [basehttp | INFO] "GET /swagger/?format=openapi HTTP/1.1" 200 21701
2022-09-17 16:45:59,780 [basehttp | INFO] "GET /swagger/ HTTP/1.1" 200 2160
2022-09-17 16:45:59,970 [basehttp | INFO] "GET /swagger/?format=openapi HTTP/1.1" 200 21701
2022-09-17 16:46:01,081 [basehttp | INFO] "GET /swagger/ HTTP/1.1" 200 2160
2022-09-17 16:46:01,221 [basehttp | INFO] "GET /swagger/?format=openapi HTTP/1.1" 200 21701
2022-09-17 16:49:26,586 [basehttp | INFO] "GET /swagger/ HTTP/1.1" 200 2160
2022-09-17 16:49:26,804 [basehttp | INFO] "GET /swagger/?format=openapi HTTP/1.1" 200 21701
2022-09-17 16:54:10,610 [autoreload | INFO] /Users/timur/Desktop/ZEON/zmall_restapi/adds/serializers.py changed, reloading.
2022-09-17 16:54:13,696 [autoreload | INFO] Watching for file changes with StatReloader
2022-09-17 16:55:46,234 [autoreload | INFO] /Users/timur/Desktop/ZEON/zmall_restapi/adds/models.py changed, reloading.
2022-09-17 16:55:48,933 [autoreload | INFO] Watching for file changes with StatReloader
2022-09-17 16:59:26,773 [autoreload | INFO] /Users/timur/Desktop/ZEON/zmall_restapi/adds/serializers.py changed, reloading.
2022-09-17 16:59:30,116 [autoreload | INFO] Watching for file changes with StatReloader
2022-09-17 17:00:13,015 [autoreload | INFO] /Users/timur/Desktop/ZEON/zmall_restapi/adds/views.py changed, reloading.
2022-09-17 17:00:15,284 [autoreload | INFO] Watching for file changes with StatReloader
2022-09-17 17:05:46,344 [autoreload | INFO] /Users/timur/Desktop/ZEON/zmall_restapi/adds/views.py changed, reloading.
2022-09-17 17:05:48,651 [autoreload | INFO] Watching for file changes with StatReloader
2022-09-17 17:06:02,778 [autoreload | INFO] /Users/timur/Desktop/ZEON/zmall_restapi/adds/urls.py changed, reloading.
2022-09-17 17:06:04,059 [autoreload | INFO] Watching for file changes with StatReloader
2022-09-17 17:06:08,113 [basehttp | INFO] "GET /swagger/ HTTP/1.1" 200 2160
2022-09-17 17:06:08,427 [basehttp | INFO] "GET /swagger/?format=openapi HTTP/1.1" 200 23532
2022-09-17 17:06:36,489 [basehttp | INFO] "GET /admin/adds/category/add/ HTTP/1.1" 200 11372
2022-09-17 17:06:36,518 [basehttp | INFO] "GET /admin/jsi18n/ HTTP/1.1" 200 3343
2022-09-17 17:06:57,606 [basehttp | INFO] "POST /admin/adds/category/add/ HTTP/1.1" 302 0
2022-09-17 17:06:57,682 [basehttp | INFO] "GET /admin/adds/category/ HTTP/1.1" 200 11531
2022-09-17 17:06:57,726 [basehttp | INFO] "GET /admin/jsi18n/ HTTP/1.1" 200 3343
2022-09-17 17:06:58,947 [basehttp | INFO] "GET /admin/adds/city/add/ HTTP/1.1" 200 11298
2022-09-17 17:06:58,984 [basehttp | INFO] "GET /admin/jsi18n/ HTTP/1.1" 200 3343
2022-09-17 17:07:13,224 [basehttp | INFO] "POST /admin/adds/city/add/ HTTP/1.1" 302 0
2022-09-17 17:07:13,278 [basehttp | INFO] "GET /admin/adds/city/ HTTP/1.1" 200 11479
2022-09-17 17:07:13,305 [basehttp | INFO] "GET /admin/jsi18n/ HTTP/1.1" 200 3343
2022-09-17 17:07:21,489 [basehttp | INFO] "GET /admin/adds/subcategory/add/ HTTP/1.1" 200 12027
2022-09-17 17:07:21,515 [basehttp | INFO] "GET /admin/jsi18n/ HTTP/1.1" 200 3343
2022-09-17 17:07:25,902 [basehttp | INFO] "POST /admin/adds/subcategory/add/ HTTP/1.1" 302 0
2022-09-17 17:07:25,956 [basehttp | INFO] "GET /admin/adds/subcategory/ HTTP/1.1" 200 11579
2022-09-17 17:07:25,988 [basehttp | INFO] "GET /admin/jsi18n/ HTTP/1.1" 200 3343
2022-09-17 17:07:28,207 [basehttp | INFO] "GET /admin/adds/subscription/add/ HTTP/1.1" 200 12014
2022-09-17 17:07:28,232 [basehttp | INFO] "GET /admin/jsi18n/ HTTP/1.1" 200 3343
2022-09-17 17:07:35,828 [basehttp | INFO] "POST /admin/adds/subscription/add/ HTTP/1.1" 302 0
2022-09-17 17:07:35,887 [basehttp | INFO] "GET /admin/adds/subscription/ HTTP/1.1" 200 11588
2022-09-17 17:07:35,925 [basehttp | INFO] "GET /admin/jsi18n/ HTTP/1.1" 200 3343
2022-09-17 17:07:38,033 [basehttp | INFO] "GET /admin/adds/post/ HTTP/1.1" 200 10147
2022-09-17 17:07:38,056 [basehttp | INFO] "GET /admin/jsi18n/ HTTP/1.1" 200 3343
2022-09-17 17:07:39,559 [basehttp | INFO] "GET /admin/adds/post/add/ HTTP/1.1" 200 21477
2022-09-17 17:07:39,584 [basehttp | INFO] "GET /admin/jsi18n/ HTTP/1.1" 200 3343
2022-09-17 17:07:39,598 [basehttp | INFO] "GET /static/admin/img/icon-deletelink.svg HTTP/1.1" 304 0
2022-09-17 17:08:15,237 [basehttp | INFO] "POST /admin/adds/post/add/ HTTP/1.1" 302 0
2022-09-17 17:08:15,302 [basehttp | INFO] "GET /admin/adds/post/ HTTP/1.1" 200 11487
2022-09-17 17:08:15,339 [basehttp | INFO] "GET /admin/jsi18n/ HTTP/1.1" 200 3343
2022-09-17 17:08:33,929 [basehttp | INFO] "GET /api/v1/adds/favoritecreate HTTP/1.1" 301 0
2022-09-17 17:08:33,986 [log | WARNING] Method Not Allowed: /api/v1/adds/favoritecreate/
2022-09-17 17:08:33,987 [basehttp | WARNING] "GET /api/v1/adds/favoritecreate/ HTTP/1.1" 405 7371
2022-09-17 17:09:04,138 [autoreload | INFO] /Users/timur/Desktop/ZEON/zmall_restapi/adds/urls.py changed, reloading.
2022-09-17 17:09:06,794 [autoreload | INFO] Watching for file changes with StatReloader
2022-09-17 17:09:12,267 [basehttp | INFO] "GET /admin/adds/post/add/ HTTP/1.1" 200 21477
2022-09-17 17:09:12,310 [basehttp | INFO] "GET /admin/jsi18n/ HTTP/1.1" 200 3343
2022-09-17 17:09:42,466 [basehttp | INFO] "POST /admin/adds/post/add/ HTTP/1.1" 302 0
2022-09-17 17:09:42,543 [basehttp | INFO] "GET /admin/adds/post/ HTTP/1.1" 200 11695
2022-09-17 17:09:42,590 [basehttp | INFO] "GET /admin/jsi18n/ HTTP/1.1" 200 3343
2022-09-17 17:09:46,144 [log | WARNING] Method Not Allowed: /api/v1/adds/favoritecreate/
2022-09-17 17:09:46,144 [basehttp | WARNING] "GET /api/v1/adds/favoritecreate/ HTTP/1.1" 405 7453
2022-09-17 17:09:48,251 [log | WARNING] Method Not Allowed: /api/v1/adds/favoritecreate/
2022-09-17 17:09:48,252 [basehttp | WARNING] "GET /api/v1/adds/favoritecreate/ HTTP/1.1" 405 7453
2022-09-17 17:09:55,081 [log | ERROR] Internal Server Error: /api/v1/adds/favoritecreate/ @ /Users/timur/Desktop/ZEON/zmall_restapi/venv/lib/python3.10/site-packages/django/utils/log.py : 241 : log_response
Traceback (most recent call last):
  File "/Users/timur/Desktop/ZEON/zmall_restapi/venv/lib/python3.10/site-packages/rest_framework/serializers.py", line 962, in create
    instance = ModelClass._default_manager.create(**validated_data)
  File "/Users/timur/Desktop/ZEON/zmall_restapi/venv/lib/python3.10/site-packages/django/db/models/manager.py", line 85, in manager_method
    return getattr(self.get_queryset(), name)(*args, **kwargs)
  File "/Users/timur/Desktop/ZEON/zmall_restapi/venv/lib/python3.10/site-packages/django/db/models/query.py", line 512, in create
    obj = self.model(**kwargs)
  File "/Users/timur/Desktop/ZEON/zmall_restapi/venv/lib/python3.10/site-packages/django/db/models/base.py", line 559, in __init__
    raise TypeError(
TypeError: Favorite() got an unexpected keyword argument 'owner'

During handling of the above exception, another exception occurred:

Traceback (most recent call last):
  File "/Users/timur/Desktop/ZEON/zmall_restapi/venv/lib/python3.10/site-packages/django/core/handlers/exception.py", line 55, in inner
    response = get_response(request)
  File "/Users/timur/Desktop/ZEON/zmall_restapi/venv/lib/python3.10/site-packages/django/core/handlers/base.py", line 197, in _get_response
    response = wrapped_callback(request, *callback_args, **callback_kwargs)
  File "/Users/timur/Desktop/ZEON/zmall_restapi/venv/lib/python3.10/site-packages/django/views/decorators/csrf.py", line 54, in wrapped_view
    return view_func(*args, **kwargs)
  File "/Users/timur/Desktop/ZEON/zmall_restapi/venv/lib/python3.10/site-packages/django/views/generic/base.py", line 84, in view
    return self.dispatch(request, *args, **kwargs)
  File "/Users/timur/Desktop/ZEON/zmall_restapi/venv/lib/python3.10/site-packages/rest_framework/views.py", line 509, in dispatch
    response = self.handle_exception(exc)
  File "/Users/timur/Desktop/ZEON/zmall_restapi/venv/lib/python3.10/site-packages/rest_framework/views.py", line 469, in handle_exception
    self.raise_uncaught_exception(exc)
  File "/Users/timur/Desktop/ZEON/zmall_restapi/venv/lib/python3.10/site-packages/rest_framework/views.py", line 480, in raise_uncaught_exception
    raise exc
  File "/Users/timur/Desktop/ZEON/zmall_restapi/venv/lib/python3.10/site-packages/rest_framework/views.py", line 506, in dispatch
    response = handler(request, *args, **kwargs)
  File "/Users/timur/Desktop/ZEON/zmall_restapi/venv/lib/python3.10/site-packages/rest_framework/generics.py", line 190, in post
    return self.create(request, *args, **kwargs)
  File "/Users/timur/Desktop/ZEON/zmall_restapi/venv/lib/python3.10/site-packages/rest_framework/mixins.py", line 19, in create
    self.perform_create(serializer)
  File "/Users/timur/Desktop/ZEON/zmall_restapi/adds/views.py", line 198, in perform_create
    serializer.save(owner=self.request.user)
  File "/Users/timur/Desktop/ZEON/zmall_restapi/venv/lib/python3.10/site-packages/rest_framework/serializers.py", line 212, in save
    self.instance = self.create(validated_data)
  File "/Users/timur/Desktop/ZEON/zmall_restapi/venv/lib/python3.10/site-packages/rest_framework/serializers.py", line 981, in create
    raise TypeError(msg)
TypeError: Got a `TypeError` when calling `Favorite.objects.create()`. This may be because you have a writable field on the serializer class that is not a valid argument to `Favorite.objects.create()`. You may need to make the field read-only, or override the FavoritesSerializer.create() method to handle this correctly.
Original exception was:
 Traceback (most recent call last):
  File "/Users/timur/Desktop/ZEON/zmall_restapi/venv/lib/python3.10/site-packages/rest_framework/serializers.py", line 962, in create
    instance = ModelClass._default_manager.create(**validated_data)
  File "/Users/timur/Desktop/ZEON/zmall_restapi/venv/lib/python3.10/site-packages/django/db/models/manager.py", line 85, in manager_method
    return getattr(self.get_queryset(), name)(*args, **kwargs)
  File "/Users/timur/Desktop/ZEON/zmall_restapi/venv/lib/python3.10/site-packages/django/db/models/query.py", line 512, in create
    obj = self.model(**kwargs)
  File "/Users/timur/Desktop/ZEON/zmall_restapi/venv/lib/python3.10/site-packages/django/db/models/base.py", line 559, in __init__
    raise TypeError(
TypeError: Favorite() got an unexpected keyword argument 'owner'

2022-09-17 17:09:55,081 [log | ERROR] Internal Server Error: /api/v1/adds/favoritecreate/
Traceback (most recent call last):
  File "/Users/timur/Desktop/ZEON/zmall_restapi/venv/lib/python3.10/site-packages/rest_framework/serializers.py", line 962, in create
    instance = ModelClass._default_manager.create(**validated_data)
  File "/Users/timur/Desktop/ZEON/zmall_restapi/venv/lib/python3.10/site-packages/django/db/models/manager.py", line 85, in manager_method
    return getattr(self.get_queryset(), name)(*args, **kwargs)
  File "/Users/timur/Desktop/ZEON/zmall_restapi/venv/lib/python3.10/site-packages/django/db/models/query.py", line 512, in create
    obj = self.model(**kwargs)
  File "/Users/timur/Desktop/ZEON/zmall_restapi/venv/lib/python3.10/site-packages/django/db/models/base.py", line 559, in __init__
    raise TypeError(
TypeError: Favorite() got an unexpected keyword argument 'owner'

During handling of the above exception, another exception occurred:

Traceback (most recent call last):
  File "/Users/timur/Desktop/ZEON/zmall_restapi/venv/lib/python3.10/site-packages/django/core/handlers/exception.py", line 55, in inner
    response = get_response(request)
  File "/Users/timur/Desktop/ZEON/zmall_restapi/venv/lib/python3.10/site-packages/django/core/handlers/base.py", line 197, in _get_response
    response = wrapped_callback(request, *callback_args, **callback_kwargs)
  File "/Users/timur/Desktop/ZEON/zmall_restapi/venv/lib/python3.10/site-packages/django/views/decorators/csrf.py", line 54, in wrapped_view
    return view_func(*args, **kwargs)
  File "/Users/timur/Desktop/ZEON/zmall_restapi/venv/lib/python3.10/site-packages/django/views/generic/base.py", line 84, in view
    return self.dispatch(request, *args, **kwargs)
  File "/Users/timur/Desktop/ZEON/zmall_restapi/venv/lib/python3.10/site-packages/rest_framework/views.py", line 509, in dispatch
    response = self.handle_exception(exc)
  File "/Users/timur/Desktop/ZEON/zmall_restapi/venv/lib/python3.10/site-packages/rest_framework/views.py", line 469, in handle_exception
    self.raise_uncaught_exception(exc)
  File "/Users/timur/Desktop/ZEON/zmall_restapi/venv/lib/python3.10/site-packages/rest_framework/views.py", line 480, in raise_uncaught_exception
    raise exc
  File "/Users/timur/Desktop/ZEON/zmall_restapi/venv/lib/python3.10/site-packages/rest_framework/views.py", line 506, in dispatch
    response = handler(request, *args, **kwargs)
  File "/Users/timur/Desktop/ZEON/zmall_restapi/venv/lib/python3.10/site-packages/rest_framework/generics.py", line 190, in post
    return self.create(request, *args, **kwargs)
  File "/Users/timur/Desktop/ZEON/zmall_restapi/venv/lib/python3.10/site-packages/rest_framework/mixins.py", line 19, in create
    self.perform_create(serializer)
  File "/Users/timur/Desktop/ZEON/zmall_restapi/adds/views.py", line 198, in perform_create
    serializer.save(owner=self.request.user)
  File "/Users/timur/Desktop/ZEON/zmall_restapi/venv/lib/python3.10/site-packages/rest_framework/serializers.py", line 212, in save
    self.instance = self.create(validated_data)
  File "/Users/timur/Desktop/ZEON/zmall_restapi/venv/lib/python3.10/site-packages/rest_framework/serializers.py", line 981, in create
    raise TypeError(msg)
TypeError: Got a `TypeError` when calling `Favorite.objects.create()`. This may be because you have a writable field on the serializer class that is not a valid argument to `Favorite.objects.create()`. You may need to make the field read-only, or override the FavoritesSerializer.create() method to handle this correctly.
Original exception was:
 Traceback (most recent call last):
  File "/Users/timur/Desktop/ZEON/zmall_restapi/venv/lib/python3.10/site-packages/rest_framework/serializers.py", line 962, in create
    instance = ModelClass._default_manager.create(**validated_data)
  File "/Users/timur/Desktop/ZEON/zmall_restapi/venv/lib/python3.10/site-packages/django/db/models/manager.py", line 85, in manager_method
    return getattr(self.get_queryset(), name)(*args, **kwargs)
  File "/Users/timur/Desktop/ZEON/zmall_restapi/venv/lib/python3.10/site-packages/django/db/models/query.py", line 512, in create
    obj = self.model(**kwargs)
  File "/Users/timur/Desktop/ZEON/zmall_restapi/venv/lib/python3.10/site-packages/django/db/models/base.py", line 559, in __init__
    raise TypeError(
TypeError: Favorite() got an unexpected keyword argument 'owner'

2022-09-17 17:09:55,083 [basehttp | ERROR] "POST /api/v1/adds/favoritecreate/ HTTP/1.1" 500 145040 @ /Users/timur/Desktop/ZEON/zmall_restapi/venv/lib/python3.10/site-packages/django/core/servers/basehttp.py : 187 : log_message
2022-09-17 17:09:55,083 [basehttp | ERROR] "POST /api/v1/adds/favoritecreate/ HTTP/1.1" 500 145040
2022-09-17 17:12:17,088 [autoreload | INFO] /Users/timur/Desktop/ZEON/zmall_restapi/adds/views.py changed, reloading.
2022-09-17 17:12:20,425 [autoreload | INFO] Watching for file changes with StatReloader
2022-09-17 17:12:23,215 [log | ERROR] Internal Server Error: /api/v1/adds/favoritecreate/ @ /Users/timur/Desktop/ZEON/zmall_restapi/venv/lib/python3.10/site-packages/django/utils/log.py : 241 : log_response
Traceback (most recent call last):
  File "/Users/timur/Desktop/ZEON/zmall_restapi/venv/lib/python3.10/site-packages/django/db/backends/utils.py", line 89, in _execute
    return self.cursor.execute(sql, params)
  File "/Users/timur/Desktop/ZEON/zmall_restapi/venv/lib/python3.10/site-packages/django/db/backends/sqlite3/base.py", line 477, in execute
    return Database.Cursor.execute(self, query, params)
sqlite3.OperationalError: table adds_favorite has no column named post_id

The above exception was the direct cause of the following exception:

Traceback (most recent call last):
  File "/Users/timur/Desktop/ZEON/zmall_restapi/venv/lib/python3.10/site-packages/django/core/handlers/exception.py", line 55, in inner
    response = get_response(request)
  File "/Users/timur/Desktop/ZEON/zmall_restapi/venv/lib/python3.10/site-packages/django/core/handlers/base.py", line 197, in _get_response
    response = wrapped_callback(request, *callback_args, **callback_kwargs)
  File "/Users/timur/Desktop/ZEON/zmall_restapi/venv/lib/python3.10/site-packages/django/views/decorators/csrf.py", line 54, in wrapped_view
    return view_func(*args, **kwargs)
  File "/Users/timur/Desktop/ZEON/zmall_restapi/venv/lib/python3.10/site-packages/django/views/generic/base.py", line 84, in view
    return self.dispatch(request, *args, **kwargs)
  File "/Users/timur/Desktop/ZEON/zmall_restapi/venv/lib/python3.10/site-packages/rest_framework/views.py", line 509, in dispatch
    response = self.handle_exception(exc)
  File "/Users/timur/Desktop/ZEON/zmall_restapi/venv/lib/python3.10/site-packages/rest_framework/views.py", line 469, in handle_exception
    self.raise_uncaught_exception(exc)
  File "/Users/timur/Desktop/ZEON/zmall_restapi/venv/lib/python3.10/site-packages/rest_framework/views.py", line 480, in raise_uncaught_exception
    raise exc
  File "/Users/timur/Desktop/ZEON/zmall_restapi/venv/lib/python3.10/site-packages/rest_framework/views.py", line 506, in dispatch
    response = handler(request, *args, **kwargs)
  File "/Users/timur/Desktop/ZEON/zmall_restapi/venv/lib/python3.10/site-packages/rest_framework/generics.py", line 190, in post
    return self.create(request, *args, **kwargs)
  File "/Users/timur/Desktop/ZEON/zmall_restapi/venv/lib/python3.10/site-packages/rest_framework/mixins.py", line 19, in create
    self.perform_create(serializer)
  File "/Users/timur/Desktop/ZEON/zmall_restapi/venv/lib/python3.10/site-packages/rest_framework/mixins.py", line 24, in perform_create
    serializer.save()
  File "/Users/timur/Desktop/ZEON/zmall_restapi/venv/lib/python3.10/site-packages/rest_framework/serializers.py", line 212, in save
    self.instance = self.create(validated_data)
  File "/Users/timur/Desktop/ZEON/zmall_restapi/venv/lib/python3.10/site-packages/rest_framework/serializers.py", line 962, in create
    instance = ModelClass._default_manager.create(**validated_data)
  File "/Users/timur/Desktop/ZEON/zmall_restapi/venv/lib/python3.10/site-packages/django/db/models/manager.py", line 85, in manager_method
    return getattr(self.get_queryset(), name)(*args, **kwargs)
  File "/Users/timur/Desktop/ZEON/zmall_restapi/venv/lib/python3.10/site-packages/django/db/models/query.py", line 514, in create
    obj.save(force_insert=True, using=self.db)
  File "/Users/timur/Desktop/ZEON/zmall_restapi/venv/lib/python3.10/site-packages/django/db/models/base.py", line 806, in save
    self.save_base(
  File "/Users/timur/Desktop/ZEON/zmall_restapi/venv/lib/python3.10/site-packages/django/db/models/base.py", line 857, in save_base
    updated = self._save_table(
  File "/Users/timur/Desktop/ZEON/zmall_restapi/venv/lib/python3.10/site-packages/django/db/models/base.py", line 1000, in _save_table
    results = self._do_insert(
  File "/Users/timur/Desktop/ZEON/zmall_restapi/venv/lib/python3.10/site-packages/django/db/models/base.py", line 1041, in _do_insert
    return manager._insert(
  File "/Users/timur/Desktop/ZEON/zmall_restapi/venv/lib/python3.10/site-packages/django/db/models/manager.py", line 85, in manager_method
    return getattr(self.get_queryset(), name)(*args, **kwargs)
  File "/Users/timur/Desktop/ZEON/zmall_restapi/venv/lib/python3.10/site-packages/django/db/models/query.py", line 1434, in _insert
    return query.get_compiler(using=using).execute_sql(returning_fields)
  File "/Users/timur/Desktop/ZEON/zmall_restapi/venv/lib/python3.10/site-packages/django/db/models/sql/compiler.py", line 1621, in execute_sql
    cursor.execute(sql, params)
  File "/Users/timur/Desktop/ZEON/zmall_restapi/venv/lib/python3.10/site-packages/django/db/backends/utils.py", line 103, in execute
    return super().execute(sql, params)
  File "/Users/timur/Desktop/ZEON/zmall_restapi/venv/lib/python3.10/site-packages/django/db/backends/utils.py", line 67, in execute
    return self._execute_with_wrappers(
  File "/Users/timur/Desktop/ZEON/zmall_restapi/venv/lib/python3.10/site-packages/django/db/backends/utils.py", line 80, in _execute_with_wrappers
    return executor(sql, params, many, context)
  File "/Users/timur/Desktop/ZEON/zmall_restapi/venv/lib/python3.10/site-packages/django/db/backends/utils.py", line 84, in _execute
    with self.db.wrap_database_errors:
  File "/Users/timur/Desktop/ZEON/zmall_restapi/venv/lib/python3.10/site-packages/django/db/utils.py", line 91, in __exit__
    raise dj_exc_value.with_traceback(traceback) from exc_value
  File "/Users/timur/Desktop/ZEON/zmall_restapi/venv/lib/python3.10/site-packages/django/db/backends/utils.py", line 89, in _execute
    return self.cursor.execute(sql, params)
  File "/Users/timur/Desktop/ZEON/zmall_restapi/venv/lib/python3.10/site-packages/django/db/backends/sqlite3/base.py", line 477, in execute
    return Database.Cursor.execute(self, query, params)
django.db.utils.OperationalError: table adds_favorite has no column named post_id
2022-09-17 17:12:23,215 [log | ERROR] Internal Server Error: /api/v1/adds/favoritecreate/
Traceback (most recent call last):
  File "/Users/timur/Desktop/ZEON/zmall_restapi/venv/lib/python3.10/site-packages/django/db/backends/utils.py", line 89, in _execute
    return self.cursor.execute(sql, params)
  File "/Users/timur/Desktop/ZEON/zmall_restapi/venv/lib/python3.10/site-packages/django/db/backends/sqlite3/base.py", line 477, in execute
    return Database.Cursor.execute(self, query, params)
sqlite3.OperationalError: table adds_favorite has no column named post_id

The above exception was the direct cause of the following exception:

Traceback (most recent call last):
  File "/Users/timur/Desktop/ZEON/zmall_restapi/venv/lib/python3.10/site-packages/django/core/handlers/exception.py", line 55, in inner
    response = get_response(request)
  File "/Users/timur/Desktop/ZEON/zmall_restapi/venv/lib/python3.10/site-packages/django/core/handlers/base.py", line 197, in _get_response
    response = wrapped_callback(request, *callback_args, **callback_kwargs)
  File "/Users/timur/Desktop/ZEON/zmall_restapi/venv/lib/python3.10/site-packages/django/views/decorators/csrf.py", line 54, in wrapped_view
    return view_func(*args, **kwargs)
  File "/Users/timur/Desktop/ZEON/zmall_restapi/venv/lib/python3.10/site-packages/django/views/generic/base.py", line 84, in view
    return self.dispatch(request, *args, **kwargs)
  File "/Users/timur/Desktop/ZEON/zmall_restapi/venv/lib/python3.10/site-packages/rest_framework/views.py", line 509, in dispatch
    response = self.handle_exception(exc)
  File "/Users/timur/Desktop/ZEON/zmall_restapi/venv/lib/python3.10/site-packages/rest_framework/views.py", line 469, in handle_exception
    self.raise_uncaught_exception(exc)
  File "/Users/timur/Desktop/ZEON/zmall_restapi/venv/lib/python3.10/site-packages/rest_framework/views.py", line 480, in raise_uncaught_exception
    raise exc
  File "/Users/timur/Desktop/ZEON/zmall_restapi/venv/lib/python3.10/site-packages/rest_framework/views.py", line 506, in dispatch
    response = handler(request, *args, **kwargs)
  File "/Users/timur/Desktop/ZEON/zmall_restapi/venv/lib/python3.10/site-packages/rest_framework/generics.py", line 190, in post
    return self.create(request, *args, **kwargs)
  File "/Users/timur/Desktop/ZEON/zmall_restapi/venv/lib/python3.10/site-packages/rest_framework/mixins.py", line 19, in create
    self.perform_create(serializer)
  File "/Users/timur/Desktop/ZEON/zmall_restapi/venv/lib/python3.10/site-packages/rest_framework/mixins.py", line 24, in perform_create
    serializer.save()
  File "/Users/timur/Desktop/ZEON/zmall_restapi/venv/lib/python3.10/site-packages/rest_framework/serializers.py", line 212, in save
    self.instance = self.create(validated_data)
  File "/Users/timur/Desktop/ZEON/zmall_restapi/venv/lib/python3.10/site-packages/rest_framework/serializers.py", line 962, in create
    instance = ModelClass._default_manager.create(**validated_data)
  File "/Users/timur/Desktop/ZEON/zmall_restapi/venv/lib/python3.10/site-packages/django/db/models/manager.py", line 85, in manager_method
    return getattr(self.get_queryset(), name)(*args, **kwargs)
  File "/Users/timur/Desktop/ZEON/zmall_restapi/venv/lib/python3.10/site-packages/django/db/models/query.py", line 514, in create
    obj.save(force_insert=True, using=self.db)
  File "/Users/timur/Desktop/ZEON/zmall_restapi/venv/lib/python3.10/site-packages/django/db/models/base.py", line 806, in save
    self.save_base(
  File "/Users/timur/Desktop/ZEON/zmall_restapi/venv/lib/python3.10/site-packages/django/db/models/base.py", line 857, in save_base
    updated = self._save_table(
  File "/Users/timur/Desktop/ZEON/zmall_restapi/venv/lib/python3.10/site-packages/django/db/models/base.py", line 1000, in _save_table
    results = self._do_insert(
  File "/Users/timur/Desktop/ZEON/zmall_restapi/venv/lib/python3.10/site-packages/django/db/models/base.py", line 1041, in _do_insert
    return manager._insert(
  File "/Users/timur/Desktop/ZEON/zmall_restapi/venv/lib/python3.10/site-packages/django/db/models/manager.py", line 85, in manager_method
    return getattr(self.get_queryset(), name)(*args, **kwargs)
  File "/Users/timur/Desktop/ZEON/zmall_restapi/venv/lib/python3.10/site-packages/django/db/models/query.py", line 1434, in _insert
    return query.get_compiler(using=using).execute_sql(returning_fields)
  File "/Users/timur/Desktop/ZEON/zmall_restapi/venv/lib/python3.10/site-packages/django/db/models/sql/compiler.py", line 1621, in execute_sql
    cursor.execute(sql, params)
  File "/Users/timur/Desktop/ZEON/zmall_restapi/venv/lib/python3.10/site-packages/django/db/backends/utils.py", line 103, in execute
    return super().execute(sql, params)
  File "/Users/timur/Desktop/ZEON/zmall_restapi/venv/lib/python3.10/site-packages/django/db/backends/utils.py", line 67, in execute
    return self._execute_with_wrappers(
  File "/Users/timur/Desktop/ZEON/zmall_restapi/venv/lib/python3.10/site-packages/django/db/backends/utils.py", line 80, in _execute_with_wrappers
    return executor(sql, params, many, context)
  File "/Users/timur/Desktop/ZEON/zmall_restapi/venv/lib/python3.10/site-packages/django/db/backends/utils.py", line 84, in _execute
    with self.db.wrap_database_errors:
  File "/Users/timur/Desktop/ZEON/zmall_restapi/venv/lib/python3.10/site-packages/django/db/utils.py", line 91, in __exit__
    raise dj_exc_value.with_traceback(traceback) from exc_value
  File "/Users/timur/Desktop/ZEON/zmall_restapi/venv/lib/python3.10/site-packages/django/db/backends/utils.py", line 89, in _execute
    return self.cursor.execute(sql, params)
  File "/Users/timur/Desktop/ZEON/zmall_restapi/venv/lib/python3.10/site-packages/django/db/backends/sqlite3/base.py", line 477, in execute
    return Database.Cursor.execute(self, query, params)
django.db.utils.OperationalError: table adds_favorite has no column named post_id
2022-09-17 17:12:23,218 [basehttp | ERROR] "POST /api/v1/adds/favoritecreate/ HTTP/1.1" 500 193264 @ /Users/timur/Desktop/ZEON/zmall_restapi/venv/lib/python3.10/site-packages/django/core/servers/basehttp.py : 187 : log_message
2022-09-17 17:12:23,218 [basehttp | ERROR] "POST /api/v1/adds/favoritecreate/ HTTP/1.1" 500 193264
2022-09-17 17:12:58,246 [autoreload | INFO] /Users/timur/Desktop/ZEON/zmall_restapi/adds/views.py changed, reloading.
2022-09-17 17:13:00,873 [autoreload | INFO] Watching for file changes with StatReloader
2022-09-17 17:13:05,191 [log | ERROR] Internal Server Error: /api/v1/adds/favoritecreate/ @ /Users/timur/Desktop/ZEON/zmall_restapi/venv/lib/python3.10/site-packages/django/utils/log.py : 241 : log_response
Traceback (most recent call last):
  File "/Users/timur/Desktop/ZEON/zmall_restapi/venv/lib/python3.10/site-packages/django/core/handlers/exception.py", line 55, in inner
    response = get_response(request)
  File "/Users/timur/Desktop/ZEON/zmall_restapi/venv/lib/python3.10/site-packages/django/core/handlers/base.py", line 197, in _get_response
    response = wrapped_callback(request, *callback_args, **callback_kwargs)
  File "/Users/timur/Desktop/ZEON/zmall_restapi/venv/lib/python3.10/site-packages/django/views/decorators/csrf.py", line 54, in wrapped_view
    return view_func(*args, **kwargs)
  File "/Users/timur/Desktop/ZEON/zmall_restapi/venv/lib/python3.10/site-packages/django/views/generic/base.py", line 84, in view
    return self.dispatch(request, *args, **kwargs)
  File "/Users/timur/Desktop/ZEON/zmall_restapi/venv/lib/python3.10/site-packages/rest_framework/views.py", line 509, in dispatch
    response = self.handle_exception(exc)
  File "/Users/timur/Desktop/ZEON/zmall_restapi/venv/lib/python3.10/site-packages/rest_framework/views.py", line 469, in handle_exception
    self.raise_uncaught_exception(exc)
  File "/Users/timur/Desktop/ZEON/zmall_restapi/venv/lib/python3.10/site-packages/rest_framework/views.py", line 480, in raise_uncaught_exception
    raise exc
  File "/Users/timur/Desktop/ZEON/zmall_restapi/venv/lib/python3.10/site-packages/rest_framework/views.py", line 506, in dispatch
    response = handler(request, *args, **kwargs)
  File "/Users/timur/Desktop/ZEON/zmall_restapi/venv/lib/python3.10/site-packages/rest_framework/generics.py", line 190, in post
    return self.create(request, *args, **kwargs)
  File "/Users/timur/Desktop/ZEON/zmall_restapi/venv/lib/python3.10/site-packages/rest_framework/mixins.py", line 19, in create
    self.perform_create(serializer)
  File "/Users/timur/Desktop/ZEON/zmall_restapi/adds/views.py", line 198, in perform_create
    serializer.save(user=self.request.user)
  File "/Users/timur/Desktop/ZEON/zmall_restapi/venv/lib/python3.10/site-packages/rest_framework/serializers.py", line 212, in save
    self.instance = self.create(validated_data)
  File "/Users/timur/Desktop/ZEON/zmall_restapi/venv/lib/python3.10/site-packages/rest_framework/serializers.py", line 962, in create
    instance = ModelClass._default_manager.create(**validated_data)
  File "/Users/timur/Desktop/ZEON/zmall_restapi/venv/lib/python3.10/site-packages/django/db/models/manager.py", line 85, in manager_method
    return getattr(self.get_queryset(), name)(*args, **kwargs)
  File "/Users/timur/Desktop/ZEON/zmall_restapi/venv/lib/python3.10/site-packages/django/db/models/query.py", line 512, in create
    obj = self.model(**kwargs)
  File "/Users/timur/Desktop/ZEON/zmall_restapi/venv/lib/python3.10/site-packages/django/db/models/base.py", line 541, in __init__
    _setattr(self, field.name, rel_obj)
  File "/Users/timur/Desktop/ZEON/zmall_restapi/venv/lib/python3.10/site-packages/django/db/models/fields/related_descriptors.py", line 235, in __set__
    raise ValueError(
ValueError: Cannot assign "<django.contrib.auth.models.AnonymousUser object at 0x105d8d480>": "Favorite.user" must be a "User" instance.
2022-09-17 17:13:05,191 [log | ERROR] Internal Server Error: /api/v1/adds/favoritecreate/
Traceback (most recent call last):
  File "/Users/timur/Desktop/ZEON/zmall_restapi/venv/lib/python3.10/site-packages/django/core/handlers/exception.py", line 55, in inner
    response = get_response(request)
  File "/Users/timur/Desktop/ZEON/zmall_restapi/venv/lib/python3.10/site-packages/django/core/handlers/base.py", line 197, in _get_response
    response = wrapped_callback(request, *callback_args, **callback_kwargs)
  File "/Users/timur/Desktop/ZEON/zmall_restapi/venv/lib/python3.10/site-packages/django/views/decorators/csrf.py", line 54, in wrapped_view
    return view_func(*args, **kwargs)
  File "/Users/timur/Desktop/ZEON/zmall_restapi/venv/lib/python3.10/site-packages/django/views/generic/base.py", line 84, in view
    return self.dispatch(request, *args, **kwargs)
  File "/Users/timur/Desktop/ZEON/zmall_restapi/venv/lib/python3.10/site-packages/rest_framework/views.py", line 509, in dispatch
    response = self.handle_exception(exc)
  File "/Users/timur/Desktop/ZEON/zmall_restapi/venv/lib/python3.10/site-packages/rest_framework/views.py", line 469, in handle_exception
    self.raise_uncaught_exception(exc)
  File "/Users/timur/Desktop/ZEON/zmall_restapi/venv/lib/python3.10/site-packages/rest_framework/views.py", line 480, in raise_uncaught_exception
    raise exc
  File "/Users/timur/Desktop/ZEON/zmall_restapi/venv/lib/python3.10/site-packages/rest_framework/views.py", line 506, in dispatch
    response = handler(request, *args, **kwargs)
  File "/Users/timur/Desktop/ZEON/zmall_restapi/venv/lib/python3.10/site-packages/rest_framework/generics.py", line 190, in post
    return self.create(request, *args, **kwargs)
  File "/Users/timur/Desktop/ZEON/zmall_restapi/venv/lib/python3.10/site-packages/rest_framework/mixins.py", line 19, in create
    self.perform_create(serializer)
  File "/Users/timur/Desktop/ZEON/zmall_restapi/adds/views.py", line 198, in perform_create
    serializer.save(user=self.request.user)
  File "/Users/timur/Desktop/ZEON/zmall_restapi/venv/lib/python3.10/site-packages/rest_framework/serializers.py", line 212, in save
    self.instance = self.create(validated_data)
  File "/Users/timur/Desktop/ZEON/zmall_restapi/venv/lib/python3.10/site-packages/rest_framework/serializers.py", line 962, in create
    instance = ModelClass._default_manager.create(**validated_data)
  File "/Users/timur/Desktop/ZEON/zmall_restapi/venv/lib/python3.10/site-packages/django/db/models/manager.py", line 85, in manager_method
    return getattr(self.get_queryset(), name)(*args, **kwargs)
  File "/Users/timur/Desktop/ZEON/zmall_restapi/venv/lib/python3.10/site-packages/django/db/models/query.py", line 512, in create
    obj = self.model(**kwargs)
  File "/Users/timur/Desktop/ZEON/zmall_restapi/venv/lib/python3.10/site-packages/django/db/models/base.py", line 541, in __init__
    _setattr(self, field.name, rel_obj)
  File "/Users/timur/Desktop/ZEON/zmall_restapi/venv/lib/python3.10/site-packages/django/db/models/fields/related_descriptors.py", line 235, in __set__
    raise ValueError(
ValueError: Cannot assign "<django.contrib.auth.models.AnonymousUser object at 0x105d8d480>": "Favorite.user" must be a "User" instance.
2022-09-17 17:13:05,194 [basehttp | ERROR] "POST /api/v1/adds/favoritecreate/ HTTP/1.1" 500 129333 @ /Users/timur/Desktop/ZEON/zmall_restapi/venv/lib/python3.10/site-packages/django/core/servers/basehttp.py : 187 : log_message
2022-09-17 17:13:05,194 [basehttp | ERROR] "POST /api/v1/adds/favoritecreate/ HTTP/1.1" 500 129333
2022-09-17 17:18:47,445 [autoreload | INFO] /Users/timur/Desktop/ZEON/zmall_restapi/adds/views.py changed, reloading.
2022-09-17 17:18:50,174 [autoreload | INFO] Watching for file changes with StatReloader
2022-09-17 17:18:53,374 [log | WARNING] Not Found: /api/v1/adds/favorite/
2022-09-17 17:18:53,375 [basehttp | WARNING] "GET /api/v1/adds/favorite/ HTTP/1.1" 404 2966
2022-09-17 17:18:57,230 [log | WARNING] Not Found: /api/v1/adds/favorite/
2022-09-17 17:18:57,230 [basehttp | WARNING] "GET /api/v1/adds/favorite/ HTTP/1.1" 404 2966
2022-09-17 17:19:23,756 [autoreload | INFO] /Users/timur/Desktop/ZEON/zmall_restapi/adds/urls.py changed, reloading.
2022-09-17 17:19:26,149 [autoreload | INFO] Watching for file changes with StatReloader
2022-09-17 17:19:27,600 [basehttp | INFO] "GET /api/v1/adds/favorite/ HTTP/1.1" 200 8881
2022-09-17 17:19:31,946 [log | ERROR] Internal Server Error: /api/v1/adds/favorite/ @ /Users/timur/Desktop/ZEON/zmall_restapi/venv/lib/python3.10/site-packages/django/utils/log.py : 241 : log_response
Traceback (most recent call last):
  File "/Users/timur/Desktop/ZEON/zmall_restapi/venv/lib/python3.10/site-packages/django/db/backends/utils.py", line 89, in _execute
    return self.cursor.execute(sql, params)
  File "/Users/timur/Desktop/ZEON/zmall_restapi/venv/lib/python3.10/site-packages/django/db/backends/sqlite3/base.py", line 477, in execute
    return Database.Cursor.execute(self, query, params)
sqlite3.OperationalError: table adds_favorite has no column named post_id

The above exception was the direct cause of the following exception:

Traceback (most recent call last):
  File "/Users/timur/Desktop/ZEON/zmall_restapi/venv/lib/python3.10/site-packages/django/core/handlers/exception.py", line 55, in inner
    response = get_response(request)
  File "/Users/timur/Desktop/ZEON/zmall_restapi/venv/lib/python3.10/site-packages/django/core/handlers/base.py", line 197, in _get_response
    response = wrapped_callback(request, *callback_args, **callback_kwargs)
  File "/Users/timur/Desktop/ZEON/zmall_restapi/venv/lib/python3.10/site-packages/django/views/decorators/csrf.py", line 54, in wrapped_view
    return view_func(*args, **kwargs)
  File "/Users/timur/Desktop/ZEON/zmall_restapi/venv/lib/python3.10/site-packages/rest_framework/viewsets.py", line 125, in view
    return self.dispatch(request, *args, **kwargs)
  File "/Users/timur/Desktop/ZEON/zmall_restapi/venv/lib/python3.10/site-packages/rest_framework/views.py", line 509, in dispatch
    response = self.handle_exception(exc)
  File "/Users/timur/Desktop/ZEON/zmall_restapi/venv/lib/python3.10/site-packages/rest_framework/views.py", line 469, in handle_exception
    self.raise_uncaught_exception(exc)
  File "/Users/timur/Desktop/ZEON/zmall_restapi/venv/lib/python3.10/site-packages/rest_framework/views.py", line 480, in raise_uncaught_exception
    raise exc
  File "/Users/timur/Desktop/ZEON/zmall_restapi/venv/lib/python3.10/site-packages/rest_framework/views.py", line 506, in dispatch
    response = handler(request, *args, **kwargs)
  File "/Users/timur/Desktop/ZEON/zmall_restapi/venv/lib/python3.10/site-packages/rest_framework/mixins.py", line 19, in create
    self.perform_create(serializer)
  File "/Users/timur/Desktop/ZEON/zmall_restapi/venv/lib/python3.10/site-packages/rest_framework/mixins.py", line 24, in perform_create
    serializer.save()
  File "/Users/timur/Desktop/ZEON/zmall_restapi/venv/lib/python3.10/site-packages/rest_framework/serializers.py", line 212, in save
    self.instance = self.create(validated_data)
  File "/Users/timur/Desktop/ZEON/zmall_restapi/venv/lib/python3.10/site-packages/rest_framework/serializers.py", line 962, in create
    instance = ModelClass._default_manager.create(**validated_data)
  File "/Users/timur/Desktop/ZEON/zmall_restapi/venv/lib/python3.10/site-packages/django/db/models/manager.py", line 85, in manager_method
    return getattr(self.get_queryset(), name)(*args, **kwargs)
  File "/Users/timur/Desktop/ZEON/zmall_restapi/venv/lib/python3.10/site-packages/django/db/models/query.py", line 514, in create
    obj.save(force_insert=True, using=self.db)
  File "/Users/timur/Desktop/ZEON/zmall_restapi/venv/lib/python3.10/site-packages/django/db/models/base.py", line 806, in save
    self.save_base(
  File "/Users/timur/Desktop/ZEON/zmall_restapi/venv/lib/python3.10/site-packages/django/db/models/base.py", line 857, in save_base
    updated = self._save_table(
  File "/Users/timur/Desktop/ZEON/zmall_restapi/venv/lib/python3.10/site-packages/django/db/models/base.py", line 1000, in _save_table
    results = self._do_insert(
  File "/Users/timur/Desktop/ZEON/zmall_restapi/venv/lib/python3.10/site-packages/django/db/models/base.py", line 1041, in _do_insert
    return manager._insert(
  File "/Users/timur/Desktop/ZEON/zmall_restapi/venv/lib/python3.10/site-packages/django/db/models/manager.py", line 85, in manager_method
    return getattr(self.get_queryset(), name)(*args, **kwargs)
  File "/Users/timur/Desktop/ZEON/zmall_restapi/venv/lib/python3.10/site-packages/django/db/models/query.py", line 1434, in _insert
    return query.get_compiler(using=using).execute_sql(returning_fields)
  File "/Users/timur/Desktop/ZEON/zmall_restapi/venv/lib/python3.10/site-packages/django/db/models/sql/compiler.py", line 1621, in execute_sql
    cursor.execute(sql, params)
  File "/Users/timur/Desktop/ZEON/zmall_restapi/venv/lib/python3.10/site-packages/django/db/backends/utils.py", line 103, in execute
    return super().execute(sql, params)
  File "/Users/timur/Desktop/ZEON/zmall_restapi/venv/lib/python3.10/site-packages/django/db/backends/utils.py", line 67, in execute
    return self._execute_with_wrappers(
  File "/Users/timur/Desktop/ZEON/zmall_restapi/venv/lib/python3.10/site-packages/django/db/backends/utils.py", line 80, in _execute_with_wrappers
    return executor(sql, params, many, context)
  File "/Users/timur/Desktop/ZEON/zmall_restapi/venv/lib/python3.10/site-packages/django/db/backends/utils.py", line 84, in _execute
    with self.db.wrap_database_errors:
  File "/Users/timur/Desktop/ZEON/zmall_restapi/venv/lib/python3.10/site-packages/django/db/utils.py", line 91, in __exit__
    raise dj_exc_value.with_traceback(traceback) from exc_value
  File "/Users/timur/Desktop/ZEON/zmall_restapi/venv/lib/python3.10/site-packages/django/db/backends/utils.py", line 89, in _execute
    return self.cursor.execute(sql, params)
  File "/Users/timur/Desktop/ZEON/zmall_restapi/venv/lib/python3.10/site-packages/django/db/backends/sqlite3/base.py", line 477, in execute
    return Database.Cursor.execute(self, query, params)
django.db.utils.OperationalError: table adds_favorite has no column named post_id
2022-09-17 17:19:31,946 [log | ERROR] Internal Server Error: /api/v1/adds/favorite/
Traceback (most recent call last):
  File "/Users/timur/Desktop/ZEON/zmall_restapi/venv/lib/python3.10/site-packages/django/db/backends/utils.py", line 89, in _execute
    return self.cursor.execute(sql, params)
  File "/Users/timur/Desktop/ZEON/zmall_restapi/venv/lib/python3.10/site-packages/django/db/backends/sqlite3/base.py", line 477, in execute
    return Database.Cursor.execute(self, query, params)
sqlite3.OperationalError: table adds_favorite has no column named post_id

The above exception was the direct cause of the following exception:

Traceback (most recent call last):
  File "/Users/timur/Desktop/ZEON/zmall_restapi/venv/lib/python3.10/site-packages/django/core/handlers/exception.py", line 55, in inner
    response = get_response(request)
  File "/Users/timur/Desktop/ZEON/zmall_restapi/venv/lib/python3.10/site-packages/django/core/handlers/base.py", line 197, in _get_response
    response = wrapped_callback(request, *callback_args, **callback_kwargs)
  File "/Users/timur/Desktop/ZEON/zmall_restapi/venv/lib/python3.10/site-packages/django/views/decorators/csrf.py", line 54, in wrapped_view
    return view_func(*args, **kwargs)
  File "/Users/timur/Desktop/ZEON/zmall_restapi/venv/lib/python3.10/site-packages/rest_framework/viewsets.py", line 125, in view
    return self.dispatch(request, *args, **kwargs)
  File "/Users/timur/Desktop/ZEON/zmall_restapi/venv/lib/python3.10/site-packages/rest_framework/views.py", line 509, in dispatch
    response = self.handle_exception(exc)
  File "/Users/timur/Desktop/ZEON/zmall_restapi/venv/lib/python3.10/site-packages/rest_framework/views.py", line 469, in handle_exception
    self.raise_uncaught_exception(exc)
  File "/Users/timur/Desktop/ZEON/zmall_restapi/venv/lib/python3.10/site-packages/rest_framework/views.py", line 480, in raise_uncaught_exception
    raise exc
  File "/Users/timur/Desktop/ZEON/zmall_restapi/venv/lib/python3.10/site-packages/rest_framework/views.py", line 506, in dispatch
    response = handler(request, *args, **kwargs)
  File "/Users/timur/Desktop/ZEON/zmall_restapi/venv/lib/python3.10/site-packages/rest_framework/mixins.py", line 19, in create
    self.perform_create(serializer)
  File "/Users/timur/Desktop/ZEON/zmall_restapi/venv/lib/python3.10/site-packages/rest_framework/mixins.py", line 24, in perform_create
    serializer.save()
  File "/Users/timur/Desktop/ZEON/zmall_restapi/venv/lib/python3.10/site-packages/rest_framework/serializers.py", line 212, in save
    self.instance = self.create(validated_data)
  File "/Users/timur/Desktop/ZEON/zmall_restapi/venv/lib/python3.10/site-packages/rest_framework/serializers.py", line 962, in create
    instance = ModelClass._default_manager.create(**validated_data)
  File "/Users/timur/Desktop/ZEON/zmall_restapi/venv/lib/python3.10/site-packages/django/db/models/manager.py", line 85, in manager_method
    return getattr(self.get_queryset(), name)(*args, **kwargs)
  File "/Users/timur/Desktop/ZEON/zmall_restapi/venv/lib/python3.10/site-packages/django/db/models/query.py", line 514, in create
    obj.save(force_insert=True, using=self.db)
  File "/Users/timur/Desktop/ZEON/zmall_restapi/venv/lib/python3.10/site-packages/django/db/models/base.py", line 806, in save
    self.save_base(
  File "/Users/timur/Desktop/ZEON/zmall_restapi/venv/lib/python3.10/site-packages/django/db/models/base.py", line 857, in save_base
    updated = self._save_table(
  File "/Users/timur/Desktop/ZEON/zmall_restapi/venv/lib/python3.10/site-packages/django/db/models/base.py", line 1000, in _save_table
    results = self._do_insert(
  File "/Users/timur/Desktop/ZEON/zmall_restapi/venv/lib/python3.10/site-packages/django/db/models/base.py", line 1041, in _do_insert
    return manager._insert(
  File "/Users/timur/Desktop/ZEON/zmall_restapi/venv/lib/python3.10/site-packages/django/db/models/manager.py", line 85, in manager_method
    return getattr(self.get_queryset(), name)(*args, **kwargs)
  File "/Users/timur/Desktop/ZEON/zmall_restapi/venv/lib/python3.10/site-packages/django/db/models/query.py", line 1434, in _insert
    return query.get_compiler(using=using).execute_sql(returning_fields)
  File "/Users/timur/Desktop/ZEON/zmall_restapi/venv/lib/python3.10/site-packages/django/db/models/sql/compiler.py", line 1621, in execute_sql
    cursor.execute(sql, params)
  File "/Users/timur/Desktop/ZEON/zmall_restapi/venv/lib/python3.10/site-packages/django/db/backends/utils.py", line 103, in execute
    return super().execute(sql, params)
  File "/Users/timur/Desktop/ZEON/zmall_restapi/venv/lib/python3.10/site-packages/django/db/backends/utils.py", line 67, in execute
    return self._execute_with_wrappers(
  File "/Users/timur/Desktop/ZEON/zmall_restapi/venv/lib/python3.10/site-packages/django/db/backends/utils.py", line 80, in _execute_with_wrappers
    return executor(sql, params, many, context)
  File "/Users/timur/Desktop/ZEON/zmall_restapi/venv/lib/python3.10/site-packages/django/db/backends/utils.py", line 84, in _execute
    with self.db.wrap_database_errors:
  File "/Users/timur/Desktop/ZEON/zmall_restapi/venv/lib/python3.10/site-packages/django/db/utils.py", line 91, in __exit__
    raise dj_exc_value.with_traceback(traceback) from exc_value
  File "/Users/timur/Desktop/ZEON/zmall_restapi/venv/lib/python3.10/site-packages/django/db/backends/utils.py", line 89, in _execute
    return self.cursor.execute(sql, params)
  File "/Users/timur/Desktop/ZEON/zmall_restapi/venv/lib/python3.10/site-packages/django/db/backends/sqlite3/base.py", line 477, in execute
    return Database.Cursor.execute(self, query, params)
django.db.utils.OperationalError: table adds_favorite has no column named post_id
2022-09-17 17:19:31,949 [basehttp | ERROR] "POST /api/v1/adds/favorite/ HTTP/1.1" 500 189756 @ /Users/timur/Desktop/ZEON/zmall_restapi/venv/lib/python3.10/site-packages/django/core/servers/basehttp.py : 187 : log_message
2022-09-17 17:19:31,949 [basehttp | ERROR] "POST /api/v1/adds/favorite/ HTTP/1.1" 500 189756
2022-09-17 17:25:06,535 [autoreload | INFO] /Users/timur/Desktop/ZEON/zmall_restapi/adds/views.py changed, reloading.
2022-09-17 17:25:09,363 [autoreload | INFO] Watching for file changes with StatReloader
2022-09-17 17:25:16,143 [log | ERROR] Internal Server Error: /api/v1/adds/favorite/ @ /Users/timur/Desktop/ZEON/zmall_restapi/venv/lib/python3.10/site-packages/django/utils/log.py : 241 : log_response
Traceback (most recent call last):
  File "/Users/timur/Desktop/ZEON/zmall_restapi/venv/lib/python3.10/site-packages/django/db/backends/utils.py", line 89, in _execute
    return self.cursor.execute(sql, params)
  File "/Users/timur/Desktop/ZEON/zmall_restapi/venv/lib/python3.10/site-packages/django/db/backends/sqlite3/base.py", line 477, in execute
    return Database.Cursor.execute(self, query, params)
sqlite3.OperationalError: table adds_favorite has no column named post_id

The above exception was the direct cause of the following exception:

Traceback (most recent call last):
  File "/Users/timur/Desktop/ZEON/zmall_restapi/venv/lib/python3.10/site-packages/django/core/handlers/exception.py", line 55, in inner
    response = get_response(request)
  File "/Users/timur/Desktop/ZEON/zmall_restapi/venv/lib/python3.10/site-packages/django/core/handlers/base.py", line 197, in _get_response
    response = wrapped_callback(request, *callback_args, **callback_kwargs)
  File "/Users/timur/Desktop/ZEON/zmall_restapi/venv/lib/python3.10/site-packages/django/views/decorators/csrf.py", line 54, in wrapped_view
    return view_func(*args, **kwargs)
  File "/Users/timur/Desktop/ZEON/zmall_restapi/venv/lib/python3.10/site-packages/rest_framework/viewsets.py", line 125, in view
    return self.dispatch(request, *args, **kwargs)
  File "/Users/timur/Desktop/ZEON/zmall_restapi/venv/lib/python3.10/site-packages/rest_framework/views.py", line 509, in dispatch
    response = self.handle_exception(exc)
  File "/Users/timur/Desktop/ZEON/zmall_restapi/venv/lib/python3.10/site-packages/rest_framework/views.py", line 469, in handle_exception
    self.raise_uncaught_exception(exc)
  File "/Users/timur/Desktop/ZEON/zmall_restapi/venv/lib/python3.10/site-packages/rest_framework/views.py", line 480, in raise_uncaught_exception
    raise exc
  File "/Users/timur/Desktop/ZEON/zmall_restapi/venv/lib/python3.10/site-packages/rest_framework/views.py", line 506, in dispatch
    response = handler(request, *args, **kwargs)
  File "/Users/timur/Desktop/ZEON/zmall_restapi/venv/lib/python3.10/site-packages/rest_framework/mixins.py", line 19, in create
    self.perform_create(serializer)
  File "/Users/timur/Desktop/ZEON/zmall_restapi/venv/lib/python3.10/site-packages/rest_framework/mixins.py", line 24, in perform_create
    serializer.save()
  File "/Users/timur/Desktop/ZEON/zmall_restapi/venv/lib/python3.10/site-packages/rest_framework/serializers.py", line 212, in save
    self.instance = self.create(validated_data)
  File "/Users/timur/Desktop/ZEON/zmall_restapi/venv/lib/python3.10/site-packages/rest_framework/serializers.py", line 962, in create
    instance = ModelClass._default_manager.create(**validated_data)
  File "/Users/timur/Desktop/ZEON/zmall_restapi/venv/lib/python3.10/site-packages/django/db/models/manager.py", line 85, in manager_method
    return getattr(self.get_queryset(), name)(*args, **kwargs)
  File "/Users/timur/Desktop/ZEON/zmall_restapi/venv/lib/python3.10/site-packages/django/db/models/query.py", line 514, in create
    obj.save(force_insert=True, using=self.db)
  File "/Users/timur/Desktop/ZEON/zmall_restapi/venv/lib/python3.10/site-packages/django/db/models/base.py", line 806, in save
    self.save_base(
  File "/Users/timur/Desktop/ZEON/zmall_restapi/venv/lib/python3.10/site-packages/django/db/models/base.py", line 857, in save_base
    updated = self._save_table(
  File "/Users/timur/Desktop/ZEON/zmall_restapi/venv/lib/python3.10/site-packages/django/db/models/base.py", line 1000, in _save_table
    results = self._do_insert(
  File "/Users/timur/Desktop/ZEON/zmall_restapi/venv/lib/python3.10/site-packages/django/db/models/base.py", line 1041, in _do_insert
    return manager._insert(
  File "/Users/timur/Desktop/ZEON/zmall_restapi/venv/lib/python3.10/site-packages/django/db/models/manager.py", line 85, in manager_method
    return getattr(self.get_queryset(), name)(*args, **kwargs)
  File "/Users/timur/Desktop/ZEON/zmall_restapi/venv/lib/python3.10/site-packages/django/db/models/query.py", line 1434, in _insert
    return query.get_compiler(using=using).execute_sql(returning_fields)
  File "/Users/timur/Desktop/ZEON/zmall_restapi/venv/lib/python3.10/site-packages/django/db/models/sql/compiler.py", line 1621, in execute_sql
    cursor.execute(sql, params)
  File "/Users/timur/Desktop/ZEON/zmall_restapi/venv/lib/python3.10/site-packages/django/db/backends/utils.py", line 103, in execute
    return super().execute(sql, params)
  File "/Users/timur/Desktop/ZEON/zmall_restapi/venv/lib/python3.10/site-packages/django/db/backends/utils.py", line 67, in execute
    return self._execute_with_wrappers(
  File "/Users/timur/Desktop/ZEON/zmall_restapi/venv/lib/python3.10/site-packages/django/db/backends/utils.py", line 80, in _execute_with_wrappers
    return executor(sql, params, many, context)
  File "/Users/timur/Desktop/ZEON/zmall_restapi/venv/lib/python3.10/site-packages/django/db/backends/utils.py", line 84, in _execute
    with self.db.wrap_database_errors:
  File "/Users/timur/Desktop/ZEON/zmall_restapi/venv/lib/python3.10/site-packages/django/db/utils.py", line 91, in __exit__
    raise dj_exc_value.with_traceback(traceback) from exc_value
  File "/Users/timur/Desktop/ZEON/zmall_restapi/venv/lib/python3.10/site-packages/django/db/backends/utils.py", line 89, in _execute
    return self.cursor.execute(sql, params)
  File "/Users/timur/Desktop/ZEON/zmall_restapi/venv/lib/python3.10/site-packages/django/db/backends/sqlite3/base.py", line 477, in execute
    return Database.Cursor.execute(self, query, params)
django.db.utils.OperationalError: table adds_favorite has no column named post_id
2022-09-17 17:25:16,143 [log | ERROR] Internal Server Error: /api/v1/adds/favorite/
Traceback (most recent call last):
  File "/Users/timur/Desktop/ZEON/zmall_restapi/venv/lib/python3.10/site-packages/django/db/backends/utils.py", line 89, in _execute
    return self.cursor.execute(sql, params)
  File "/Users/timur/Desktop/ZEON/zmall_restapi/venv/lib/python3.10/site-packages/django/db/backends/sqlite3/base.py", line 477, in execute
    return Database.Cursor.execute(self, query, params)
sqlite3.OperationalError: table adds_favorite has no column named post_id

The above exception was the direct cause of the following exception:

Traceback (most recent call last):
  File "/Users/timur/Desktop/ZEON/zmall_restapi/venv/lib/python3.10/site-packages/django/core/handlers/exception.py", line 55, in inner
    response = get_response(request)
  File "/Users/timur/Desktop/ZEON/zmall_restapi/venv/lib/python3.10/site-packages/django/core/handlers/base.py", line 197, in _get_response
    response = wrapped_callback(request, *callback_args, **callback_kwargs)
  File "/Users/timur/Desktop/ZEON/zmall_restapi/venv/lib/python3.10/site-packages/django/views/decorators/csrf.py", line 54, in wrapped_view
    return view_func(*args, **kwargs)
  File "/Users/timur/Desktop/ZEON/zmall_restapi/venv/lib/python3.10/site-packages/rest_framework/viewsets.py", line 125, in view
    return self.dispatch(request, *args, **kwargs)
  File "/Users/timur/Desktop/ZEON/zmall_restapi/venv/lib/python3.10/site-packages/rest_framework/views.py", line 509, in dispatch
    response = self.handle_exception(exc)
  File "/Users/timur/Desktop/ZEON/zmall_restapi/venv/lib/python3.10/site-packages/rest_framework/views.py", line 469, in handle_exception
    self.raise_uncaught_exception(exc)
  File "/Users/timur/Desktop/ZEON/zmall_restapi/venv/lib/python3.10/site-packages/rest_framework/views.py", line 480, in raise_uncaught_exception
    raise exc
  File "/Users/timur/Desktop/ZEON/zmall_restapi/venv/lib/python3.10/site-packages/rest_framework/views.py", line 506, in dispatch
    response = handler(request, *args, **kwargs)
  File "/Users/timur/Desktop/ZEON/zmall_restapi/venv/lib/python3.10/site-packages/rest_framework/mixins.py", line 19, in create
    self.perform_create(serializer)
  File "/Users/timur/Desktop/ZEON/zmall_restapi/venv/lib/python3.10/site-packages/rest_framework/mixins.py", line 24, in perform_create
    serializer.save()
  File "/Users/timur/Desktop/ZEON/zmall_restapi/venv/lib/python3.10/site-packages/rest_framework/serializers.py", line 212, in save
    self.instance = self.create(validated_data)
  File "/Users/timur/Desktop/ZEON/zmall_restapi/venv/lib/python3.10/site-packages/rest_framework/serializers.py", line 962, in create
    instance = ModelClass._default_manager.create(**validated_data)
  File "/Users/timur/Desktop/ZEON/zmall_restapi/venv/lib/python3.10/site-packages/django/db/models/manager.py", line 85, in manager_method
    return getattr(self.get_queryset(), name)(*args, **kwargs)
  File "/Users/timur/Desktop/ZEON/zmall_restapi/venv/lib/python3.10/site-packages/django/db/models/query.py", line 514, in create
    obj.save(force_insert=True, using=self.db)
  File "/Users/timur/Desktop/ZEON/zmall_restapi/venv/lib/python3.10/site-packages/django/db/models/base.py", line 806, in save
    self.save_base(
  File "/Users/timur/Desktop/ZEON/zmall_restapi/venv/lib/python3.10/site-packages/django/db/models/base.py", line 857, in save_base
    updated = self._save_table(
  File "/Users/timur/Desktop/ZEON/zmall_restapi/venv/lib/python3.10/site-packages/django/db/models/base.py", line 1000, in _save_table
    results = self._do_insert(
  File "/Users/timur/Desktop/ZEON/zmall_restapi/venv/lib/python3.10/site-packages/django/db/models/base.py", line 1041, in _do_insert
    return manager._insert(
  File "/Users/timur/Desktop/ZEON/zmall_restapi/venv/lib/python3.10/site-packages/django/db/models/manager.py", line 85, in manager_method
    return getattr(self.get_queryset(), name)(*args, **kwargs)
  File "/Users/timur/Desktop/ZEON/zmall_restapi/venv/lib/python3.10/site-packages/django/db/models/query.py", line 1434, in _insert
    return query.get_compiler(using=using).execute_sql(returning_fields)
  File "/Users/timur/Desktop/ZEON/zmall_restapi/venv/lib/python3.10/site-packages/django/db/models/sql/compiler.py", line 1621, in execute_sql
    cursor.execute(sql, params)
  File "/Users/timur/Desktop/ZEON/zmall_restapi/venv/lib/python3.10/site-packages/django/db/backends/utils.py", line 103, in execute
    return super().execute(sql, params)
  File "/Users/timur/Desktop/ZEON/zmall_restapi/venv/lib/python3.10/site-packages/django/db/backends/utils.py", line 67, in execute
    return self._execute_with_wrappers(
  File "/Users/timur/Desktop/ZEON/zmall_restapi/venv/lib/python3.10/site-packages/django/db/backends/utils.py", line 80, in _execute_with_wrappers
    return executor(sql, params, many, context)
  File "/Users/timur/Desktop/ZEON/zmall_restapi/venv/lib/python3.10/site-packages/django/db/backends/utils.py", line 84, in _execute
    with self.db.wrap_database_errors:
  File "/Users/timur/Desktop/ZEON/zmall_restapi/venv/lib/python3.10/site-packages/django/db/utils.py", line 91, in __exit__
    raise dj_exc_value.with_traceback(traceback) from exc_value
  File "/Users/timur/Desktop/ZEON/zmall_restapi/venv/lib/python3.10/site-packages/django/db/backends/utils.py", line 89, in _execute
    return self.cursor.execute(sql, params)
  File "/Users/timur/Desktop/ZEON/zmall_restapi/venv/lib/python3.10/site-packages/django/db/backends/sqlite3/base.py", line 477, in execute
    return Database.Cursor.execute(self, query, params)
django.db.utils.OperationalError: table adds_favorite has no column named post_id
2022-09-17 17:25:16,147 [basehttp | ERROR] "POST /api/v1/adds/favorite/ HTTP/1.1" 500 189752 @ /Users/timur/Desktop/ZEON/zmall_restapi/venv/lib/python3.10/site-packages/django/core/servers/basehttp.py : 187 : log_message
2022-09-17 17:25:16,147 [basehttp | ERROR] "POST /api/v1/adds/favorite/ HTTP/1.1" 500 189752
